Workbook

Sheet Oxides
A2: Mass percent | B2: Group : Olivine | C2: Sample : 010317Fr | D2: Page | E2: 1
A4: No. | B4: MgO | C4: MnO | D4: FeO | E4: SiO2 | F4: CaO | G4: Cr2O3 | H4: NiO | I4: Al2O3 | J4: Total | K4: Comment
A5: 1 | B5: 49.78 | C5: 0.1478 | D5: 9.56 | E5: 39.72 | F5: 0.1024 | G5: 0.0311 | H5: 0.3672 | I5: 0.0316 | J5: 99.7402 | K5: SC-Olivine | M5: =B5/(B5+D5) -> 0.83889451 | N5: =100*(B5/40.3)/((B5/40.3)+(D5/71.84)) -> 90.274604
A6: 2 | B6: 49.65 | C6: 0.1413 | D6: 9.61 | E6: 39.76 | F6: 0.0978 | G6: 0.0162 | H6: 0.381 | I6: 0.033 | J6: =SUM(B6:I6) -> 99.6893 | K6: SC-Olivine
A7: 3 | B7: 49.6 | C7: 0.144 | D7: 9.5 | E7: 39.65 | F7: 0.1039 | G7: 0.0179 | H7: 0.3469 | I7: 0.0344 | J7: =SUM(B7:I7) -> 99.3971 | K7: SC-Olivine
A8: 4 | B8: 46.01 | C8: 0.2421 | D8: 14.5 | E8: 38.7 | F8: 0.3536 | G8: 0.0355 | H8: 0.2042 | I8: 0.0358 | J8: =SUM(B8:I8) -> 100.0812 | K8: UnkA-C20-S2-1MI_1_1
A9: 5 | B9: 45.73 | C9: 0.2578 | D9: 14.88 | E9: 38.52 | F9: 0.353 | G9: 0.0244 | H9: 0.1967 | I9: 0.034 | J9: =SUM(B9:I9) -> 99.9959 | K9: UnkA-C20-S2-1MI_1_2
A10: 6 | B10: 46.3 | C10: 0.2209 | D10: 13.92 | E10: 39.71 | F10: 0.3368 | G10: 0.0266 | H10: 0.2088 | I10: 0.0248 | J10: =SUM(B10:I10) -> 100.7479 | K10: UnkA-C20-S2-1MI_1_3
A11: 7 | B11: 44.96 | C11: 0.2504 | D11: 15.32 | E11: 40 | F11: 0.3416 | G11: 0.0176 | H11: 0.1803 | I11: 0.0352 | J11: =SUM(B11:I11) -> 101.1051 | K11: UnkA-C20-S2-1MI_2_1
A12: 8 | B12: 44.92 | C12: 0.2524 | D12: 15.22 | E12: 38.43 | F12: 0.3443 | G12: 0.011 | H12: 0.1934 | I12: 0.0391 | J12: =SUM(B12:I12) -> 99.4102 | K12: UnkA-C20-S2-1MI_2_2
A13: 9 | B13: 44.49 | C13: 0.2462 | D13: 15.37 | E13: 39.08 | F13: 0.3368 | G13: 0.0049 | H13: 0.1965 | I13: 0.0488 | J13: =SUM(B13:I13) -> 99.7732 | K13: UnkA-C20-S2-1MI_2_3
A14: 10 | B14: 47.3 | C14: 0.2065 | D14: 12.77 | E14: 38.99 | F14: 0.3588 | G14: 0.0418 | H14: 0.2019 | I14: 0.0451 | J14: =SUM(B14:I14) -> 99.9141 | K14: UnkA-C20-S2-1MI_3_1
A15: 11 | B15: 47.27 | C15: 0.2181 | D15: 12.97 | E15: 39.02 | F15: 0.3563 | G15: 0.0319 | H15: 0.2124 | I15: 0.0242 | J15: =SUM(B15:I15) -> 100.1029 | K15: UnkA-C20-S2-1MI_3_2
A16: 12 | B16: 47.14 | C16: 0.2082 | D16: 12.83 | E16: 40.15 | F16: 0.3522 | G16: 0.0436 | H16: 0.2098 | I16: 0.0344 | J16: =SUM(B16:I16) -> 100.9682 | K16: UnkA-C20-S2-1MI_3_3
A17: 13 | B17: 47.47 | C17: 0.2114 | D17: 12.9 | E17: 40.01 | F17: 0.3616 | G17: 0.0332 | H17: 0.219 | I17: 0.0353 | J17: =SUM(B17:I17) -> 101.2405 | K17: UnkA-C20-S2-1MI_4_1
... A132: 128 | B132: 49.47 | C132: 0.1408 | D132: 9.42 | E132: 41.28 | F132: 0.1042 | G132: 0.0152 | H132: 0.364 | I132: 0.0438 | J132: =SUM(B132:I132) -> 100.838 | K132: SC-Olivine
A133: SRM SC-Ol | B133: 49.4299 | C133: 0.14 | D133: 9.5457 | E133: 40.8158 | F133: 0.092 | G133: 0.014 | H133: 0.37 | I133: 0.033
A135: CorrFactor | B135: 1.0056955 | F135: 1.1062319
A139: Average SC-Ol | B139: =AVERAGE(B5:B7,B29:B31,B63:B65,B93:B95,B130:B132) -> 49.735333 | C139: =AVERAGE(C5:C7,C29:C31,C63:C65,C93:C95,C130:C132) -> 0.14332 | D139: =AVERAGE(D5:D7,D29:D31,D63:D65,D93:D95,D130:D132) -> 9.5066667 | E139: =AVERAGE(E5:E7,E29:E31,E63:E65,E93:E95) -> 39.8125 | F139: =AVERAGE(F5:F6,F7,F29:F31,F63:F65,F93:F95,F130:F132) -> 0.10177333 | G139: =AVERAGE(G6:G7,G29:G31,G63:G65,G93:G95,G130:G132) -> 0.01415 | H139: =AVERAGE(H5:H7,H29:H31,H63:H65,H93:H95,H130:H132) -> 0.35354 | I139: =AVERAGE(I5:I7,I29:I31,I63:I65,I93:I95,I130:I132) -> 0.03396
A140: Stdev SC-Ol | B140: =STDEV(B5:B7,B29:B31,B63:B65,B93:B95,B130:B131) -> 0.12756382 | C140: =STDEV(C5:C7,C29:C31,C63:C65,C93:C95,C130:C132) -> 0.0042340794 | D140: =STDEV(D5:D7,D29:D31,D63:D65,D93:D95,D130:D132) -> 0.070474582 | E140: =STDEV(E5:E7,E29:E31,E63:E65,E93:E95) -> 0.27604759 | F140: =STDEV(F5:F6,F7,F29:F31,F63:F65,F93:F95,F130:F132) -> 0.0020182973 | G140: =STDEV(G6:G7,G29:G31,G63:G65,G93:G95,G130:G132) -> 0.0049297761 | H140: =STDEV(H5:H7,H29:H31,H63:H65,H93:H95,H130:H132) -> 0.022384459 | I140: =STDEV(I5:I7,I29:I31,I63:I65,I93:I95,I130:I132) -> 0.0038973984
A141: SRM SC-Ol | B141: 49.4299 | C141: 0.14 | D141: 9.5457 | E141: 40.8158 | F141: 0.092 | G141: 0.014 | H141: 0.37 | I141: 0.033
A142: Correction Factor | B142: 1.0056666 | F142: =F139/F141 -> 1.1062319
A144: Precision | B144: =B140 -> 0.12756382 | C144: =C140 -> 0.0042340794 | D144: =D140 -> 0.070474582 | E144: =E140 -> 0.27604759 | F144: =F140 -> 0.0020182973 | G144: =G140 -> 0.0049297761 | H144: =H140 -> 0.022384459 | I144: =I140 -> 0.0038973984
A145: Accuracy Err | B145: =(ABS((B139-B141))/B141) -> 0.006179121 | C145: =(ABS((C139-C141))/C141) -> 0.023714286 | D145: =(ABS((D139-D141))/D141) -> 0.0040891012 | E145: =(ABS((E139-E141))/E141) -> 0.024581167 | F145: =(ABS((F139-F141))/F141) -> 0.10623188 | G145: =(ABS((G139-G141))/G141) -> 0.010714286 | H145: =(ABS((H139-H141))/H141) -> 0.044486486 | I145: =(ABS((I139-I141))/I141) -> 0.029090909

Sheet Oxides Corr
A2: Mass percent | B2: Group : Olivine | C2: Sample : 010317Fr | D2: Page | E2: 1
A4: No. | B4: MgO Corr | C4: MnO | D4: FeO Corr | E4: SiO2 Corr | F4: CaO Corr | G4: Cr2O3 | H4: NiO | I4: Al2O3 | J4: Total | K4: Comment | N4: Fo+M | O4: Fa+M | P4: Total
A5: 1 | B5: =Oxides!B5/StdCalc!B$26 -> 49.474292 | C5: =Oxides!C5/StdCalc!C$26 -> 0.14437622 | D5: =Oxides!D5/StdCalc!D$26 -> 9.5992523 | E5: =Oxides!E5/StdCalc!E$26 -> 40.438429 | F5: =Oxides!F5/StdCalc!F$26 -> 0.092566488 | G5: =Oxides!G5/StdCalc!G$26 -> 0.030770318 | H5: =Oxides!H5/StdCalc!H$26 -> 0.37892623 | I5: =Oxides!I5/StdCalc!I$26 -> 0.03135567 | J5: =SUM(B5:I5) -> 100.18997 | K5: SC-Olivine | N5: =100*(B5/40.304)/((B5/40.304)+(D5/71.844)) -> 90.183788 | O5: =100-N5 -> 9.8162121 | P5: =SUM(N5:O5) -> 100
A6: 2 | B6: =Oxides!B6/StdCalc!B$26 -> 49.345091 | C6: =Oxides!C6/StdCalc!C$26 -> 0.13802679 | D6: =Oxides!D6/StdCalc!D$26 -> 9.6494576 | E6: =Oxides!E6/StdCalc!E$26 -> 40.479152 | F6: =Oxides!F6/StdCalc!F$26 -> 0.088408227 | G6: =Oxides!G6/StdCalc!G$26 -> 0.016028269 | H6: =Oxides!H6/StdCalc!H$26 -> 0.39316692 | I6: =Oxides!I6/StdCalc!I$26 -> 0.032744845 | J6: =SUM(B6:I6) -> 100.14208 | K6: SC-Olivine | N6: =100*(B6/40.304)/((B6/40.304)+(D6/71.844)) -> 90.114241 | O6: =100-N6 -> 9.8857591 | P6: =SUM(N6:O6) -> 100
A7: 3 | B7: =Oxides!B7/StdCalc!B$26 -> 49.295398 | C7: =Oxides!C7/StdCalc!C$26 -> 0.14066425 | D7: =Oxides!D7/StdCalc!D$26 -> 9.539006 | E7: =Oxides!E7/StdCalc!E$26 -> 40.367163 | F7: =Oxides!F7/StdCalc!F$26 -> 0.093922442 | G7: =Oxides!G7/StdCalc!G$26 -> 0.017710247 | H7: =Oxides!H7/StdCalc!H$26 -> 0.35797797 | I7: =Oxides!I7/StdCalc!I$26 -> 0.034134021 | J7: =SUM(B7:I7) -> 99.845976 | K7: SC-Olivine | N7: =100*(B7/40.304)/((B7/40.304)+(D7/71.844)) -> 90.20743 | O7: =100-N7 -> 9.7925703 | P7: =SUM(N7:O7) -> 100
A8: 4 | B8: =Oxides!B8/StdCalc!B$26 -> 45.727445 | C8: =Oxides!C8/StdCalc!C$26 -> 0.23649177 | D8: =Oxides!D8/StdCalc!D$26 -> 14.559535 | E8: =Oxides!E8/StdCalc!E$26 -> 39.39998 | F8: =Oxides!F8/StdCalc!F$26 -> 0.31964365 | G8: =Oxides!G8/StdCalc!G$26 -> 0.035123675 | H8: =Oxides!H8/StdCalc!H$26 -> 0.21072096 | I8: =Oxides!I8/StdCalc!I$26 -> 0.035523196 | J8: =SUM(B8:I8) -> 100.52446 | K8: UnkA-C20-S2-1MI_1_1 | N8: =100*(B8/40.304)/((B8/40.304)+(D8/71.844)) -> 84.845043 | O8: =100-N8 -> 15.154957 | P8: =SUM(N8:O8) -> 100
A9: 5 | B9: =Oxides!B9/StdCalc!B$26 -> 45.449164 | C9: =Oxides!C9/StdCalc!C$26 -> 0.25182808 | D9: =Oxides!D9/StdCalc!D$26 -> 14.941096 | E9: =Oxides!E9/StdCalc!E$26 -> 39.216724 | F9: =Oxides!F9/StdCalc!F$26 -> 0.31910127 | G9: =Oxides!G9/StdCalc!G$26 -> 0.024141343 | H9: =Oxides!H9/StdCalc!H$26 -> 0.20298145 | I9: =Oxides!I9/StdCalc!I$26 -> 0.033737113 | J9: =SUM(B9:I9) -> 100.43877 | K9: UnkA-C20-S2-1MI_1_2 | N9: =100*(B9/40.304)/((B9/40.304)+(D9/71.844)) -> 84.429323 | O9: =100-N9 -> 15.570677 | P9: =SUM(N9:O9) -> 100
A10: 6 | B10: =Oxides!B10/StdCalc!B$26 -> 46.015664 | C10: =Oxides!C10/StdCalc!C$26 -> 0.21578286 | D10: =Oxides!D10/StdCalc!D$26 -> 13.977154 | E10: =Oxides!E10/StdCalc!E$26 -> 40.428248 | F10: =Oxides!F10/StdCalc!F$26 -> 0.30445696 | G10: =Oxides!G10/StdCalc!G$26 -> 0.026318021 | H10: =Oxides!H10/StdCalc!H$26 -> 0.21546786 | I10: =Oxides!I10/StdCalc!I$26 -> 0.024608247 | J10: =SUM(B10:I10) -> 101.2077 | K10: UnkA-C20-S2-1MI_1_3 | N10: =100*(B10/40.304)/((B10/40.304)+(D10/71.844)) -> 85.440843 | O10: =100-N10 -> 14.559157 | P10: =SUM(N10:O10) -> 100
A11: 7 | B11: =Oxides!B11/StdCalc!B$26 -> 44.683893 | C11: =Oxides!C11/StdCalc!C$26 -> 0.2445995 | D11: =Oxides!D11/StdCalc!D$26 -> 15.382902 | E11: =Oxides!E11/StdCalc!E$26 -> 40.723493 | F11: =Oxides!F11/StdCalc!F$26 -> 0.30879602 | G11: =Oxides!G11/StdCalc!G$26 -> 0.017413428 | H11: =Oxides!H11/StdCalc!H$26 -> 0.18605773 | I11: =Oxides!I11/StdCalc!I$26 -> 0.034927835 | J11: =SUM(B11:I11) -> 101.58208 | K11: UnkA-C20-S2-1MI_2_1 | N11: =100*(B11/40.304)/((B11/40.304)+(D11/71.844)) -> 83.813314 | O11: =100-N11 -> 16.186686 | P11: =SUM(N11:O11) -> 100
A12: 8 | B12: =Oxides!B12/StdCalc!B$26 -> 44.644138 | C12: =Oxides!C12/StdCalc!C$26 -> 0.24655317 | D12: =Oxides!D12/StdCalc!D$26 -> 15.282492 | E12: =Oxides!E12/StdCalc!E$26 -> 39.125096 | F12: =Oxides!F12/StdCalc!F$26 -> 0.31123674 | G12: =Oxides!G12/StdCalc!G$26 -> 0.010883392 | H12: =Oxides!H12/StdCalc!H$26 -> 0.19957607 | I12: =Oxides!I12/StdCalc!I$26 -> 0.03879768 | J12: =SUM(B12:I12) -> 99.858773 | K12: UnkA-C20-S2-1MI_2_2 | N12: =100*(B12/40.304)/((B12/40.304)+(D12/71.844)) -> 83.889937 | O12: =100-N12 -> 16.110063 | P12: =SUM(N12:O12) -> 100
A13: 9 | B13: =Oxides!B13/StdCalc!B$26 -> 44.216779 | C13: =Oxides!C13/StdCalc!C$26 -> 0.24049679 | D13: =Oxides!D13/StdCalc!D$26 -> 15.433108 | E13: =Oxides!E13/StdCalc!E$26 -> 39.786853 | F13: =Oxides!F13/StdCalc!F$26 -> 0.30445696 | G13: =Oxides!G13/StdCalc!G$26 -> 0.0048480565 | H13: =Oxides!H13/StdCalc!H$26 -> 0.20277507 | I13: =Oxides!I13/StdCalc!I$26 -> 0.04842268 | J13: =SUM(B13:I13) -> 100.23774 | K13: UnkA-C20-S2-1MI_2_3 | N13: =100*(B13/40.304)/((B13/40.304)+(D13/71.844)) -> 83.62567 | O13: =100-N13 -> 16.37433 | P13: =SUM(N13:O13) -> 100
A14: 10 | B14: =Oxides!B14/StdCalc!B$26 -> 47.009522 | C14: =Oxides!C14/StdCalc!C$26 -> 0.20171644 | D14: =Oxides!D14/StdCalc!D$26 -> 12.822432 | E14: =Oxides!E14/StdCalc!E$26 -> 39.695225 | F14: =Oxides!F14/StdCalc!F$26 -> 0.32434429 | G14: =Oxides!G14/StdCalc!G$26 -> 0.04135689 | H14: =Oxides!H14/StdCalc!H$26 -> 0.20834751 | I14: =Oxides!I14/StdCalc!I$26 -> 0.044751289 | J14: =SUM(B14:I14) -> 100.3477 | K14: UnkA-C20-S2-1MI_3_1 | N14: =100*(B14/40.304)/((B14/40.304)+(D14/71.844)) -> 86.728923 | O14: =100-N14 -> 13.271077 | P14: =SUM(N14:O14) -> 100
A15: 11 | B15: =Oxides!B15/StdCalc!B$26 -> 46.979707 | C15: =Oxides!C15/StdCalc!C$26 -> 0.21304773 | D15: =Oxides!D15/StdCalc!D$26 -> 13.023253 | E15: =Oxides!E15/StdCalc!E$26 -> 39.725768 | F15: =Oxides!F15/StdCalc!F$26 -> 0.32208437 | G15: =Oxides!G15/StdCalc!G$26 -> 0.031561837 | H15: =Oxides!H15/StdCalc!H$26 -> 0.21918282 | I15: =Oxides!I15/StdCalc!I$26 -> 0.024012887 | J15: =SUM(B15:I15) -> 100.53862 | K15: UnkA-C20-S2-1MI_3_2 | N15: =100*(B15/40.304)/((B15/40.304)+(D15/71.844)) -> 86.541645 | O15: =100-N15 -> 13.458355 | P15: =SUM(N15:O15) -> 100
A16: 12 | B16: =Oxides!B16/StdCalc!B$26 -> 46.850505 | C16: =Oxides!C16/StdCalc!C$26 -> 0.20337706 | D16: =Oxides!D16/StdCalc!D$26 -> 12.882679 | E16: =Oxides!E16/StdCalc!E$26 -> 40.876207 | F16: =Oxides!F16/StdCalc!F$26 -> 0.3183781 | G16: =Oxides!G16/StdCalc!G$26 -> 0.043137809 | H16: =Oxides!H16/StdCalc!H$26 -> 0.21649979 | I16: =Oxides!I16/StdCalc!I$26 -> 0.034134021 | J16: =SUM(B16:I16) -> 101.42492 | K16: UnkA-C20-S2-1MI_3_3 | N16: =100*(B16/40.304)/((B16/40.304)+(D16/71.844)) -> 86.635694 | O16: =100-N16 -> 13.364306 | P16: =SUM(N16:O16) -> 100
... A132: 128 | B132: =Oxides!B132/StdCalc!B$26 -> 49.166196 | C132: =Oxides!C132/StdCalc!C$26 -> 0.13753838 | D132: =Oxides!D132/StdCalc!D$26 -> 9.4586775 | E132: =Oxides!E132/StdCalc!E$26 -> 42.026645 | F132: =Oxides!F132/StdCalc!F$26 -> 0.094193633 | G132: =Oxides!G132/StdCalc!G$26 -> 0.015038869 | H132: =Oxides!H132/StdCalc!H$26 -> 0.37562404 | I132: =Oxides!I132/StdCalc!I$26 -> 0.04346134 | J132: =SUM(B132:I132) -> 101.31738 | K132: SC-Olivine | N132: =100*(B132/40.304)/((B132/40.304)+(D132/71.844)) -> 90.258829 | O132: =100-N132 -> 9.7411706 | P132: =SUM(N132:O132) -> 100
A134: SRM SC-Ol | B134: 49.4299 | C134: 0.14 | D134: 9.5457 | E134: 40.81 | F134: 0.092 | G134: 0.014 | H134: 0.37 | I134: 0.033 | K134: SC-Olivine
A135: Average | B135: 49.735333 | C135: 0.14332 | D135: 9.5066667 | E135: 40.090667 | F135: 0.10177333 | G135: 0.01415 | H135: 0.35855 | I135: 0.033257143 | K135: SC-Olivine
A136: StdDev | B136: 0.14317156 | C136: 0.0042340794 | D136: 0.070474582 | E136: 0.62826822 | F136: 0.0020182973 | G136: 0.0049297761 | H136: 0.011582065 | I136: 0.0028944813 | K136: SC-Olivine
A137: 2SIG | B137: 0.28634312 | C137: 0.0084681588 | D137: 0.14094916 | E137: 1.2565364 | F137: 0.0040365945 | G137: 0.0098595522 | H137: 0.02316413 | I137: 0.0057889626 | K137: SC-Olivine
A138: Accuracy | B138: 0.0007638498 | C138: 0.033121722 | D138: 0.007031168 | E138: 0.0011469606 | F138: 0.02087662 | G138: 0.12518458 | H138: 0.0019509476 | I138: 0.058544788 | K138: SC-Olivine
A139: RSD | B139: 0.0057573379 | C139: 0.059085674 | D139: 0.01482635 | E139: 0.031342368 | F139: 0.039662595 | G139: 0.69678814 | H139: 0.06460502 | I139: 0.17406674 | K139: SC-Olivine
A140: CorrFactor | B140: 1.0061791 | C140: 1.0237143 | D140: 0.9959109 | E140: 0.982234 | F140: 1.1062319 | G140: 1.0107143 | H140: 0.96905405 | I140: 1.0077922 | K140: SC-Olivine

Sheet StdCalc
A1: Original | M1: Corrected | Y1: Accuracy | AK1: Accuracy Corrected
A3: No. | B3: MgO | C3: MnO | D3: FeO | E3: SiO2 | F3: CaO | G3: Cr2O3 | H3: NiO | I3: Al2O3 | J3: Total | K3: Comment | M3: No. | N3: MgO | O3: MnO | P3: FeO | Q3: SiO2 | R3: CaO | S3: Cr2O3 | T3: NiO | U3: Al2O3 | V3: TOTAL | Y3: No. | Z3: MgO | AA3: MnO | AB3: FeO | AC3: SiO2 | AD3: CaO | AE3: Cr2O3 | AF3: NiO | AG3: Al2O3 | AH3: Total | AI3: Comment | AK3: No. | AL3: MgO | AM3: MnO | AN3: FeO | AO3: SiO2 | AP3: CaO | AQ3: Cr2O3 | AR3: NiO | AS3: Al2O3 | AT3: Total | AU3: Comment
A4: 1 | B4: 49.78 | C4: 0.1478 | D4: 9.56 | E4: 39.72 | F4: 0.1024 | G4: 0.0311 | H4: 0.3672 | I4: 0.0316 | J4: 99.7402 | K4: SC-Olivine | M4: 1 | N4: =B4/$B$26 -> 49.474292 | O4: =C4/$C$26 -> 0.14437622 | P4: =D4/D$26 -> 9.5992523 | Q4: =E4/E$26 -> 40.438429 | R4: =F4/F$26 -> 0.092566488 | S4: =G4/G$26 -> 0.030770318 | T4: =H4/H$26 -> 0.37892623 | U4: =I4/I$26 -> 0.03135567 | V4: =SUM(N4:U4) -> 100.18997 | Y4: 1 | Z4: 49.78 | AA4: 0.1478 | AB4: 9.56 | AC4: 39.72 | AD4: 0.1024 | AE4: 0.0311 | AF4: 0.3672 | AG4: 0.0316 | AH4: 99.7402 | AI4: SC-Olivine | AK4: 1 | AL4: =Z4/Z$26 -> 49.461695 | AM4: =AA4/AA$26 -> 0.14278222 | AN4: =AB4/AB$26 -> 9.5767543 | AO4: =AC4/AC$26 -> 40.422969 | AP4: =AD4/AD$26 -> 0.093210646 | AQ4: =AE4/AE$26 -> 0.032146021 | AR4: =AF4/AF$26 -> 0.37866221 | AS4: =AG4/AG$26 -> 0.031880159 | AT4: 99.7402 | AU4: SC-Olivine
A5: 2 | B5: 49.65 | C5: 0.1413 | D5: 9.61 | E5: 39.76 | F5: 0.0978 | G5: 0.0162 | H5: 0.381 | I5: 0.033 | J5: 99.6893 | K5: SC-Olivine | M5: 2 | N5: =B5/$B$26 -> 49.345091 | O5: =C5/$C$26 -> 0.13802679 | P5: =D5/D$26 -> 9.6494576 | Q5: =E5/E$26 -> 40.479152 | R5: =F5/F$26 -> 0.088408227 | S5: =G5/G$26 -> 0.016028269 | T5: =H5/H$26 -> 0.39316692 | U5: =I5/I$26 -> 0.032744845 | V5: =SUM(N5:U5) -> 100.14208 | Y5: 2 | Z5: 49.65 | AA5: 0.1413 | AB5: 9.61 | AC5: 39.76 | AD5: 0.0978 | AE5: 0.0162 | AF5: 0.381 | AG5: 0.033 | AH5: 99.6893 | AI5: SC-Olivine | AK5: 2 | AL5: =Z5/Z$26 -> 49.332527 | AM5: =AA5/AA$26 -> 0.1365029 | AN5: =AB5/AB$26 -> 9.626842 | AO5: =AC5/AC$26 -> 40.463676 | AP5: =AD5/AD$26 -> 0.089023449 | AQ5: =AE5/AE$26 -> 0.016744873 | AR5: =AF5/AF$26 -> 0.39289298 | AS5: =AG5/AG$26 -> 0.033292571 | AT5: 99.6893 | AU5: SC-Olivine
A6: 3 | B6: 49.6 | C6: 0.144 | D6: 9.5 | E6: 39.65 | F6: 0.1039 | G6: 0.0179 | H6: 0.3469 | I6: 0.0344 | J6: 99.3971 | K6: SC-Olivine | M6: 3 | N6: =B6/$B$26 -> 49.295398 | O6: =C6/$C$26 -> 0.14066425 | P6: =D6/D$26 -> 9.539006 | Q6: =E6/E$26 -> 40.367163 | R6: =F6/F$26 -> 0.093922442 | S6: =G6/G$26 -> 0.017710247 | T6: =H6/H$26 -> 0.35797797 | U6: =I6/I$26 -> 0.034134021 | V6: =SUM(N6:U6) -> 99.845976 | Y6: 3 | Z6: 49.6 | AA6: 0.144 | AB6: 9.5 | AC6: 39.65 | AD6: 0.1039 | AE6: 0.0179 | AF6: 0.3469 | AG6: 0.0344 | AH6: 99.3971 | AI6: SC-Olivine | AK6: 3 | AL6: =Z6/Z$26 -> 49.282846 | AM6: =AA6/AA$26 -> 0.13911123 | AN6: =AB6/AB$26 -> 9.5166492 | AO6: =AC6/AC$26 -> 40.35173 | AP6: =AD6/AD$26 -> 0.094576036 | AQ6: =AE6/AE$26 -> 0.018502051 | AR6: =AF6/AF$26 -> 0.35772854 | AS6: =AG6/AG$26 -> 0.034704983 | AT6: 99.3971 | AU6: SC-Olivine
A7: 25 | B7: 49.71 | C7: 0.1437 | D7: 9.51 | E7: 39.65 | F7: 0.0992 | G7: 0.0072 | H7: 0.3527 | I7: 0.0314 | J7: 99.5043 | K7: SC-Olivine | M7: 25 | N7: =B7/$B$26 -> 49.404722 | O7: =C7/$C$26 -> 0.1403712 | P7: =D7/D$26 -> 9.549047 | Q7: =E7/E$26 -> 40.367163 | R7: =F7/F$26 -> 0.089673785 | S7: =G7/G$26 -> 0.0071236749 | T7: =H7/H$26 -> 0.36396319 | U7: =I7/I$26 -> 0.031157216 | V7: =SUM(N7:U7) -> 99.953221 | Y7: 25 | Z7: 49.71 | AA7: 0.1437 | AB7: 9.51 | AC7: 39.65 | AD7: 0.0992 | AE7: 0.0072 | AF7: 0.3527 | AG7: 0.0314 | AH7: 99.5043 | AI7: SC-Olivine | AK7: 25 | AL7: =Z7/Z$26 -> 49.392143 | AM7: =AA7/AA$26 -> 0.13882142 | AN7: =AB7/AB$26 -> 9.5266667 | AO7: =AC7/AC$26 -> 40.35173 | AP7: =AD7/AD$26 -> 0.090297813 | AQ7: =AE7/AE$26 -> 0.0074421657 | AR7: =AF7/AF$26 -> 0.36370959 | AS7: =AG7/AG$26 -> 0.031678386 | AT7: 99.5043 | AU7: SC-Olivine
A8: 26 | B8: 49.74 | C8: 0.1491 | D8: 9.44 | E8: 39.61 | F8: 0.1043 | G8: 0.0142 | H8: 0.3645 | I8: 0.0321 | J8: 99.4543 | K8: SC-Olivine | M8: 26 | N8: =B8/$B$26 -> 49.434538 | O8: =C8/$C$26 -> 0.14564611 | P8: =D8/D$26 -> 9.4787596 | Q8: =E8/E$26 -> 40.326439 | R8: =F8/F$26 -> 0.09428403 | S8: =G8/G$26 -> 0.01404947 | T8: =H8/H$26 -> 0.37614001 | U8: =I8/I$26 -> 0.031851804 | V8: =SUM(N8:U8) -> 99.901708 | Y8: 26 | Z8: 49.74 | AA8: 0.1491 | AB8: 9.44 | AC8: 39.61 | AD8: 0.1043 | AE8: 0.0142 | AF8: 0.3645 | AG8: 0.0321 | AH8: 99.4543 | AI8: SC-Olivine | AK8: 26 | AL8: =Z8/Z$26 -> 49.421951 | AM8: =AA8/AA$26 -> 0.14403809 | AN8: =AB8/AB$26 -> 9.456544 | AO8: =AC8/AC$26 -> 40.311022 | AP8: =AD8/AD$26 -> 0.09494014 | AQ8: =AE8/AE$26 -> 0.014677605 | AR8: =AF8/AF$26 -> 0.37587793 | AS8: =AG8/AG$26 -> 0.032384592 | AT8: 99.4543 | AU8: SC-Olivine
A9: 27 | B9: 49.74 | C9: 0.1368 | D9: 9.53 | E9: 39.46 | F9: 0.1035 | G9: 0.019 | H9: 0.3459 | I9: 0.0368 | J9: 99.372 | K9: SC-Olivine | M9: 27 | N9: =B9/$B$26 -> 49.434538 | O9: =C9/$C$26 -> 0.13363104 | P9: =D9/D$26 -> 9.5691291 | Q9: =E9/E$26 -> 40.173726 | R9: =F9/F$26 -> 0.093560854 | S9: =G9/G$26 -> 0.018798587 | T9: =H9/H$26 -> 0.35694603 | U9: =I9/I$26 -> 0.036515464 | V9: =SUM(N9:U9) -> 99.816845 | Y9: 27 | Z9: 49.74 | AA9: 0.1368 | AB9: 9.53 | AC9: 39.46 | AD9: 0.1035 | AE9: 0.019 | AF9: 0.3459 | AG9: 0.0368 | AH9: 99.372 | AI9: SC-Olivine | AK9: 27 | AL9: =Z9/Z$26 -> 49.421951 | AM9: =AA9/AA$26 -> 0.13215567 | AN9: =AB9/AB$26 -> 9.5467018 | AO9: =AC9/AC$26 -> 40.158367 | AP9: =AD9/AD$26 -> 0.094211932 | AQ9: =AE9/AE$26 -> 0.019639048 | AR9: =AF9/AF$26 -> 0.35669732 | AS9: =AG9/AG$26 -> 0.037126261 | AT9: 99.372 | AU9: SC-Olivine
A10: 59 | B10: 49.76 | C10: 0.1487 | D10: 9.54 | E10: 39.77 | F10: 0.1018 | G10: 0.0054 | H10: 0.3552 | I10: 0.034 | J10: 99.7152 | K10: SC-Olivine | M10: 59 | N10: =B10/$B$26 -> 49.454415 | O10: =C10/$C$26 -> 0.14525537 | P10: =D10/D$26 -> 9.5791702 | Q10: =E10/E$26 -> 40.489333 | R10: =F10/F$26 -> 0.092024106 | S10: =G10/G$26 -> 0.0053427562 | T10: =H10/H$26 -> 0.36654302 | U10: =I10/I$26 -> 0.033737113 | V10: =SUM(N10:U10) -> 100.16582 | Y10: 59 | Z10: 49.76 | AA10: 0.1487 | AB10: 9.54 | AC10: 39.77 | AD10: 0.1018 | AE10: 0.0054 | AF10: 0.3552 | AG10: 0.034 | AH10: 99.7152 | AI10: SC-Olivine | AK10: 59 | AL10: =Z10/Z$26 -> 49.441823 | AM10: =AA10/AA$26 -> 0.14365167 | AN10: =AB10/AB$26 -> 9.5567193 | AO10: =AC10/AC$26 -> 40.473853 | AP10: =AD10/AD$26 -> 0.09266449 | AQ10: =AE10/AE$26 -> 0.0055816243 | AR10: =AF10/AF$26 -> 0.36628763 | AS10: =AG10/AG$26 -> 0.034301437 | AT10: 99.7152 | AU10: SC-Olivine
A11: 60 | B11: 49.97 | C11: 0.1457 | D11: 9.62 | E11: 39.7 | F11: 0.1033 | G11: 0.0104 | H11: 0.3548 | I11: 0.0313 | J11: 99.9356 | K11: SC-Olivine | M11: 60 | N11: =B11/$B$26 -> 49.663126 | O11: =C11/$C$26 -> 0.14232487 | P11: =D11/D$26 -> 9.6594987 | Q11: =E11/E$26 -> 40.418067 | R11: =F11/F$26 -> 0.09338006 | S11: =G11/G$26 -> 0.010289753 | T11: =H11/H$26 -> 0.36613025 | U11: =I11/I$26 -> 0.03105799 | V11: =SUM(N11:U11) -> 100.38387 | Y11: 60 | Z11: 49.97 | AA11: 0.1457 | AB11: 9.62 | AC11: 39.7 | AD11: 0.1033 | AE11: 0.0104 | AF11: 0.3548 | AG11: 0.0313 | AH11: 99.9356 | AI11: SC-Olivine | AK11: 60 | AL11: =Z11/Z$26 -> 49.65048 | AM11: =AA11/AA$26 -> 0.14075352 | AN11: =AB11/AB$26 -> 9.6368595 | AO11: =AC11/AC$26 -> 40.402615 | AP11: =AD11/AD$26 -> 0.09402988 | AQ11: =AE11/AE$26 -> 0.010749795 | AR11: =AF11/AF$26 -> 0.36587514 | AS11: =AG11/AG$26 -> 0.031577499 | AT11: 99.9356 | AU11: SC-Olivine
A12: 61 | B12: 50.07 | C12: 0.1356 | D12: 9.49 | E12: 39.69 | F12: 0.1028 | G12: 0.0143 | H12: 0.3781 | I12: 0.0382 | J12: 99.9191 | K12: SC-Olivine | M12: 61 | N12: =B12/$B$26 -> 49.762511 | O12: =C12/$C$26 -> 0.13245883 | P12: =D12/D$26 -> 9.5289649 | Q12: =E12/E$26 -> 40.407886 | R12: =F12/F$26 -> 0.092928075 | S12: =G12/G$26 -> 0.01414841 | T12: =H12/H$26 -> 0.39017431 | U12: =I12/I$26 -> 0.037904639 | V12: =SUM(N12:U12) -> 100.36698 | Y12: 61 | Z12: 50.07 | AA12: 0.1356 | AB12: 9.49 | AC12: 39.69 | AD12: 0.1028 | AE12: 0.0143 | AF12: 0.3781 | AG12: 0.0382 | AH12: 99.9191 | AI12: SC-Olivine | AK12: 61 | AL12: =Z12/Z$26 -> 49.749841 | AM12: =AA12/AA$26 -> 0.13099641 | AN12: =AB12/AB$26 -> 9.5066317 | AO12: =AC12/AC$26 -> 40.392438 | AP12: =AD12/AD$26 -> 0.09357475 | AQ12: =AE12/AE$26 -> 0.014780968 | AR12: =AF12/AF$26 -> 0.38990245 | AS12: =AG12/AG$26 -> 0.038538673 | AT12: 99.9191 | AU12: SC-Olivine
A13: 89 | B13: 49.77 | C13: 0.1457 | D13: 9.54 | E13: 40.18 | F13: 0.0991 | G13: 0.0215 | H13: 0.3401 | I13: 0.0389 | J13: 100.1352 | K13: SC-Olivine | M13: 89 | N13: =B13/$B$26 -> 49.464354 | O13: =C13/$C$26 -> 0.14232487 | P13: =D13/D$26 -> 9.5791702 | Q13: =E13/E$26 -> 40.906749 | R13: =F13/F$26 -> 0.089583388 | S13: =G13/G$26 -> 0.021272085 | T13: =H13/H$26 -> 0.35096081 | U13: =I13/I$26 -> 0.038599227 | V13: =SUM(N13:U13) -> 100.59301 | Y13: 89 | Z13: 49.77 | AA13: 0.1457 | AB13: 9.54 | AC13: 40.18 | AD13: 0.0991 | AE13: 0.0215 | AF13: 0.3401 | AG13: 0.0389 | AH13: 100.1352 | AI13: SC-Olivine | AK13: 89 | AL13: =Z13/Z$26 -> 49.451759 | AM13: =AA13/AA$26 -> 0.14075352 | AN13: =AB13/AB$26 -> 9.5567193 | AO13: =AC13/AC$26 -> 40.89111 | AP13: =AD13/AD$26 -> 0.090206787 | AQ13: =AE13/AE$26 -> 0.022223134 | AR13: =AF13/AF$26 -> 0.35071628 | AS13: =AG13/AG$26 -> 0.039244879 | AT13: 100.1352 | AU13: SC-Olivine
A14: 90 | B14: 49.77 | C14: 0.1421 | D14: 9.48 | E14: 40.34 | F14: 0.102 | G14: 0.0193 | H14: 0.2834 | I14: 0.0308 | J14: 100.1675 | K14: SC-Olivine | M14: 90 | N14: =B14/$B$26 -> 49.464354 | O14: =C14/$C$26 -> 0.13880826 | P14: =D14/D$26 -> 9.5189238 | Q14: =E14/E$26 -> 41.069643 | R14: =F14/F$26 -> 0.0922049 | S14: =G14/G$26 -> 0.019095406 | T14: =H14/H$26 -> 0.29245015 | U14: =I14/I$26 -> 0.030561856 | V14: =SUM(N14:U14) -> 100.62604 | Y14: 90 | Z14: 49.77 | AA14: 0.1421 | AB14: 9.48 | AC14: 40.34 | AD14: 0.102 | AE14: 0.0193 | AF14: 0.2834 | AG14: 0.0308 | AH14: 100.1675 | AI14: SC-Olivine | AK14: 90 | AL14: =Z14/Z$26 -> 49.451759 | AM14: =AA14/AA$26 -> 0.13727574 | AN14: =AB14/AB$26 -> 9.4966141 | AO14: =AC14/AC$26 -> 41.053941 | AP14: =AD14/AD$26 -> 0.092846542 | AQ14: =AE14/AE$26 -> 0.019949139 | AR14: =AF14/AF$26 -> 0.29224638 | AS14: =AG14/AG$26 -> 0.031073066 | AT14: 100.1675 | AU14: SC-Olivine
A15: 91 | B15: 49.67 | C15: 0.1434 | D15: 9.37 | E15: 40.22 | F15: 0.1015 | G15: 0.0098 | H15: 0.3556 | I15: 0.0291 | J15: 99.8995 | K15: SC-Olivine | M15: 91 | N15: =B15/$B$26 -> 49.364968 | O15: =C15/$C$26 -> 0.14007815 | P15: =D15/D$26 -> 9.4084722 | Q15: =E15/E$26 -> 40.947473 | R15: =F15/F$26 -> 0.091752915 | S15: =G15/G$26 -> 0.0096961131 | T15: =H15/H$26 -> 0.36695579 | U15: =I15/I$26 -> 0.028875 | V15: =SUM(N15:U15) -> 100.35827 | Y15: 91 | Z15: 49.67 | AA15: 0.1434 | AB15: 9.37 | AC15: 40.22 | AD15: 0.1015 | AE15: 0.0098 | AF15: 0.3556 | AG15: 0.0291 | AH15: 99.8995 | AI15: SC-Olivine | AK15: 91 | AL15: =Z15/Z$26 -> 49.352399 | AM15: =AA15/AA$26 -> 0.1385316 | AN15: =AB15/AB$26 -> 9.3864213 | AO15: =AC15/AC$26 -> 40.931818 | AP15: =AD15/AD$26 -> 0.092391412 | AQ15: =AE15/AE$26 -> 0.010129614 | AR15: =AF15/AF$26 -> 0.36670011 | AS15: =AG15/AG$26 -> 0.029357994 | AT15: 99.8995 | AU15: SC-Olivine
... A18: 128 | B18: 49.47 | C18: 0.1408 | D18: 9.42 | E18: 41.28 | F18: 0.1042 | G18: 0.0152 | H18: 0.364 | I18: 0.0438 | J18: 100.8379 | K18: SC-Olivine | M18: 128 | N18: =B18/$B$26 -> 49.166196 | O18: =C18/$C$26 -> 0.13753838 | P18: =D18/D$26 -> 9.4586775 | Q18: =E18/E$26 -> 42.026645 | R18: =F18/F$26 -> 0.094193633 | S18: =G18/G$26 -> 0.015038869 | T18: =H18/H$26 -> 0.37562404 | U18: =I18/I$26 -> 0.04346134 | V18: =SUM(N18:U18) -> 101.31738 | Y18: 128 | Z18: 49.47 | AA18: 0.1408 | AB18: 9.42 | AC18: 41.28 | AD18: 0.1042 | AE18: 0.0152 | AF18: 0.364 | AG18: 0.0438 | AH18: 100.8379 | AI18: SC-Olivine | AK18: 128 | AL18: =Z18/Z$26 -> 49.153678 | AM18: =AA18/AA$26 -> 0.13601987 | AN18: =AB18/AB$26 -> 9.436509 | AO18: =AC18/AC$26 -> 42.010578 | AP18: =AD18/AD$26 -> 0.094849114 | AQ18: =AE18/AE$26 -> 0.015711239 | AR18: =AF18/AF$26 -> 0.37536232 | AS18: =AG18/AG$26 -> 0.044188322 | AT18: 100.8379 | AU18: SC-Olivine
A19: SRM SC-Ol | B19: 49.4299 | C19: 0.14 | D19: 9.5457 | E19: 40.8158 | F19: 0.092 | G19: 0.014 | H19: 0.37 | I19: 0.033 | M19: SRM SC-Ol | N19: 49.4299 | O19: 0.14 | P19: 9.5457 | Q19: 40.8158 | R19: 0.092 | S19: 0.014 | T19: 0.37 | U19: 0.033 | Y19: SRM SC-Ol | Z19: 49.4299 | AA19: 0.14 | AB19: 9.5457 | AC19: 40.8158 | AD19: 0.092 | AE19: 0.014 | AF19: 0.37 | AG19: 0.033 | AK19: SRM SC-Ol | AL19: 49.4299 | AM19: 0.14 | AN19: 9.5457 | AO19: 40.8158 | AP19: 0.092 | AQ19: 0.014 | AR19: 0.37 | AS19: 0.033
A21: Average | B21: =AVERAGE(B4:B12,B13:B18) -> 49.735333 | C21: =AVERAGE(C4:C18) -> 0.14332 | D21: =AVERAGE(D4:D18) -> 9.5066667 | E21: =AVERAGE(E4:E18) -> 40.090667 | F21: =AVERAGE(F4:F18) -> 0.10177333 | G21: =AVERAGE(G5:G18) -> 0.01415 | H21: =AVERAGE(H4:H13,H15:H18) -> 0.35855 | I21: =AVERAGE(I4:I17) -> 0.033257143 | Y21: Average | Z21: =AVERAGE(Z4:Z5,Z7:Z8,Z10:Z11,Z13:Z14,Z16:Z17) -> 49.748 | AA21: =AVERAGE(AA4:AA5,AA7:AA8,AA10:AA11,AA13:AA14,AA16:AA17) -> 0.14492 | AB21: =AVERAGE(AB4:AB5,AB7:AB8,AB10:AB11,AB13:AB14,AB16:AB17) -> 9.529 | AC21: =AVERAGE(AC4:AC5,AC7:AC8,AC10:AC11,AC13:AC14,AC16:AC17) -> 40.106 | AD21: =AVERAGE(AD4:AD5,AD7:AD8,AD10:AD11,AD13:AD14,AD16:AD17) -> 0.10107 | AE21: =AVERAGE(AE5,AE7:AE8,AE10:AE11,AE13:AE14,AE16:AE17) -> 0.013544444 | AF21: =AVERAGE(AF4:AF5,AF7:AF8,AF10:AF11,AF13,AF16:AF17) -> 0.3588 | AG21: =AVERAGE(AG4:AG5,AG7:AG8,AG10:AG11,AG13:AG14,AG16:AG17) -> 0.03271 | AK21: Average Train | AL21: =AVERAGE(AL4:AL5,AL7:AL8,AL10:AL11,AL13:AL14,AL16:AL17) -> 49.4299 | AM21: =AVERAGE(AM4:AM5,AM7:AM8,AM10:AM11,AM13:AM14,AM16:AM17) -> 0.14 | AN21: =AVERAGE(AN4:AN5,AN7:AN8,AN10:AN11,AN13:AN14,AN16:AN17) -> 9.5457 | AO21: =AVERAGE(AO4:AO5,AO7:AO8,AO10:AO11,AO13:AO14,AO16:AO17) -> 40.8158 | AP21: =AVERAGE(AP4:AP5,AP7:AP8,AP10:AP11,AP13:AP14,AP16:AP17) -> 0.092 | AQ21: =AVERAGE(AQ5,AQ7:AQ8,AQ10:AQ11,AQ13:AQ14,AQ16:AQ17) -> 0.014 | AR21: =AVERAGE(AR4:AR5,AR7:AR8,AR10:AR11,AR13,AR16:AR17) -> 0.37 | AS21: =AVERAGE(AS4:AS5,AS7:AS8,AS10:AS11,AS13:AS14,AS16:AS17) -> 0.033
A22: StdDev | B22: =STDEV(B4:B18) -> 0.14317156 | C22: =STDEV(C4:C18) -> 0.0042340794 | D22: =STDEV(D4:D18) -> 0.070474582 | E22: =STDEV(E4:E18) -> 0.62826822 | F22: =STDEV(F4:F18) -> 0.0020182973 | G22: =STDEV(G5:G18) -> 0.0049297761 | H22: =STDEV(H4:H13,H15:H18) -> 0.011582065 | I22: =STDEV(I4:I17) -> 0.0028944813 | Y22: StdDev | Z22: =STDEV(Z4:Z11,Z13:Z18) -> 0.11333118 | AA22: =STDEV(AA4:AA18) -> 0.0042340794 | AB22: =STDEV(AB4:AB18) -> 0.070474582 | AC22: =STDEV(AC4:AC18) -> 0.62826822 | AD22: =STDEV(AD4:AD18) -> 0.0020182973 | AE22: =STDEV(AE5:AE18) -> 0.0049297761 | AF22: =STDEV(AF4:AF13,AF15:AF18) -> 0.011582065 | AG22: =STDEV(AG4:AG17) -> 0.0028944813 | AK22: Average Test | AL22: =AVERAGE(AL6,AL9,AL12,AL15,AL18) -> 49.392143 | AM22: =AVERAGE(AM6,AM9,AM12,AM15,AM18) -> 0.13536296 | AN22: =AVERAGE(AN6,AN9,AN12,AN15,AN18) -> 9.4785826 | AO22: =AVERAGE(AO6,AO9,AO12,AO15,AO18) -> 40.768986 | AP22: =AVERAGE(AP6,AP9,AP12,AP15,AP18) -> 0.093920649 | AQ22: =AVERAGE(AQ6,AQ9,AQ12,AQ15,AQ18) -> 0.015752584 | AR22: =AVERAGE(AR6,AR9,AR12,AR15,AR18) -> 0.36927815 | AS22: =AVERAGE(AS6,AS9,AS12,AS15) -> 0.034931978
A23: 2SIG | B23: =2*B22 -> 0.28634312 | C23: =2*C22 -> 0.0084681588 | D23: =2*D22 -> 0.14094916 | E23: =2*E22 -> 1.2565364 | F23: =2*F22 -> 0.0040365945 | G23: =2*G22 -> 0.0098595522 | H23: =2*H22 -> 0.02316413 | I23: =2*I22 -> 0.0057889626 | AK23: StdDev | AL23: =STDEV(AL4:AL11,AL13:AL18) -> 0.11260651 | AM23: =STDEV(AM4:AM18) -> 0.0040903334 | AN23: =STDEV(AN4:AN18) -> 0.070598092 | AO23: =STDEV(AO4:AO18) -> 0.63938737 | AP23: =STDEV(AP4:AP18) -> 0.0018371757 | AQ23: =STDEV(AQ5:AQ18) -> 0.0050955848 | AR23: =STDEV(AR4:AR13,AR15:AR18) -> 0.011943601 | AS23: =STDEV(AS4:AS17) -> 0.0029201432
A24: Accuracy | B24: 0.0007638498 | C24: 0.033121722 | D24: 0.007031168 | E24: 0.0011469606 | F24: 0.02087662 | G24: 0.12518458 | H24: 0.0019509476 | I24: 0.058544788 | AK24: Accuracy | AL24: =ABS(AL22-AL19)/AL19 -> 0.0007638498 | AM24: =ABS(AM22-AM19)/AM19 -> 0.033121722 | AN24: =ABS(AN22-AN19)/AN19 -> 0.007031168 | AO24: =ABS(AO22-AO19)/AO19 -> 0.0011469606 | AP24: =ABS(AP22-AP19)/AP19 -> 0.02087662 | AQ24: =ABS(AQ22-AQ19)/AQ19 -> 0.12518458 | AR24: =ABS(AR22-AR19)/AR19 -> 0.0019509476 | AS24: =ABS(AS22-AS19)/AS19 -> 0.058544788
A25: RSD | B25: =B23/B21 -> 0.0057573379 | C25: =C23/C21 -> 0.059085674 | D25: =D23/D21 -> 0.01482635 | E25: =E23/E21 -> 0.031342368 | F25: =F23/F21 -> 0.039662595 | G25: =G23/G21 -> 0.69678814 | H25: =H23/H21 -> 0.06460502 | I25: =I23/I21 -> 0.17406674
A26: CorrFactor | B26: =B21/B19 -> 1.0061791 | C26: =C21/C19 -> 1.0237143 | D26: =D21/D19 -> 0.9959109 | E26: =E21/E19 -> 0.982234 | F26: =F21/F19 -> 1.1062319 | G26: =G21/G19 -> 1.0107143 | H26: =H21/H19 -> 0.96905405 | I26: =I21/I19 -> 1.0077922 | Y26: CorrFactor | Z26: =Z21/Z19 -> 1.0064354 | AA26: =AA21/AA19 -> 1.0351429 | AB26: =AB21/AB19 -> 0.99825052 | AC26: =AC21/AC19 -> 0.98260968 | AD26: =AD21/AD19 -> 1.098587 | AE26: =AE21/AE19 -> 0.96746032 | AF26: =AF21/AF19 -> 0.96972973 | AG26: =AG21/AG19 -> 0.99121212

Sheet Fa-Fo Ratios
A2: Ratios | B2: Group : Olivine | C2: Sample : 010317Fr | D2: Page | E2: 1
A4: No. | B4: Fo+M | C4: Fa+M | D4: Total | E4: Comment
A5: 1 | B5: 90.2772 | C5: 9.7228 | D5: =SUM(B5:C5) -> 100 | E5: SC-Olivine
A6: 2 | B6: 90.2076 | C6: 9.7925 | D6: =SUM(B6:C6) -> 100.0001 | E6: SC-Olivine
A7: 3 | B7: 90.3021 | C7: 9.6979 | D7: =SUM(B7:C7) -> 100 | E7: SC-Olivine
A8: 4 | B8: 84.9758 | C8: 15.0242 | D8: =SUM(B8:C8) -> 100 | E8: UnkA-C20-S2-1MI_1_1
A9: 5 | B9: 84.558 | C9: 15.442 | D9: =SUM(B9:C9) -> 100 | E9: UnkA-C20-S2-1MI_1_2
A10: 6 | B10: 85.5647 | C10: 14.4353 | D10: =SUM(B10:C10) -> 100 | E10: UnkA-C20-S2-1MI_1_3
A11: 7 | B11: 83.9524 | C11: 16.0476 | D11: =SUM(B11:C11) -> 100 | E11: UnkA-C20-S2-1MI_2_1
A12: 8 | B12: 84.0273 | C12: 15.9727 | D12: =SUM(B12:C12) -> 100 | E12: UnkA-C20-S2-1MI_2_2
A13: 9 | B13: 83.7606 | C13: 16.2394 | D13: =SUM(B13:C13) -> 100 | E13: UnkA-C20-S2-1MI_2_3
A14: 10 | B14: 86.844 | C14: 13.1559 | D14: =SUM(B14:C14) -> 99.9999 | E14: UnkA-C20-S2-1MI_3_1
A15: 11 | B15: 86.6617 | C15: 13.3383 | D15: =SUM(B15:C15) -> 100 | E15: UnkA-C20-S2-1MI_3_2
A16: 12 | B16: 86.7473 | C16: 13.2527 | D16: =SUM(B16:C16) -> 100 | E16: UnkA-C20-S2-1MI_3_3
... A132: 128 | B132: 90.3432 | C132: 9.6568 | D132: =SUM(B132:C132) -> 100 | E132: SC-Olivine
A134: Minimum | B134: 78.6713 | C134: 9.5664 | D134: 100
A135: Maximum | B135: 90.4336 | C135: 21.3287 | D135: 100
A136: Average | B136: 83.7741 | C136: 16.2259 | D136: 100
A137: Sigma | B137: 3.4485 | C137: 3.4485 | D137: 0
A138: No. of data 128

Sheet Elements
A2: Mole% | B2: Group : Olivine | C2: Sample : 010317Fr | D2: Page | E2: 1
A4: No. | B4: Mg | C4: Mn | D4: Fe | E4: Si | F4: Ca | G4: Cr | H4: Ni | I4: Al | J4: Total | K4: Comment
A5: 1 | B5: 60.5853 | C5: 0.1022 | D5: 6.5276 | E5: 32.4289 | F5: 0.0896 | G5: 0.01 | H5: 0.2411 | I5: 0.0152 | J5: 100 | K5: SC-Olivine
A6: 2 | B6: 60.4845 | C6: 0.0978 | D6: 6.568 | E6: 32.4924 | F6: 0.0856 | G6: 0.0052 | H6: 0.2504 | I6: 0.0159 | J6: 100 | K6: SC-Olivine
A7: 3 | B7: 60.569 | C7: 0.0999 | D7: 6.5085 | E7: 32.4805 | F7: 0.0912 | G7: 0.0058 | H7: 0.2286 | I7: 0.0166 | J7: 100 | K7: SC-Olivine
A8: 4 | B8: 57.0621 | C8: 0.1706 | D8: 10.089 | E8: 32.1971 | F8: 0.3152 | G8: 0.0117 | H8: 0.1366 | I8: 0.0176 | J8: 100 | K8: UnkA-C20-S2-1MI_1_1
A9: 5 | B9: 56.8465 | C9: 0.1821 | D9: 10.3775 | E9: 32.1218 | F9: 0.3154 | G9: 0.008 | H9: 0.1319 | I9: 0.0167 | J9: 100 | K9: UnkA-C20-S2-1MI_1_2
A10: 6 | B10: 56.988 | C10: 0.1545 | D10: 9.6123 | E10: 32.7878 | F10: 0.298 | G10: 0.0087 | H10: 0.1387 | I10: 0.0121 | J10: 100 | K10: UnkA-C20-S2-1MI_1_3
A11: 7 | B11: 55.5804 | C11: 0.1759 | D11: 10.6253 | E11: 33.1716 | F11: 0.3035 | G11: 0.0058 | H11: 0.1203 | I11: 0.0172 | J11: 100 | K11: UnkA-C20-S2-1MI_2_1
A12: 8 | B12: 56.3243 | C12: 0.1798 | D12: 10.7067 | E12: 32.3249 | F12: 0.3103 | G12: 0.0037 | H12: 0.1308 | I12: 0.0194 | J12: 100 | K12: UnkA-C20-S2-1MI_2_2
A13: 9 | B13: 55.7257 | C13: 0.1752 | D13: 10.8007 | E13: 32.8366 | F13: 0.3032 | G13: 0.0016 | H13: 0.1328 | I13: 0.0242 | J13: 100 | K13: UnkA-C20-S2-1MI_2_3
A14: 10 | B14: 58.2993 | C14: 0.1446 | D14: 8.8304 | E14: 32.2379 | F14: 0.3179 | G14: 0.0137 | H14: 0.1343 | I14: 0.022 | J14: 100 | K14: UnkA-C20-S2-1MI_3_1
A15: 11 | B15: 58.1893 | C15: 0.1526 | D15: 8.9574 | E15: 32.2222 | F15: 0.3153 | G15: 0.0104 | H15: 0.1411 | I15: 0.0118 | J15: 100 | K15: UnkA-C20-S2-1MI_3_2
A16: 12 | B16: 57.6414 | C16: 0.1447 | D16: 8.8015 | E16: 32.9337 | F16: 0.3096 | G16: 0.0141 | H16: 0.1384 | I16: 0.0166 | J16: 100 | K16: UnkA-C20-S2-1MI_3_3
... A132: 128 | B132: 59.7325 | C132: 0.0966 | D132: 6.3812 | E132: 33.4363 | F132: 0.0904 | G132: 0.0049 | H132: 0.2371 | I132: 0.0209 | J132: 100 | K132: SC-Olivine
A134: Minimum | B134: 52.2263 | C134: 0.0935 | D134: 6.3758 | E134: 32.0483 | F134: 0.0856 | G134: 0 | H134: 0.0612 | I134: 0.0093 | J134: 100
A135: Maximum | B135: 60.7696 | C135: 0.2679 | D135: 14.2998 | E135: 33.4363 | F135: 0.3585 | G135: 0.0223 | H135: 0.2504 | I135: 0.0242 | J135: 100
A136: Average | B136: 55.8069 | C136: 0.1917 | D136: 10.8049 | E136: 32.7636 | F136: 0.2827 | G136: 0.0054 | H136: 0.1299 | I136: 0.015 | J136: 100
A137: Sigma | B137: 2.4019 | C137: 0.051 | D137: 2.2869 | E137: 0.3762 | F137: 0.0752 | G137: 0.0043 | H137: 0.0448 | I137: 0.0028 | J137: 0
A138: No. of data 128

Sheet Standard Conditions
A2: ==============================================================================
A3: | | B3: CITZAF | C3: |
A4: | | B4: Copyright, | C4: John | D4: T. | E4: Armstrong, | F4: California | G4: Institute | H4: of | I4: Technology | J4: |
A5: | | B5: JEOL | C5: On-line | D5: type | E5: Implemented | F5: by | G5: Paul | H5: Carpenter | I5: Caltech | J5: 1993 | K5: |
A6: | | B6: JEOL | C6: License | D6: of | E6: CITZAF | F6: Version: | G6: 3.5 | H6: |
A7: ==============================================================================
A10: Measurement | B10: Condition
A11: WDS elements
A12: Element | B12: X-ray | C12: Crystal | D12: CH | E12: Acc.v | F12: Peak | G12: Pos. | H12: (nm) | I12: BG_L | J12: BG_U | K12: (mm)
A13: 1 | B13: Mg | C13: Ka | D13: TAPH | E13: ( | F13: 1) | G13: 15 | H13: 107.54 | I13: 0.989 | J13: 5.2 | K13: 5.2
A14: 2 | B14: Mn | C14: Ka | D14: LIFH | E14: ( | F14: 2) | G14: 15 | H14: 146.037 | I14: 0.21018 | J14: 2 | K14: 2.5
A15: 3 | B15: Fe | C15: Ka | D15: LIF | E15: ( | F15: 3) | G15: 15 | H15: 134.743 | I15: 0.1936 | J15: 0 | K15: 2
A16: 4 | B16: Si | C16: Ka | D16: TAP | E16: ( | F16: 4) | G16: 15 | H16: 77.808 | I16: 0.71254 | J16: 6 | K16: 6
A17: 5 | B17: Ca | C17: Ka | D17: PETH | E17: ( | F17: 5) | G17: 15 | H17: 107.775 | I17: 0.33584 | J17: 2.3 | K17: 3
A18: 6 | B18: Cr | C18: Ka | D18: LIFH | E18: ( | F18: 2) | G18: 15 | H18: 159.16 | I18: 0.22897 | J18: 0.712 | K18: 0.688
A19: 7 | B19: Ni | C19: Ka | D19: LIF | E19: ( | F19: 3) | G19: 15 | H19: 115.415 | I19: 0.16579 | J19: 2 | K19: 2
A20: 8 | B20: Al | C20: Ka | D20: TAP | E20: ( | F20: 4) | G20: 15 | H20: 90.986 | I20: 0.83393 | J20: 1.5 | K20: 2
A22: Element | B22: Peak | C22: Back | D22: Pksk | E22: Gain | F22: High.V | G22: Base.L | H22: Window.W | I22: Mode
A23: 1 | B23: Mg | C23: 20 | D23: 10 | E23: (s) | F23: 1 | G23: 32 | H23: 1726 | I23: 0.2 | J23: 0 | K23: (V) | L23: Int
A24: 2 | B24: Mn | C24: 60 | D24: 30 | E24: (s) | F24: 1 | G24: 64 | H24: 1696 | I24: 0.2 | J24: 0 | K24: (V) | L24: Int
A25: 3 | B25: Fe | C25: 20 | D25: 10 | E25: (s) | F25: 1 | G25: 32 | H25: 1732 | I25: 0.5 | J25: 0 | K25: (V) | L25: Int
A26: 4 | B26: Si | C26: 20 | D26: 10 | E26: (s) | F26: 1 | G26: 32 | H26: 1678 | I26: 0.2 | J26: 9.8 | K26: (V) | L26: Dif
A27: 5 | B27: Ca | C27: 60 | D27: 30 | E27: (s) | F27: 1 | G27: 64 | H27: 1718 | I27: 0.7 | J27: 0 | K27: (V) | L27: Int
A28: 6 | B28: Cr | C28: 30 | D28: 15 | E28: (s) | F28: 1 | G28: 64 | H28: 1708 | I28: 0.2 | J28: 0 | K28: (V) | L28: Int
A29: 7 | B29: Ni | C29: 60 | D29: 30 | E29: (s) | F29: 1 | G29: 32 | H29: 1732 | I29: 0.7 | J29: 0 | K29: (V) | L29: Int
A30: 8 | B30: Al | C30: 40 | D30: 20 | E30: (s) | F30: 1 | G30: 32 | H30: 1732 | I30: 0.7 | J30: 0 | K30: (V) | L30: Int
A32: Measurement | B32: Order | C32: of | D32: WDS
A33: Order | B33: Channel | C33: 1 | D33: 2 | E33: 3 | F33: 4 | G33: 5
A34: 1 | B34: Mg1TH | C34: Mn2LH | D34: Fe3L | E34: Si4T | F34: Ca5PH
A35: 2 | B35: 0 | C35: Cr2LH | D35: Ni3L | E35: Al4T | F35: 0
A37: Calc. | B37: Elements | C37: : | D37: O | E37: (Anion)
A39: Standard Data
A40: Element | B40: Standard name | C40: Mass(%)
A41: 1 | B41: MgO | C41: SC-Olivine | D41: 49.4299
A42: 2 | B42: MnO | C42: Rhodonite | D42: 43.4885
A43: 3 | B43: FeO | C43: SC-Olivine | D43: 9.5457
A44: 4 | B44: SiO2 | C44: SC-Olivine | D44: 40.8158
A45: 5 | B45: CaO | C45: Wollastonite | D45: 47.7408
A46: 6 | B46: Cr2O3 | C46: Cr2O3 | D46: 99.9985
A47: 7 | B47: NiO | C47: NiO | D47: 99.9951
...

Sheet AllData
A1: ql
A2: Intensity & Mass% Group : Olivine Sample : 010317Fr Page 1
A7: Unknown Specimen No. 1
A8: Group : Olivine Sample : 010317Fr
A9: UNK No. : 1 Comment : SC-Olivine
A10: Stage : X= 17.1570 Y= 25.6005 Z= 11.6455
A11: Acc. Voltage : 15.0 (kV) Probe Dia. : 0 Scan : Off
A12: Dated on Mar 2 02:12 2017
A13: WDS only No. of accumulation : 1
A15: Curr.(A) : 9.833E-08
A16: Element Peak(mm) Net(cps) Bg- Bg+ S.D.(%) D.L.(ppm)
A17: 1 Mg 107.540 65873.2 299.4 243.4 0.09 39
... A5852: Total: 100.85 100.85 100.00 100.00 17.984

Sheet Bgls_std-cnd
A2: ==============================================================================
A3: | | B3: CITZAF | C3: |
A4: | | B4: Copyright, | C4: John | D4: T. | E4: Armstrong, | F4: California | G4: Institute | H4: of | I4: Technology | J4: |
A5: | | B5: JEOL | C5: On-line | D5: type | E5: Implemented | F5: by | G5: Paul | H5: Carpenter | I5: Caltech | J5: 1993 | K5: |
A6: | | B6: JEOL | C6: License | D6: of | E6: CITZAF | F6: Version: | G6: 3.5 | H6: |
A7: ==============================================================================
A10: Measurement | B10: Condition
A11: WDS elements
A12: Element | B12: X-ray | C12: Crystal | D12: CH | E12: Acc.v | F12: Peak | G12: Pos. | H12: (nm) | I12: BG_L | J12: BG_U | K12: (mm)
A13: 1 | B13: Na | C13: Ka | D13: TAPH | E13: ( | F13: 1) | G13: 15 | H13: 129.476 | I13: 1.19101 | J13: 0 | K13: 1.1
A14: 2 | B14: S | C14: Ka | D14: PETH | E14: ( | F14: 2) | G14: 15 | H14: 171.948 | I14: 0.53722 | J14: 2.14 | K14: 1.5
A15: 3 | B15: Fe | C15: Ka | D15: LIF | E15: ( | F15: 3) | G15: 15 | H15: 134.739 | I15: 0.1936 | J15: 3.1 | K15: 1.5
A16: 4 | B16: Si | C16: Ka | D16: TAP | E16: ( | F16: 4) | G16: 15 | H16: 77.822 | I16: 0.71254 | J16: 2.4 | K16: 3.3
A17: 5 | B17: Cl | C17: Ka | D17: PETH | E17: ( | F17: 5) | G17: 15 | H17: 151.478 | I17: 0.47278 | J17: 1.7 | K17: 1.5
A18: 6 | B18: F | C18: Ka | D18: TAPH | E18: ( | F18: 1) | G18: 15 | H18: 199.129 | I18: 1.832 | J18: 2 | K18: 3.25
A19: 7 | B19: K | C19: Ka | D19: PETH | E19: ( | F19: 2) | G19: 15 | H19: 119.485 | I19: 0.37414 | J19: 0.942 | K19: 1.238
A20: 8 | B20: Mn | C20: Ka | D20: LIF | E20: ( | F20: 3) | G20: 15 | H20: 146.243 | I20: 0.21018 | J20: 2.2 | K20: 1.7
A21: 9 | B21: Al | C21: Ka | D21: TAP | E21: ( | F21: 4) | G21: 15 | H21: 90.995 | I21: 0.83393 | J21: 2.64 | K21: 3.1
A22: 10 | B22: P | C22: Ka | D22: PETH | E22: ( | F22: 5) | G22: 15 | H22: 197.118 | I22: 0.6157 | J22: 2 | K22: 1.2
A23: 11 | B23: Mg | C23: Ka | D23: TAPH | E23: ( | F23: 1) | G23: 15 | H23: 107.534 | I23: 0.989 | J23: 1.701 | K23: 0
A24: 12 | B24: Ca | C24: Ka | D24: PETH | E24: ( | F24: 2) | G24: 15 | H24: 107.121 | I24: 0.33584 | J24: 1.8 | K24: 1.3
A25: 13 | B25: Ti | C25: Ka | D25: PETH | E25: ( | F25: 5) | G25: 15 | H25: 88.305 | I25: 0.27485 | J25: 0 | K25: 1.3
A27: Element | B27: Peak | C27: Back | D27: Pksk | E27: Gain | F27: High.V | G27: Base.L | H27: Window.W | I27: Mode
A28: 1 | B28: Na | C28: 10 | D28: 10 | E28: (s) | F28: 1 | G28: 32 | H28: 1732 | I28: 0.7 | J28: 0 | K28: (V) | L28: Int
A29: 2 | B29: S | C29: 30 | D29: 15 | E29: (s) | F29: 1 | G29: 128 | H29: 1708 | I29: 0.7 | J29: 0 | K29: (V) | L29: Int
A30: 3 | B30: Fe | C30: 20 | D30: 10 | E30: (s) | F30: 1 | G30: 32 | H30: 1728 | I30: 0.7 | J30: 0 | K30: (V) | L30: Int
A31: 4 | B31: Si | C31: 20 | D31: 10 | E31: (s) | F31: 1 | G31: 32 | H31: 1680 | I31: 0.2 | J31: 0 | K31: (V) | L31: Int
A32: 5 | B32: Cl | C32: 30 | D32: 15 | E32: (s) | F32: 1 | G32: 64 | H32: 1714 | I32: 0.7 | J32: 0 | K32: (V) | L32: Int
A33: 6 | B33: F | C33: 30 | D33: 15 | E33: (s) | F33: 1 | G33: 32 | H33: 1748 | I33: 0.7 | J33: 0 | K33: (V) | L33: Int
A34: 7 | B34: K | C34: 30 | D34: 15 | E34: (s) | F34: 1 | G34: 64 | H34: 1738 | I34: 0.7 | J34: 0 | K34: (V) | L34: Int
A35: 8 | B35: Mn | C35: 30 | D35: 15 | E35: (s) | F35: 1 | G35: 32 | H35: 1734 | I35: 0.7 | J35: 0 | K35: (V) | L35: Int
A36: 9 | B36: Al | C36: 20 | D36: 10 | E36: (s) | F36: 1 | G36: 32 | H36: 1694 | I36: 0.2 | J36: 0 | K36: (V) | L36: Int
A37: 10 | B37: P | C37: 20 | D37: 10 | E37: (s) | F37: 1 | G37: 64 | H37: 1746 | I37: 0.7 | J37: 0 | K37: (V) | L37: Int
A38: 11 | B38: Mg | C38: 20 | D38: 10 | E38: (s) | F38: 1 | G38: 32 | H38: 1710 | I38: 0.7 | J38: 0 | K38: (V) | L38: Int
A39: 12 | B39: Ca | C39: 20 | D39: 10 | E39: (s) | F39: 1 | G39: 64 | H39: 1734 | I39: 0.7 | J39: 0 | K39: (V) | L39: Int
A40: 13 | B40: Ti | C40: 20 | D40: 10 | E40: (s) | F40: 1 | G40: 64 | H40: 1676 | I40: 0.7 | J40: 0 | K40: (V) | L40: Int
A42: Measurement | B42: Order | C42: of | D42: WDS
A43: Order | B43: Channel | C43: 1 | D43: 2 | E43: 3 | F43: 4 | G43: 5
A44: 1 | B44: Na1TH | C44: S2PH | D44: Fe3L | E44: Si4T | F44: Cl5PH
A45: 2 | B45: F1T | C45: K2PH | D45: Mn3L | E45: Al4T | F45: P5PH
...

Sheet Bgls_oxides
A2: Mass percent | B2: Group : bas-Glas | C2: Sample : 201216_Fr | D2: Page | E2: 1
A4: No. | B4: Na2O | C4: SO3 | D4: FeO | E4: SiO2 | F4: Cl | G4: F | H4: K2O | I4: MnO | J4: Al2O3 | K4: P2O5 | L4: MgO | M4: CaO | N4: TiO2 | O4: Total | P4: Comment
A5: 1 | B5: 2.8 | C5: 0.0408 | D5: 13.6 | E5: 51.16 | F5: 0.0237 | G5: 0.0126 | H5: 0.8138 | I5: 0.1786 | J5: 12.3 | K5: 0.3881 | L5: 5.13 | M5: 9.27 | N5: 4.08 | O5: 99.7976 | P5: VGA99_
A6: 2 | B6: 2.7 | C6: 0.0232 | D6: 13.46 | E6: 51.24 | F6: 0.03 | G6: 0.0791 | H6: 0.8142 | I6: 0.2468 | J6: 12.48 | K6: 0.3543 | L6: 5.2 | M6: 9.37 | N6: 4.06 | O6: 100.0575 | P6: VGA99_
A7: 3 | B7: 2.69 | C7: 0.3666 | D7: 11.76 | E7: 51.66 | F7: 0.0331 | G7: 0.0693 | H7: 0.1994 | I7: 0.2396 | J7: 14.03 | K7: 0.1729 | L7: 7.04 | M7: 11.38 | N7: 1.82 | O7: 101.4608 | P7: VG-2_
A8: 4 | B8: 2.6 | C8: 0.3591 | D8: 12.1 | E8: 51.6 | F8: 0.0346 | G8: 0.0702 | H8: 0.1893 | I8: 0.2448 | J8: 14.04 | K8: 0.1601 | L8: 7.17 | M8: 11.31 | N8: 1.85 | O8: 101.728 | P8: VG-2_
A9: 5 | B9: 6.21 | C9: 0.0261 | D9: 7.86 | E9: 70.77 | F9: 0.3989 | G9: 0.4579 | H9: 4.29 | I9: 0.1916 | J9: 8.83 | K9: 0.0161 | L9: 0.0224 | M9: 0.396 | N9: 0.3392 | O9: 99.8083 | P9: KE3_
A10: 6 | B10: 2.36 | C10: 0.0348 | D10: 8 | E10: 72.72 | F10: 0.3848 | G10: 0.5147 | H10: 4.16 | I10: 0.2905 | J10: 8.85 | K10: 0.0147 | L10: 0.0417 | M10: 0.4585 | N10: 0.3403 | O10: 98.1701 | P10: KE3_
A11: 7 | B11: 5.35 | C11: 1.392 | D11: 0.1958 | E11: 51.04 | F11: 1.45 | G11: 0.0068 | H11: 0.8437 | I11: 0.0059 | J11: 25.88 | K11: 0.0203 | L11: 0 | M11: 13.88 | N11: 0.0025 | O11: 100.0669 | P11: Scap
A12: 8 | B12: 5.19 | C12: 1.3602 | D12: 0.0852 | E12: 50.95 | F12: 1.42 | G12: 0 | H12: 0.8733 | I12: 0.035 | J12: 25.46 | K12: 0.0014 | L12: 0.002 | M12: 14.02 | N12: 0.0129 | O12: 99.41 | P12: Scap
A13: 9 | B13: 2.65 | C13: 0.0175 | D13: 13.79 | E13: 46 | F13: 0.1143 | G13: 0.1165 | H13: 1.75 | I13: 0.2421 | J13: 14.9 | K13: 0.6354 | L13: 5.07 | M13: 11.22 | N13: 4 | O13: 100.5058 | P13: 1982-CS2-L3A_1
A14: 10 | B14: 2.59 | C14: 0.0165 | D14: 13.75 | E14: 45.97 | F14: 0.1074 | G14: 0.16 | H14: 1.77 | I14: 0.22 | J14: 14.99 | K14: 0.6266 | L14: 5.08 | M14: 11.12 | N14: 3.9 | O14: 100.3005 | P14: 1982-CS2-L3A_2
A15: 11 | B15: 2.9 | C15: 0.0292 | D15: 13.49 | E15: 45.63 | F15: 0.1246 | G15: 0.1055 | H15: 1.83 | I15: 0.2252 | J15: 15.01 | K15: 0.6494 | L15: 5.07 | M15: 11.16 | N15: 3.9 | O15: 100.1238 | P15: 1982-CS2-L3A_3
A16: 12 | B16: 2.65 | C16: 0.0435 | D16: 13.63 | E16: 46.2 | F16: 0.1232 | G16: 0.1241 | H16: 1.58 | I16: 0.22 | J16: 14.93 | K16: 0.5646 | L16: 5.17 | M16: 11.22 | N16: 3.99 | O16: 100.4453 | P16: 1982-CS2-L3A_4
... A109: 105 | B109: 5.11 | C109: 1.2951 | D109: 0.1009 | E109: 50.75 | F109: 1.43 | G109: 0.0152 | H109: 0.8404 | I109: 0.0535 | J109: 25.77 | K109: 0.0163 | L109: 0.0091 | M109: 14.05 | N109: 0.0158 | O109: 99.4564 | P109: Scap
A111: Minimum | B111: 0.4033 | C111: 0 | D111: 0.0852 | E111: 43.89 | F111: 0.0022 | G111: 0 | H111: 0.0011 | I111: 0.0059 | J111: 6.4 | K111: 0 | L111: 0 | M111: 0.396 | N111: 0 | O111: 98.17
A112: Maximum | B112: 8.61 | C112: 2.1971 | D112: 15.38 | E112: 72.72 | F112: 1.45 | G112: 0.5147 | H112: 4.29 | I112: 0.3318 | J112: 25.88 | K112: 1.3786 | L112: 13.83 | M112: 23.28 | N112: 4.15 | O112: 102.4754
A113: Average | B113: 4.1327 | C113: 0.1579 | D113: 11.6441 | E113: 48.3233 | F113: 0.203 | G113: 0.1309 | H113: 1.6967 | I113: 0.2048 | J113: 15.2716 | K113: 0.6177 | L113: 4.5776 | M113: 10.594 | N113: 3.0672 | O113: 100.6216
A114: Sigma | B114: 1.1731 | C114: 0.3713 | D114: 3.2989 | E114: 6.0513 | F114: 0.3215 | G114: 0.1071 | H114: 0.8736 | I114: 0.0603 | J114: 3.2527 | K114: 0.3341 | L114: 1.9942 | M114: 3.0563 | N114: 1.1579 | O114: 0.8623
A115: No. of data 105

Sheet Bgls_all
A2: Intensity & Mass% Group : bas-Glas Sample : 201216_Fr Page 1
A7: Unknown Specimen No. 1
A8: Group : bas-Glas Sample : 201216_Fr
A9: UNK No. : 1 Comment : VGA99_
A10: Stage : X= 42.5705 Y= 29.7320 Z= 11.4010
A11: Acc. Voltage : 15.0 (kV) Probe Dia. : 5 Scan : Off
A12: Dated on Dec 20 16:18 2016
A13: WDS only No. of accumulation : 1
A15: Curr.(A) : 1.002E-08
A16: Element Peak(mm) Net(cps) Bg- Bg+ S.D.(%) D.L.(ppm)
A17: 1 Na 129.476 231.6 0.0 14.5 2.14 145
A18: 2 S 171.948 2.1 5.9 4.9 30.75 113
... A6384: Total: 99.45 99.45 100.00 100.00 15.571
