Workbook

Sheet Bgls_std-cnd
A2: ==============================================================================
A3: | | B3: CITZAF | C3: |
A4: | | B4: Copyright, | C4: John | D4: T. | E4: Armstrong, | F4: California | G4: Institute | H4: of | I4: Technology | J4: |
A5: | | B5: JEOL | C5: On-line | D5: type | E5: Implemented | F5: by | G5: Paul | H5: Carpenter | I5: Caltech | J5: 1993 | K5: |
A6: | | B6: JEOL | C6: License | D6: of | E6: CITZAF | F6: Version: | G6: 3.5 | H6: |
A7: ==============================================================================
A10: Measurement | B10: Condition
A11: WDS elements
A12: Element | B12: X-ray | C12: Crystal | D12: CH | E12: Acc.v | F12: Peak | G12: Pos. | H12: (nm) | I12: BG_L | J12: BG_U | K12: (mm)
A13: 1 | B13: Na | C13: Ka | D13: TAPH | E13: ( | F13: 1) | G13: 15 | H13: 129.476 | I13: 1.19101 | J13: 0 | K13: 1.1
A14: 2 | B14: S | C14: Ka | D14: PETH | E14: ( | F14: 2) | G14: 15 | H14: 171.948 | I14: 0.53722 | J14: 2.14 | K14: 1.5
A15: 3 | B15: Fe | C15: Ka | D15: LIF | E15: ( | F15: 3) | G15: 15 | H15: 134.739 | I15: 0.1936 | J15: 3.1 | K15: 1.5
A16: 4 | B16: Si | C16: Ka | D16: TAP | E16: ( | F16: 4) | G16: 15 | H16: 77.822 | I16: 0.71254 | J16: 2.4 | K16: 3.3
A17: 5 | B17: Cl | C17: Ka | D17: PETH | E17: ( | F17: 5) | G17: 15 | H17: 151.478 | I17: 0.47278 | J17: 1.7 | K17: 1.5
A18: 6 | B18: F | C18: Ka | D18: TAPH | E18: ( | F18: 1) | G18: 15 | H18: 199.129 | I18: 1.832 | J18: 2 | K18: 3.25
A19: 7 | B19: K | C19: Ka | D19: PETH | E19: ( | F19: 2) | G19: 15 | H19: 119.485 | I19: 0.37414 | J19: 0.942 | K19: 1.238
A20: 8 | B20: Mn | C20: Ka | D20: LIF | E20: ( | F20: 3) | G20: 15 | H20: 146.243 | I20: 0.21018 | J20: 2.2 | K20: 1.7
A21: 9 | B21: Al | C21: Ka | D21: TAP | E21: ( | F21: 4) | G21: 15 | H21: 90.995 | I21: 0.83393 | J21: 2.64 | K21: 3.1
A22: 10 | B22: P | C22: Ka | D22: PETH | E22: ( | F22: 5) | G22: 15 | H22: 197.118 | I22: 0.6157 | J22: 2 | K22: 1.2
A23: 11 | B23: Mg | C23: Ka | D23: TAPH | E23: ( | F23: 1) | G23: 15 | H23: 107.534 | I23: 0.989 | J23: 1.701 | K23: 0
A24: 12 | B24: Ca | C24: Ka | D24: PETH | E24: ( | F24: 2) | G24: 15 | H24: 107.121 | I24: 0.33584 | J24: 1.8 | K24: 1.3
A25: 13 | B25: Ti | C25: Ka | D25: PETH | E25: ( | F25: 5) | G25: 15 | H25: 88.305 | I25: 0.27485 | J25: 0 | K25: 1.3
A27: Element | B27: Peak | C27: Back | D27: Pksk | E27: Gain | F27: High.V | G27: Base.L | H27: Window.W | I27: Mode
A28: 1 | B28: Na | C28: 10 | D28: 10 | E28: (s) | F28: 1 | G28: 32 | H28: 1732 | I28: 0.7 | J28: 0 | K28: (V) | L28: Int
A29: 2 | B29: S | C29: 30 | D29: 15 | E29: (s) | F29: 1 | G29: 128 | H29: 1708 | I29: 0.7 | J29: 0 | K29: (V) | L29: Int
A30: 3 | B30: Fe | C30: 20 | D30: 10 | E30: (s) | F30: 1 | G30: 32 | H30: 1728 | I30: 0.7 | J30: 0 | K30: (V) | L30: Int
A31: 4 | B31: Si | C31: 20 | D31: 10 | E31: (s) | F31: 1 | G31: 32 | H31: 1680 | I31: 0.2 | J31: 0 | K31: (V) | L31: Int
A32: 5 | B32: Cl | C32: 30 | D32: 15 | E32: (s) | F32: 1 | G32: 64 | H32: 1714 | I32: 0.7 | J32: 0 | K32: (V) | L32: Int
A33: 6 | B33: F | C33: 30 | D33: 15 | E33: (s) | F33: 1 | G33: 32 | H33: 1748 | I33: 0.7 | J33: 0 | K33: (V) | L33: Int
A34: 7 | B34: K | C34: 30 | D34: 15 | E34: (s) | F34: 1 | G34: 64 | H34: 1738 | I34: 0.7 | J34: 0 | K34: (V) | L34: Int
A35: 8 | B35: Mn | C35: 30 | D35: 15 | E35: (s) | F35: 1 | G35: 32 | H35: 1734 | I35: 0.7 | J35: 0 | K35: (V) | L35: Int
A36: 9 | B36: Al | C36: 20 | D36: 10 | E36: (s) | F36: 1 | G36: 32 | H36: 1694 | I36: 0.2 | J36: 0 | K36: (V) | L36: Int
A37: 10 | B37: P | C37: 20 | D37: 10 | E37: (s) | F37: 1 | G37: 64 | H37: 1746 | I37: 0.7 | J37: 0 | K37: (V) | L37: Int
A38: 11 | B38: Mg | C38: 20 | D38: 10 | E38: (s) | F38: 1 | G38: 32 | H38: 1710 | I38: 0.7 | J38: 0 | K38: (V) | L38: Int
A39: 12 | B39: Ca | C39: 20 | D39: 10 | E39: (s) | F39: 1 | G39: 64 | H39: 1734 | I39: 0.7 | J39: 0 | K39: (V) | L39: Int
A40: 13 | B40: Ti | C40: 20 | D40: 10 | E40: (s) | F40: 1 | G40: 64 | H40: 1676 | I40: 0.7 | J40: 0 | K40: (V) | L40: Int
A42: Measurement | B42: Order | C42: of | D42: WDS
A43: Order | B43: Channel | C43: 1 | D43: 2 | E43: 3 | F43: 4 | G43: 5
A44: 1 | B44: Na1TH | C44: S2PH | D44: Fe3L | E44: Si4T | F44: Cl5PH
A45: 2 | B45: F1T | C45: K2PH | D45: Mn3L | E45: Al4T | F45: P5PH
...

Sheet Bgls_oxides
A2: Mass percent | B2: Group : bas-Glas | C2: Sample : 201216_Fr | D2: Page | E2: 1
A4: No. | B4: Na2O | C4: SO3 | D4: FeO | E4: SiO2 | F4: Cl | G4: F | H4: K2O | I4: MnO | J4: Al2O3 | K4: P2O5 | L4: MgO | M4: CaO | N4: TiO2 | O4: Total | P4: Comment
A5: 1 | B5: 2.8 | C5: 0.0408 | D5: 13.6 | E5: 51.16 | F5: 0.0237 | G5: 0.0126 | H5: 0.8138 | I5: 0.1786 | J5: 12.3 | K5: 0.3881 | L5: 5.13 | M5: 9.27 | N5: 4.08 | O5: 99.7976 | P5: VGA99_
A6: 2 | B6: 2.7 | C6: 0.0232 | D6: 13.46 | E6: 51.24 | F6: 0.03 | G6: 0.0791 | H6: 0.8142 | I6: 0.2468 | J6: 12.48 | K6: 0.3543 | L6: 5.2 | M6: 9.37 | N6: 4.06 | O6: 100.0575 | P6: VGA99_
A7: 3 | B7: 2.69 | C7: 0.3666 | D7: 11.76 | E7: 51.66 | F7: 0.0331 | G7: 0.0693 | H7: 0.1994 | I7: 0.2396 | J7: 14.03 | K7: 0.1729 | L7: 7.04 | M7: 11.38 | N7: 1.82 | O7: 101.4608 | P7: VG-2_
A8: 4 | B8: 2.6 | C8: 0.3591 | D8: 12.1 | E8: 51.6 | F8: 0.0346 | G8: 0.0702 | H8: 0.1893 | I8: 0.2448 | J8: 14.04 | K8: 0.1601 | L8: 7.17 | M8: 11.31 | N8: 1.85 | O8: 101.728 | P8: VG-2_
A9: 5 | B9: 6.21 | C9: 0.0261 | D9: 7.86 | E9: 70.77 | F9: 0.3989 | G9: 0.4579 | H9: 4.29 | I9: 0.1916 | J9: 8.83 | K9: 0.0161 | L9: 0.0224 | M9: 0.396 | N9: 0.3392 | O9: 99.8083 | P9: KE3_
A10: 6 | B10: 2.36 | C10: 0.0348 | D10: 8 | E10: 72.72 | F10: 0.3848 | G10: 0.5147 | H10: 4.16 | I10: 0.2905 | J10: 8.85 | K10: 0.0147 | L10: 0.0417 | M10: 0.4585 | N10: 0.3403 | O10: 98.1701 | P10: KE3_
A11: 7 | B11: 5.35 | C11: 1.392 | D11: 0.1958 | E11: 51.04 | F11: 1.45 | G11: 0.0068 | H11: 0.8437 | I11: 0.0059 | J11: 25.88 | K11: 0.0203 | L11: 0 | M11: 13.88 | N11: 0.0025 | O11: 100.0669 | P11: Scap
A12: 8 | B12: 5.19 | C12: 1.3602 | D12: 0.0852 | E12: 50.95 | F12: 1.42 | G12: 0 | H12: 0.8733 | I12: 0.035 | J12: 25.46 | K12: 0.0014 | L12: 0.002 | M12: 14.02 | N12: 0.0129 | O12: 99.41 | P12: Scap
A13: 9 | B13: 2.65 | C13: 0.0175 | D13: 13.79 | E13: 46 | F13: 0.1143 | G13: 0.1165 | H13: 1.75 | I13: 0.2421 | J13: 14.9 | K13: 0.6354 | L13: 5.07 | M13: 11.22 | N13: 4 | O13: 100.5058 | P13: 1982-CS2-L3A_1
A14: 10 | B14: 2.59 | C14: 0.0165 | D14: 13.75 | E14: 45.97 | F14: 0.1074 | G14: 0.16 | H14: 1.77 | I14: 0.22 | J14: 14.99 | K14: 0.6266 | L14: 5.08 | M14: 11.12 | N14: 3.9 | O14: 100.3005 | P14: 1982-CS2-L3A_2
A15: 11 | B15: 2.9 | C15: 0.0292 | D15: 13.49 | E15: 45.63 | F15: 0.1246 | G15: 0.1055 | H15: 1.83 | I15: 0.2252 | J15: 15.01 | K15: 0.6494 | L15: 5.07 | M15: 11.16 | N15: 3.9 | O15: 100.1238 | P15: 1982-CS2-L3A_3
A16: 12 | B16: 2.65 | C16: 0.0435 | D16: 13.63 | E16: 46.2 | F16: 0.1232 | G16: 0.1241 | H16: 1.58 | I16: 0.22 | J16: 14.93 | K16: 0.5646 | L16: 5.17 | M16: 11.22 | N16: 3.99 | O16: 100.4453 | P16: 1982-CS2-L3A_4
... A109: 105 | B109: 5.11 | C109: 1.2951 | D109: 0.1009 | E109: 50.75 | F109: 1.43 | G109: 0.0152 | H109: 0.8404 | I109: 0.0535 | J109: 25.77 | K109: 0.0163 | L109: 0.0091 | M109: 14.05 | N109: 0.0158 | O109: 99.4564 | P109: Scap
A111: Minimum
A112: Maximum
A113: Average
A114: Sigma
A115: No. of data 105

Sheet Bgls_all
A2: Intensity & Mass% Group : bas-Glas Sample : 201216_Fr Page 1
A7: Unknown Specimen No. 1
A8: Group : bas-Glas Sample : 201216_Fr
A9: UNK No. : 1 Comment : VGA99_
A10: Stage : X= 42.5705 Y= 29.7320 Z= 11.4010
A11: Acc. Voltage : 15.0 (kV) Probe Dia. : 5 Scan : Off
A12: Dated on Dec 20 16:18 2016
A13: WDS only No. of accumulation : 1
A15: Curr.(A) : 1.002E-08
A16: Element Peak(mm) Net(cps) Bg- Bg+ S.D.(%) D.L.(ppm)
A17: 1 Na 129.476 231.6 0.0 14.5 2.14 145
A18: 2 S 171.948 2.1 5.9 4.9 30.75 113
... A6384: Total: 99.45 99.45 100.00 100.00 15.571

Sheet GlassStdCalc
S1: ACC | AK1: ACC CORR
A2: No. | B2: Na2O | C2: SO3 | D2: FeO | E2: SiO2 | F2: Cl | G2: F | H2: K2O | I2: MnO | J2: Al2O3 | K2: P2O5 | L2: MgO | M2: CaO | N2: TiO2 | O2: Total | P2: Comment | S2: No. | T2: Na2O | U2: SO3 | V2: FeO | W2: SiO2 | X2: Cl | Y2: F | Z2: K2O | AA2: MnO | AB2: Al2O3 | AC2: P2O5 | AD2: MgO | AE2: CaO | AF2: TiO2 | AG2: Total | AH2: Comment | AK2: No. | AL2: Na2O | AM2: SO3 | AN2: FeO | AO2: SiO2 | AP2: Cl | AQ2: F | AR2: K2O | AS2: MnO | AT2: Al2O3 | AU2: P2O5 | AV2: MgO | AW2: CaO | AX2: TiO2 | AY2: Total | AZ2: Comment
A3: 3 | B3: 2.69 | C3: 0.3666 | D3: 11.76 | E3: 51.66 | F3: 0.0331 | G3: 0.0693 | H3: 0.1994 | I3: 0.2396 | J3: 14.03 | K3: 0.1729 | L3: 7.04 | M3: 11.38 | N3: 1.82 | O3: =SUM(B3:N3) -> 101.4609 | P3: VG-2_ | S3: 3 | T3: 2.69 | U3: 0.3666 | V3: 11.76 | W3: 51.66 | X3: 0.0331 | Y3: 0.0693 | Z3: 0.1994 | AA3: 0.2396 | AB3: 14.03 | AC3: 0.1729 | AD3: 7.04 | AE3: 11.38 | AF3: 1.82 | AG3: =SUM(T3:AF3) -> 101.4609 | AH3: VG-2_ | AK3: 3 | AL3: =T3/T$17 -> 2.5745388 | AM3: =U3/U$17 -> 0.1441006 | AN3: =V3/V$17 -> 11.730278 | AO3: =W3/W$17 -> 50.898674 | AP3: =X3/X$17 -> 0.033346561 | AQ3: =Y3/Y$17 -> 0.050804124 | AR3: =Z3/Z$17 -> 0.19652963 | AS3: =AA3/AA$17 -> 0.2263046 | ... AX3: =AF3/AF$17 -> 1.8175439 | AY3: =SUM(AL3:AX3) -> 99.683562 | AZ3: VG-2_
A4: 4 | B4: 2.6 | C4: 0.3591 | D4: 12.1 | E4: 51.6 | F4: 0.0346 | G4: 0.0702 | H4: 0.1893 | I4: 0.2448 | J4: 14.04 | K4: 0.1601 | L4: 7.17 | M4: 11.31 | N4: 1.85 | O4: =SUM(B4:N4) -> 101.7281 | P4: VG-2_ | S4: 4 | T4: 2.6 | U4: 0.3591 | V4: 12.1 | W4: 51.6 | X4: 0.0346 | Y4: 0.0702 | Z4: 0.1893 | AA4: 0.2448 | AB4: 14.04 | AC4: 0.1601 | AD4: 7.17 | AE4: 11.31 | AF4: 1.85 | AG4: =SUM(T4:AF4) -> 101.7281 | AH4: VG-2_ | AK4: 4 | AL4: =T4/T$17 -> 2.4884018 | AM4: =U4/U$17 -> 0.14115256 | AN4: =V4/V$17 -> 12.069419 | AO4: =W4/W$17 -> 50.839558 | AP4: =X4/X$17 -> 0.034857735 | AQ4: =Y4/Y$17 -> 0.051463918 | AR4: =Z4/Z$17 -> 0.18657502 | AS4: =AA4/AA$17 -> 0.23121606 | ... AX4: =AF4/AF$17 -> 1.8475034 | AY4: =SUM(AL4:AX4) -> 99.951544 | AZ4: VG-2_
A5: 56 | B5: 2.78 | C5: 0.3621 | D5: 11.82 | E5: 51.2 | F5: 0.0345 | G5: 0.0147 | H5: 0.1945 | I5: 0.1959 | J5: 13.96 | K5: 0.1713 | L5: 7.1 | M5: 11.28 | N5: 1.86 | O5: =SUM(B5:N5) -> 100.973 | P5: VG-2_ | S5: 56 | T5: 2.78 | U5: 0.3621 | V5: 11.82 | W5: 51.2 | X5: 0.0345 | Y5: 0.0147 | Z5: 0.1945 | AA5: 0.1959 | AB5: 13.96 | AC5: 0.1713 | AD5: 7.1 | AE5: 11.28 | AF5: 1.86 | AG5: =SUM(T5:AF5) -> 100.973 | AH5: VG-2_ | AK5: 56 | AL5: =T5/T$17 -> 2.6606758 | AM5: =U5/U$17 -> 0.14233178 | AN5: =V5/V$17 -> 11.790126 | AO5: =W5/W$17 -> 50.445453 | AP5: =X5/X$17 -> 0.03475699 | AQ5: =Y5/Y$17 -> 0.010776632 | AR5: =Z5/Z$17 -> 0.19170017 | AS5: =AA5/AA$17 -> 0.18502952 | ... AX5: =AF5/AF$17 -> 1.8574899 | AY5: =SUM(AL5:AX5) -> 99.216143 | AZ5: VG-2_
A6: 57 | B6: 2.79 | C6: 0.3713 | D6: 11.69 | E6: 51.45 | F6: 0.0303 | G6: 0.0249 | H6: 0.1907 | I6: 0.258 | J6: 14.07 | K6: 0.2114 | L6: 7.21 | M6: 11.36 | N6: 1.87 | O6: =SUM(B6:N6) -> 101.5266 | P6: VG-2_ | S6: 57 | T6: 2.79 | U6: 0.3713 | V6: 11.69 | W6: 51.45 | X6: 0.0303 | Y6: 0.0249 | Z6: 0.1907 | AA6: 0.258 | AB6: 14.07 | AC6: 0.2114 | AD6: 7.21 | AE6: 11.36 | AF6: 1.87 | AG6: =SUM(T6:AF6) -> 101.5266 | AH6: VG-2_ | AK6: 57 | AL6: =T6/T$17 -> 2.6702466 | AM6: =U6/U$17 -> 0.14594805 | AN6: =V6/V$17 -> 11.660455 | AO6: =W6/W$17 -> 50.691768 | AP6: =X6/X$17 -> 0.030525704 | AQ6: =Y6/Y$17 -> 0.018254296 | AR6: =Z6/Z$17 -> 0.18795487 | AS6: =AA6/AA$17 -> 0.24368359 | ... AX6: =AF6/AF$17 -> 1.8674764 | AY6: =SUM(AL6:AX6) -> 99.747844 | AZ6: VG-2_
A7: 100 | B7: 2.87 | C7: 0.3582 | D7: 11.93 | E7: 50.39 | F7: 0.0218 | G7: 0.0102 | H7: 0.1917 | I7: 0.1893 | J7: 13.55 | K7: 0.2236 | L7: 7.17 | M7: 11.23 | N7: 1.87 | O7: =SUM(B7:N7) -> 100.0048 | P7: VG-2_ | S7: 100 | T7: 2.87 | U7: 0.3582 | V7: 11.93 | W7: 50.39 | X7: 0.0218 | Y7: 0.0102 | Z7: 0.1917 | AA7: 0.1893 | AB7: 13.55 | AC7: 0.2236 | AD7: 7.17 | AE7: 11.23 | AF7: 1.87 | AG7: =SUM(T7:AF7) -> 100.0048 | AH7: VG-2_ | AK7: 100 | AL7: =T7/T$17 -> 2.7468128 | AM7: =U7/U$17 -> 0.14079879 | AN7: =V7/V$17 -> 11.899848 | AO7: =W7/W$17 -> 49.64739 | AP7: =X7/X$17 -> 0.021962388 | AQ7: =Y7/Y$17 -> 0.0074776632 | AR7: =Z7/Z$17 -> 0.18894047 | AS7: =AA7/AA$17 -> 0.17879575 | ... AX7: =AF7/AF$17 -> 1.8674764 | AY7: =SUM(AL7:AX7) -> 98.257994 | AZ7: VG-2_
A8: 101 | B8: 2.77 | C8: 0.3441 | D8: 11.95 | E8: 51.17 | F8: 0.0311 | G8: 0.097 | H8: 0.2061 | I8: 0.1534 | J8: 13.98 | K8: 0.1933 | L8: 7.03 | M8: 11.24 | N8: 1.88 | O8: =SUM(B8:N8) -> 101.045 | P8: VG-2_ | S8: 101 | T8: 2.77 | U8: 0.3441 | V8: 11.95 | W8: 51.17 | X8: 0.0311 | Y8: 0.097 | Z8: 0.2061 | AA8: 0.1534 | AB8: 13.98 | AC8: 0.1933 | AD8: 7.03 | AE8: 11.24 | AF8: 1.88 | AG8: =SUM(T8:AF8) -> 101.045 | AH8: VG-2_ | AK8: 101 | AL8: =T8/T$17 -> 2.651105 | AM8: =U8/U$17 -> 0.13525646 | AN8: =V8/V$17 -> 11.919798 | AO8: =W8/W$17 -> 50.415895 | AP8: =X8/X$17 -> 0.031331663 | AQ8: =Y8/Y$17 -> 0.071111111 | AR8: =Z8/Z$17 -> 0.20313319 | AS8: =AA8/AA$17 -> 0.14488784 | ... AX8: =AF8/AF$17 -> 1.8774629 | AY8: =SUM(AL8:AX8) -> 99.285711 | AZ8: VG-2_
A11: SRM | B11: 2.62 | C11: 0.143 | D11: 11.84 | E11: 50.81 | F11: 0.03291 | G11: 0.032 | H11: 0.19 | I11: 0.22 | J11: 14.06 | K11: 0.2 | L11: 6.71 | M11: 11.12 | N11: 1.85 | S11: SRM | T11: 2.62 | U11: 0.143 | V11: 11.84 | W11: 50.81 | X11: 0.03291 | Y11: 0.032 | Z11: 0.19 | AA11: 0.22 | AB11: 14.06 | AC11: 0.2 | AD11: 6.71 | AE11: 11.12 | AF11: 1.85 | AK11: StdValue | AL11: 2.62 | AM11: 0.143 | AN11: 11.84 | AO11: 50.81 | AP11: 0.03291 | AQ11: 0.032 | AR11: 0.19 | AS11: 0.22 | AT11: 14.06 | AU11: 0.2 | AV11: 6.71 | AW11: 11.12 | AX11: 1.85
A12: Average | B12: =AVERAGE(B3:B8) -> 2.75 | C12: =AVERAGE(C3:C8) -> 0.36023333 | D12: =AVERAGE(D3:D8) -> 11.875 | E12: =AVERAGE(E3:E6,E8) -> 51.416 | F12: =AVERAGE(F3:F6,F8) -> 0.03272 | G12: =AVERAGE(G3:G8) -> 0.047716667 | H12: =AVERAGE(H3:H8) -> 0.19528333 | I12: =AVERAGE(I3:I8) -> 0.2135 | J12: =AVERAGE(J3:J6,J8) -> 14.016 | K12: =AVERAGE(K3:K8) -> 0.18876667 | L12: =AVERAGE(L3:L8) -> 7.12 | M12: =AVERAGE(M3:M8) -> 11.3 | N12: =AVERAGE(N3:N8) -> 1.8583333 | S12: Average | T12: =AVERAGE(T3:T4,T6:T7) -> 2.7375 | U12: =AVERAGE(U3:U4,U6:U7) -> 0.3638 | V12: =AVERAGE(V3:V4,V6:V7) -> 11.87 | W12: =AVERAGE(W3:W4,W6) -> 51.57 | X12: =AVERAGE(X3:X4,X6) -> 0.032666667 | Y12: =AVERAGE(Y3:Y4,Y6:Y7) -> 0.04365 | Z12: =AVERAGE(Z3:Z4,Z6:Z7) -> 0.192775 | AA12: =AVERAGE(AA3:AA4,AA6:AA7) -> 0.232925 | AB12: =AVERAGE(AB3:AB4,AB6) -> 14.046667 | AC12: =AVERAGE(AC3:AC4,AC6:AC7) -> 0.192 | AD12: =AVERAGE(AD3:AD4,AD6:AD7) -> 7.1475 | AE12: =AVERAGE(AE3:AE4,AE6:AE7) -> 11.32 | AF12: =AVERAGE(AF3:AF4,AF6:AF7) -> 1.8525 | AK12: Average Test | AL12: =AVERAGE(AL5,AL8) -> 2.6558904 | AM12: =AVERAGE(AM5,AM8) -> 0.13879412 | AN12: =AVERAGE(AN5,AN8) -> 11.854962 | AO12: =AVERAGE(AO5,AO8) -> 50.430674 | AP12: =AVERAGE(AP5,AP8) -> 0.033044327 | AQ12: =AVERAGE(AQ5,AQ8) -> 0.040943872 | AR12: =AVERAGE(AR5,AR8) -> 0.19741668 | AS12: =AVERAGE(AS5,AS8) -> 0.16495868 | ... AX12: =AVERAGE(AX5,AX8) -> 1.8674764
A13: StdDev | B13: =STDEV(B3:B8) -> 0.093166518 | C13: =STDEV(C3:C8) -> 0.0092972397 | D13: =STDEV(D3:D8) -> 0.14815532 | E13: =STDEV(E3:E6,E8) -> 0.22456625 | F13: =STDEV(F3:F6,F8) -> 0.0019575495 | G13: =STDEV(G3:G8) -> 0.035828448 | H13: =STDEV(H3:H8) -> 0.0063907485 | I13: =STDEV(I3:I8) -> 0.040369692 | J13: =STDEV(J3:J6,J8) -> 0.045055521 | K13: =STDEV(K3:K8) -> 0.024999173 | L13: =STDEV(L3:L8) -> 0.074833148 | M13: =STDEV(M3:M8) -> 0.06164414 | N13: =STDEV(N3:N8) -> 0.021369761
A14: 2sigma | B14: =2*B13 -> 0.18633304 | C14: =2*C13 -> 0.018594479 | D14: =2*D13 -> 0.29631065 | E14: =2*E13 -> 0.4491325 | F14: =2*F13 -> 0.003915099 | G14: =2*G13 -> 0.071656895 | H14: =2*H13 -> 0.012781497 | I14: =2*I13 -> 0.080739383 | ... N14: =2*N13 -> 0.042739521
A15: RSD | B15: =B14/B12 -> 0.067757467 | C15: =C14/C12 -> 0.051617876 | D15: =D14/D12 -> 0.024952476 | E15: =E14/E12 -> 0.0087352672 | F15: =F14/F12 -> 0.11965461 | G15: =G14/G12 -> 1.5017163 | H15: =H14/H12 -> 0.065451039 | I15: =I14/I12 -> 0.37817041 | ... N15: =N14/N12 -> 0.022998845 | AK15: Acc % | AL15: =ABS(AL12-AL11)/AL11 -> 0.01369863 | AM15: =ABS(AM12-AM11)/AM11 -> 0.029411765 | AN15: =ABS(AN12-AN11)/AN11 -> 0.00126369 | AO15: =ABS(AO12-AO11)/AO11 -> 0.0074655808 | AP15: =ABS(AP12-AP11)/AP11 -> 0.0040816327 | AQ15: =ABS(AQ12-AQ11)/AQ11 -> 0.27949599 | AR15: =ABS(AR12-AR11)/AR11 -> 0.039035145 | AS15: =ABS(AS12-AS11)/AS11 -> 0.25018783 | ... AX15: =ABS(AX12-AX11)/AX11 -> 0.0094466937
A16: Acc % | B16: 0.01369863 | C16: 0.029411765 | D16: 0.00126369 | E16: 0.0074655808 | F16: 0.0040816327 | G16: 0.27949599 | H16: 0.039035145 | I16: 0.25018783 | J16: 0.0054579972 | K16: 0.050520833 | L16: 0.011542497 | M16: 0.0053003534 | N16: 0.0094466937
A17: CorrFactor | B17: =B12/B11 -> 1.0496183 | C17: =C12/C11 -> 2.5191142 | D17: =D12/D11 -> 1.0029561 | E17: =E12/E11 -> 1.0119268 | F17: =F12/F11 -> 0.99422668 | G17: =G12/G11 -> 1.4911458 | H17: =H12/H11 -> 1.027807 | I17: =I12/I11 -> 0.97045455 | ... N17: =N12/N11 -> 1.0045045 | S17: CorrFactor | T17: =T12/T11 -> 1.0448473 | U17: =U12/U11 -> 2.5440559 | V17: =V12/V11 -> 1.0025338 | W17: =W12/W11 -> 1.0149577 | X17: =X12/X11 -> 0.9926061 | Y17: =Y12/Y11 -> 1.3640625 | Z17: =Z12/Z11 -> 1.0146053 | AA17: =AA12/AA11 -> 1.05875 | ... AF17: =AF12/AF11 -> 1.0013514

Sheet GlassCorrected
A1: No. | B1: Na2O | C1: SO3 | D1: FeO | E1: SiO2 | F1: Cl | G1: F | H1: K2O | I1: MnO | J1: Al2O3 | K1: P2O5 | L1: MgO | M1: CaO | N1: TiO2 | O1: Total | P1: Comment | S1: Fo+M | T1: Fa+M | U1: Total
A2: 1 | B2: =Bgls_oxides!B5/GlassStdCalc!B$17 -> 2.6676364 | C2: =Bgls_oxides!C5/GlassStdCalc!C$17 -> 0.016196169 | D2: =Bgls_oxides!D5/GlassStdCalc!D$17 -> 13.559916 | E2: =Bgls_oxides!E5/GlassStdCalc!E$17 -> 50.557017 | F2: =Bgls_oxides!F5/GlassStdCalc!F$17 -> 0.023837622 | G2: =Bgls_oxides!G5/GlassStdCalc!G$17 -> 0.0084498778 | H2: =Bgls_oxides!H5/GlassStdCalc!H$17 -> 0.79178288 | I2: =Bgls_oxides!I5/GlassStdCalc!I$17 -> 0.18403747 | ... N2: =Bgls_oxides!N5/GlassStdCalc!N$17 -> 4.061704 | O2: =SUM(B2:N2) -> 98.577315 | P2: VGA99_ | S2: =100*(L2/40.304)/((L2/40.304)+(D2/71.844)) -> 38.858243 | T2: =100-S2 -> 61.141757 | U2: =SUM(S2:T2) -> 100
A3: 2 | B3: =Bgls_oxides!B6/GlassStdCalc!B$17 -> 2.5723636 | C3: =Bgls_oxides!C6/GlassStdCalc!C$17 -> 0.0092095864 | D3: =Bgls_oxides!D6/GlassStdCalc!D$17 -> 13.420328 | E3: =Bgls_oxides!E6/GlassStdCalc!E$17 -> 50.636074 | F3: =Bgls_oxides!F6/GlassStdCalc!F$17 -> 0.030174205 | G3: =Bgls_oxides!G6/GlassStdCalc!G$17 -> 0.053046455 | H3: =Bgls_oxides!H6/GlassStdCalc!H$17 -> 0.79217206 | I3: =Bgls_oxides!I6/GlassStdCalc!I$17 -> 0.25431382 | ... N3: =Bgls_oxides!N6/GlassStdCalc!N$17 -> 4.0417937 | O3: =SUM(B3:N3) -> 98.825344 | P3: VGA99_ | S3: =100*(L3/40.304)/((L3/40.304)+(D3/71.844)) -> 39.427574 | T3: =100-S3 -> 60.572426 | U3: =SUM(S3:T3) -> 100
A4: 3 | B4: =Bgls_oxides!B7/GlassStdCalc!B$17 -> 2.5628364 | C4: =Bgls_oxides!C7/GlassStdCalc!C$17 -> 0.14552734 | D4: =Bgls_oxides!D7/GlassStdCalc!D$17 -> 11.725339 | E4: =Bgls_oxides!E7/GlassStdCalc!E$17 -> 51.051124 | F4: =Bgls_oxides!F7/GlassStdCalc!F$17 -> 0.033292207 | G4: =Bgls_oxides!G7/GlassStdCalc!G$17 -> 0.046474328 | H4: =Bgls_oxides!H7/GlassStdCalc!H$17 -> 0.19400529 | I4: =Bgls_oxides!I7/GlassStdCalc!I$17 -> 0.24689461 | ... N4: =Bgls_oxides!N7/GlassStdCalc!N$17 -> 1.8118386 | O4: =SUM(B4:N4) -> 99.907897 | P4: VG-2_ | S4: =100*(L4/40.304)/((L4/40.304)+(D4/71.844)) -> 50.214838 | T4: =100-S4 -> 49.785162 | U4: =SUM(S4:T4) -> 100
A5: 4 | B5: =Bgls_oxides!B8/GlassStdCalc!B$17 -> 2.4770909 | C5: =Bgls_oxides!C8/GlassStdCalc!C$17 -> 0.14255011 | D5: =Bgls_oxides!D8/GlassStdCalc!D$17 -> 12.064337 | E5: =Bgls_oxides!E8/GlassStdCalc!E$17 -> 50.991831 | F5: =Bgls_oxides!F8/GlassStdCalc!F$17 -> 0.034800917 | G5: =Bgls_oxides!G8/GlassStdCalc!G$17 -> 0.04707789 | H5: =Bgls_oxides!H8/GlassStdCalc!H$17 -> 0.18417854 | I5: =Bgls_oxides!I8/GlassStdCalc!I$17 -> 0.25225293 | ... N5: =Bgls_oxides!N8/GlassStdCalc!N$17 -> 1.841704 | O5: =SUM(B5:N5) -> 100.17649 | P5: VG-2_ | S5: =100*(L5/40.304)/((L5/40.304)+(D5/71.844)) -> 49.959738 | T5: =100-S5 -> 50.040262 | U5: =SUM(S5:T5) -> 100
A6: 5 | B6: =Bgls_oxides!B9/GlassStdCalc!B$17 -> 5.9164364 | C6: =Bgls_oxides!C9/GlassStdCalc!C$17 -> 0.010360785 | D6: =Bgls_oxides!D9/GlassStdCalc!D$17 -> 7.8368337 | E6: =Bgls_oxides!E9/GlassStdCalc!E$17 -> 69.93589 | F6: =Bgls_oxides!F9/GlassStdCalc!F$17 -> 0.40121635 | G6: =Bgls_oxides!G9/GlassStdCalc!G$17 -> 0.30707929 | H6: =Bgls_oxides!H9/GlassStdCalc!H$17 -> 4.1739353 | I6: =Bgls_oxides!I9/GlassStdCalc!I$17 -> 0.19743326 | ... N6: =Bgls_oxides!N9/GlassStdCalc!N$17 -> 0.33767892 | O6: =SUM(B6:N6) -> 98.402444 | P6: KE3_ | S6: =100*(L6/40.304)/((L6/40.304)+(D6/71.844)) -> 0.47787237 | T6: =100-S6 -> 99.522128 | U6: =SUM(S6:T6) -> 100
A7: 6 | B7: =Bgls_oxides!B10/GlassStdCalc!B$17 -> 2.2484364 | C7: =Bgls_oxides!C10/GlassStdCalc!C$17 -> 0.01381438 | D7: =Bgls_oxides!D10/GlassStdCalc!D$17 -> 7.9764211 | E7: =Bgls_oxides!E10/GlassStdCalc!E$17 -> 71.862906 | F7: =Bgls_oxides!F10/GlassStdCalc!F$17 -> 0.38703447 | G7: =Bgls_oxides!G10/GlassStdCalc!G$17 -> 0.3451708 | H7: =Bgls_oxides!H10/GlassStdCalc!H$17 -> 4.0474524 | I7: =Bgls_oxides!I10/GlassStdCalc!I$17 -> 0.29934426 | ... N7: =Bgls_oxides!N10/GlassStdCalc!N$17 -> 0.33877399 | O7: =SUM(B7:N7) -> 96.903207 | P7: KE3_ | S7: =100*(L7/40.304)/((L7/40.304)+(D7/71.844)) -> 0.8705934 | T7: =100-S7 -> 99.129407 | U7: =SUM(S7:T7) -> 100
A8: 7 | B8: =Bgls_oxides!B11/GlassStdCalc!B$17 -> 5.0970909 | C8: =Bgls_oxides!C11/GlassStdCalc!C$17 -> 0.55257518 | D8: =Bgls_oxides!D11/GlassStdCalc!D$17 -> 0.19522291 | E8: =Bgls_oxides!E11/GlassStdCalc!E$17 -> 50.438432 | F8: =Bgls_oxides!F11/GlassStdCalc!F$17 -> 1.4584199 | G8: =Bgls_oxides!G11/GlassStdCalc!G$17 -> 0.0045602515 | H8: =Bgls_oxides!H11/GlassStdCalc!H$17 -> 0.82087394 | I8: =Bgls_oxides!I11/GlassStdCalc!I$17 -> 0.0060796253 | ... N8: =Bgls_oxides!N11/GlassStdCalc!N$17 -> 0.0024887892 | O8: =SUM(B8:N8) -> 98.217398 | P8: Scap | S8: =100*(L8/40.304)/((L8/40.304)+(D8/71.844)) -> 0 | T8: =100-S8 -> 100 | U8: =SUM(S8:T8) -> 100
A9: 8 | B9: =Bgls_oxides!B12/GlassStdCalc!B$17 -> 4.9446545 | C9: =Bgls_oxides!C12/GlassStdCalc!C$17 -> 0.5399517 | D9: =Bgls_oxides!D12/GlassStdCalc!D$17 -> 0.084948884 | E9: =Bgls_oxides!E12/GlassStdCalc!E$17 -> 50.349492 | F9: =Bgls_oxides!F12/GlassStdCalc!F$17 -> 1.4282457 | G9: =Bgls_oxides!G12/GlassStdCalc!G$17 -> 0 | H9: =Bgls_oxides!H12/GlassStdCalc!H$17 -> 0.84967312 | I9: =Bgls_oxides!I12/GlassStdCalc!I$17 -> 0.036065574 | ... N9: =Bgls_oxides!N12/GlassStdCalc!N$17 -> 0.012842152 | O9: =SUM(B9:N9) -> 97.585841 | P9: Scap | S9: =100*(L9/40.304)/((L9/40.304)+(D9/71.844)) -> 3.8046211 | T9: =100-S9 -> 96.195379 | U9: =SUM(S9:T9) -> 100
A10: 9 | B10: =Bgls_oxides!B13/GlassStdCalc!B$17 -> 2.5247273 | C10: =Bgls_oxides!C13/GlassStdCalc!C$17 -> 0.0069468863 | D10: =Bgls_oxides!D13/GlassStdCalc!D$17 -> 13.749356 | E10: =Bgls_oxides!E13/GlassStdCalc!E$17 -> 45.457834 | F10: =Bgls_oxides!F13/GlassStdCalc!F$17 -> 0.11496372 | G10: =Bgls_oxides!G13/GlassStdCalc!G$17 -> 0.078127838 | H10: =Bgls_oxides!H13/GlassStdCalc!H$17 -> 1.7026543 | I10: =Bgls_oxides!I13/GlassStdCalc!I$17 -> 0.24947073 | ... N10: =Bgls_oxides!N13/GlassStdCalc!N$17 -> 3.9820628 | O10: =SUM(B10:N10) -> 99.305453 | P10: 1982-CS2-L3A_1 | S10: =100*(L10/40.304)/((L10/40.304)+(D10/71.844)) -> 38.250871 | T10: =100-S10 -> 61.749129 | U10: =SUM(S10:T10) -> 100
A11: 10 | B11: =Bgls_oxides!B14/GlassStdCalc!B$17 -> 2.4675636 | C11: =Bgls_oxides!C14/GlassStdCalc!C$17 -> 0.0065499213 | D11: =Bgls_oxides!D14/GlassStdCalc!D$17 -> 13.709474 | E11: =Bgls_oxides!E14/GlassStdCalc!E$17 -> 45.428188 | F11: =Bgls_oxides!F14/GlassStdCalc!F$17 -> 0.10802366 | G11: =Bgls_oxides!G14/GlassStdCalc!G$17 -> 0.10730003 | H11: =Bgls_oxides!H14/GlassStdCalc!H$17 -> 1.7221132 | I11: =Bgls_oxides!I14/GlassStdCalc!I$17 -> 0.22669789 | ... N11: =Bgls_oxides!N14/GlassStdCalc!N$17 -> 3.8825112 | O11: =SUM(B11:N11) -> 99.089706 | P11: 1982-CS2-L3A_2 | S11: =100*(L11/40.304)/((L11/40.304)+(D11/71.844)) -> 38.366089 | T11: =100-S11 -> 61.633911 | U11: =SUM(S11:T11) -> 100
A12: 11 | B12: =Bgls_oxides!B15/GlassStdCalc!B$17 -> 2.7629091 | C12: =Bgls_oxides!C15/GlassStdCalc!C$17 -> 0.011591376 | D12: =Bgls_oxides!D15/GlassStdCalc!D$17 -> 13.45024 | E12: =Bgls_oxides!E15/GlassStdCalc!E$17 -> 45.092195 | F12: =Bgls_oxides!F15/GlassStdCalc!F$17 -> 0.12532353 | G12: =Bgls_oxides!G15/GlassStdCalc!G$17 -> 0.070750961 | H12: =Bgls_oxides!H15/GlassStdCalc!H$17 -> 1.7804899 | I12: =Bgls_oxides!I15/GlassStdCalc!I$17 -> 0.23205621 | ... N12: =Bgls_oxides!N15/GlassStdCalc!N$17 -> 3.8825112 | O12: =SUM(B12:N12) -> 98.913511 | P12: 1982-CS2-L3A_3 | S12: =100*(L12/40.304)/((L12/40.304)+(D12/71.844)) -> 38.771709 | T12: =100-S12 -> 61.228291 | U12: =SUM(S12:T12) -> 100
A13: 12 | B13: =Bgls_oxides!B16/GlassStdCalc!B$17 -> 2.5247273 | C13: =Bgls_oxides!C16/GlassStdCalc!C$17 -> 0.017267974 | D13: =Bgls_oxides!D16/GlassStdCalc!D$17 -> 13.589827 | E13: =Bgls_oxides!E16/GlassStdCalc!E$17 -> 45.655477 | F13: =Bgls_oxides!F16/GlassStdCalc!F$17 -> 0.1239154 | G13: =Bgls_oxides!G16/GlassStdCalc!G$17 -> 0.08322459 | H13: =Bgls_oxides!H16/GlassStdCalc!H$17 -> 1.5372536 | I13: =Bgls_oxides!I16/GlassStdCalc!I$17 -> 0.22669789 | ... N13: =Bgls_oxides!N16/GlassStdCalc!N$17 -> 3.9721076 | O13: =SUM(B13:N13) -> 99.21913 | P13: 1982-CS2-L3A_4 | S13: =100*(L13/40.304)/((L13/40.304)+(D13/71.844)) -> 38.990508 | T13: =100-S13 -> 61.009492 | U13: =SUM(S13:T13) -> 100
... A106: 105 | B106: =Bgls_oxides!B109/GlassStdCalc!B$17 -> 4.8684364 | C106: =Bgls_oxides!C109/GlassStdCalc!C$17 -> 0.51410928 | D106: =Bgls_oxides!D109/GlassStdCalc!D$17 -> 0.10060261 | E106: =Bgls_oxides!E109/GlassStdCalc!E$17 -> 50.15185 | F106: =Bgls_oxides!F109/GlassStdCalc!F$17 -> 1.4383038 | G106: =Bgls_oxides!G109/GlassStdCalc!G$17 -> 0.010193503 | H106: =Bgls_oxides!H109/GlassStdCalc!H$17 -> 0.81766322 | I106: =Bgls_oxides!I109/GlassStdCalc!I$17 -> 0.055128806 | ... N106: =Bgls_oxides!N109/GlassStdCalc!N$17 -> 0.015729148 | O106: =SUM(B106:N106) -> 97.674956 | P106: Scap | S106: =100*(L106/40.304)/((L106/40.304)+(D106/71.844)) -> 13.191107 | T106: =100-S106 -> 86.808893 | U106: =SUM(S106:T106) -> 100
