Workbook

Sheet MDL Filtered Raw
A1: Element | B1: Li7 | C1: B11 | D1: Na23 | E1: Mg24 | F1: Al27 | G1: Si29 | H1: P31 | I1: K39 | J1: Ca43 | K1: Sc45 | L1: Ti47 | M1: V51 | N1: Mn55 | O1: Fe57 | P1: As75 | Q1: Rb85 | R1: Sr88 | S1: Y89 | T1: Zr90 | U1: Nb93 | V1: Cs133 | W1: Ba138 | X1: La139 | Y1: Ce140 | Z1: Pr141 | AA1: Nd146 | AB1: Sm147 | AC1: Eu151 | AD1: Gd157 | AE1: Tb159 | AF1: Dy163 | AG1: Ho165 | AH1: Er166 | AI1: Tm169 | AJ1: Yb172 | AK1: Lu175 | AL1: Hf178 | AM1: Ta181 | AN1: Pb208 | AO1: Th232 | AP1: U238
A2: 001N612 | B2: 30.66 | C2: 17.8 | D2: 87723.91 | E2: 56.61 | F2: 10153.24 | G2: 274975.25 | H2: 35.11 | I2: <21.40 | J2: 85048.7 | K2: 41.82 | L2: 47.08 | M2: 34.76 | N2: 33.94 | O2: 174.63 | P2: 10.88 | Q2: 27.33 | R2: 77.66 | S2: 42.7 | T2: 40.98 | U2: 38.69 | V2: 37.38 | W2: 37.96 | X2: 34.39 | Y2: 36.26 | Z2: 37.41 | AA2: 37.49 | AB2: 36.74 | AC2: 36.27 | AD2: 38.4 | AE2: 40.22 | AF2: 37.82 | AG2: 41.37 | AH2: 41.73 | AI2: 41.02 | AJ2: 44.17 | AK2: 41.1 | AL2: 39.38 | AM2: 41.53 | AN2: 34.17 | AO2: 41.86 | AP2: 35.16
A3: 002N612 | B3: 30.18 | C3: 17.9 | D3: 86950.13 | E3: 53.83 | F3: 9977.2 | G3: 274332.56 | H3: 31.7 | I3: <21.20 | J3: 85048.7 | K3: 42.45 | L3: 45.56 | M3: 35.21 | N3: 33.32 | O3: 165.55 | P3: 10.89 | Q3: 27.68 | R3: 78.62 | S3: 42.83 | T3: 41.06 | U3: 39.05 | V3: 37.56 | W3: 37.79 | X3: 34.35 | Y3: 36.69 | Z3: 38.1 | AA3: 36.17 | AB3: 37.97 | AC3: 35.49 | AD3: 39.53 | AE3: 40.58 | AF3: 39.02 | AG3: 40.37 | AH3: 40.83 | AI3: 40.4 | AJ3: 43.45 | AK3: 41.48 | AL3: 39.58 | AM3: 41.01 | AN3: 34.53 | AO3: 41.48 | AP3: 35.55
A4: 003N612 | B4: 29.6 | C4: 17.75 | D4: 87703.38 | E4: 57.83 | F4: 10274.38 | G4: 277987.41 | H4: 34.38 | I4: <21.54 | J4: 85048.7 | K4: 41.36 | L4: 44.58 | M4: 34.32 | N4: 34.39 | O4: 170.15 | P4: 10.69 | Q4: 27.43 | R4: 78.83 | S4: 43.42 | T4: 40.74 | U4: 39.45 | V4: 37 | W4: 38.64 | X4: 34.65 | Y4: 37.02 | Z4: 37.48 | AA4: 35.92 | AB4: 37.77 | AC4: 35.88 | AD4: 40.25 | AE4: 40.35 | AF4: 38.12 | AG4: 40.42 | AH4: 41.39 | AI4: 40.87 | AJ4: 42.62 | AK4: 40.34 | AL4: 39.35 | AM4: 41.47 | AN4: 34.37 | AO4: 40.64 | AP4: 34.66
A5: 004KL2 | B5: 5.21 | C5: 10.95 | D5: 17091.78 | E5: 43329.79 | F5: 68000.88 | G5: 227196.58 | H5: 977.73 | I5: 4196.2 | J5: 77901.7 | K5: 31.16 | L5: 15566.6 | M5: 312.43 | N5: 1303.11 | O5: 81991.84 | P5: 0.165 | Q5: 8.56 | R5: 351.98 | S5: 24.42 | T5: 158.89 | U5: 15.42 | V5: 0.122 | W5: 122.36 | X5: 12.99 | Y5: 33.23 | Z5: 4.41 | AA5: 21.36 | AB5: 5.49 | AC5: 1.88 | AD5: 5.94 | AE5: 0.844 | AF5: 5.15 | AG5: 0.94 | AH5: 2.41 | AI5: 0.288 | AJ5: 2.1 | AK5: 0.261 | AL5: 3.72 | AM5: 0.934 | AN5: 2.06 | AO5: 0.913 | AP5: 0.636
A6: 005KL2 | B6: 5.22 | C6: 2.48 | D6: 17245.47 | E6: 44940.31 | F6: 69620.05 | G6: 233055.86 | H6: 919.53 | I6: 4019.08 | J6: 77901.7 | K6: 31.98 | L6: 15304.21 | M6: 310.73 | N6: 1286.29 | O6: 82919.68 | P6: 0.107 | Q6: 8.89 | R6: 353.77 | S6: 24.97 | T6: 147.91 | U6: 14.71 | V6: 0.11 | W6: 123.03 | X6: 13.2 | Y6: 31.48 | Z6: 4.63 | AA6: 21.51 | AB6: 5.69 | AC6: 1.83 | AD6: 5.69 | AE6: 0.889 | AF6: 5.19 | AG6: 0.96 | AH6: 2.49 | AI6: 0.33 | AJ6: 2.08 | AK6: 0.288 | AL6: 3.69 | AM6: 0.936 | AN6: 2.08 | AO6: 0.977 | AP6: 0.558
A7: 006KL2 | B7: 5.23 | C7: 2.07 | D7: 18130.38 | E7: 46158.29 | F7: 72111.45 | G7: 241409.72 | H7: 956.5 | I7: 4085.24 | J7: 77901.7 | K7: 31.86 | L7: 15292.14 | M7: 314.17 | N7: 1316.63 | O7: 85107.55 | P7: 0.199 | Q7: 9.14 | R7: 362.8 | S7: 25.12 | T7: 149.61 | U7: 15.33 | V7: 0.11 | W7: 123.64 | X7: 12.47 | Y7: 32.16 | Z7: 4.63 | AA7: 21.58 | AB7: 5.58 | AC7: 1.95 | AD7: 6.14 | AE7: 0.907 | AF7: 4.97 | AG7: 0.859 | AH7: 2.57 | AI7: 0.341 | AJ7: 2.04 | AK7: 0.295 | AL7: 3.87 | AM7: 0.97 | AN7: 2.11 | AO7: 1.05 | AP7: 0.575
A8: 007BM90 | B8: 2.02 | C8: 1.67 | D8: 872.46 | E8: 208008.56 | F8: 12476.81 | G8: 241693.27 | H8: 18.41 | I8: <24.43 | J8: 15008.72 | K8: 16.53 | L8: 367.15 | M8: 56 | N8: 835.55 | O8: 56222.92 | P8: 0.104 | Q8: 0.262 | R8: 0.669 | S8: 2.21 | T8: 20.02 | U8: 0.022 | V8: 0.84 | W8: 0.463 | X8: 0.215 | Y8: 0.414 | Z8: 0.0784 | AA8: 0.412 | AB8: 0.107 | AC8: 0.0436 | AD8: 0.282 | AE8: 0.0438 | AF8: 0.359 | AG8: 0.084 | AH8: 0.216 | AI8: 0.0425 | AJ8: 0.301 | AK8: 0.0561 | AL8: 0.59 | AM8: 0.0046 | AN8: 0.475 | AO8: 0.056 | AP8: 0.085
A9: 008BM90 | B9: 1.72 | C9: 1.76 | D9: 868.99 | E9: 208148.02 | F9: 12030.06 | G9: 241599.27 | H9: 17.81 | I9: <25.01 | J9: 15008.72 | K9: 16.46 | L9: 348.62 | M9: 55.91 | N9: 843.48 | O9: 56710.61 | P9: <0.074 | Q9: 0.304 | R9: 0.65 | S9: 2.32 | T9: 19.52 | U9: <0.0218 | V9: 0.9 | W9: 0.44 | X9: 0.177 | Y9: 0.443 | Z9: 0.0734 | AA9: 0.389 | AB9: 0.151 | AC9: 0.0526 | AD9: 0.28 | AE9: 0.0453 | AF9: 0.387 | AG9: 0.091 | AH9: 0.258 | AI9: 0.0465 | AJ9: 0.318 | AK9: 0.0548 | AL9: 0.543 | AM9: <0.0062 | AN9: 0.479 | AO9: 0.0545 | AP9: 0.072
A10: 009GOR132 | B10: 8.87 | C10: 11.71 | D10: 6672.55 | E10: 142794.02 | F10: 57438.87 | G10: 218643.95 | H10: 118.34 | I10: 189.71 | J10: 60392.23 | K10: 35.59 | L10: 1785.51 | M10: 233.08 | N10: 1251.49 | O10: 86376.49 | P10: 0.141 | Q10: 2.31 | R10: 15.82 | S10: 13.19 | T10: 9.58 | U10: 0.069 | V10: 8.21 | W10: 0.868 | X10: 0.093 | Y10: 0.344 | Z10: 0.088 | AA10: 0.743 | AB10: 0.486 | AC10: 0.262 | AD10: 1.14 | AE10: 0.215 | AF10: 2.08 | AG10: 0.489 | AH10: 1.6 | AI10: 0.229 | AJ10: 1.42 | AK10: 0.232 | AL10: 0.348 | AM10: 0.0362 | AN10: 22.24 | AO10: 0.0075 | AP10: 0.051
A11: 010GOR132 | B11: 8.99 | C11: 11.28 | D11: 6319.15 | E11: 138234.5 | F11: 56407.36 | G11: 212192.69 | H11: 111.61 | I11: 165.22 | J11: 60392.23 | K11: 34.88 | L11: 1743.55 | M11: 220.64 | N11: 1203.94 | O11: 83189.79 | P11: 0.107 | Q11: 2.15 | R11: 15.1 | S11: 13.12 | T11: 9.84 | U11: 0.0263 | V11: 8.04 | W11: 0.683 | X11: 0.08 | Y11: 0.311 | Z11: 0.0847 | AA11: 0.609 | AB11: 0.511 | AC11: 0.278 | AD11: 1.27 | AE11: 0.264 | AF11: 2.03 | AG11: 0.504 | AH11: 1.55 | AI11: 0.222 | AJ11: 1.54 | AK11: 0.229 | AL11: 0.323 | AM11: 0.0259 | AN11: 21.39 | AO11: <0.0051 | AP11: 0.066
A12: 011GOR128 | B12: 10.12 | C12: 14.42 | D12: 4600.63 | E12: 147788.48 | F12: 50541.61 | G12: 213893.53 | H12: 86.35 | I12: 246.9 | J12: 44597.34 | K12: 30.37 | L12: 1671.98 | M12: 183.08 | N12: 1441.6 | O12: 84292.74 | P12: 0.126 | Q12: 0.338 | R12: 29.01 | S12: 11.38 | T12: 9.33 | U12: 0.115 | V12: 0.208 | W12: 0.956 | X12: 0.104 | Y12: 0.402 | Z12: 0.094 | AA12: 0.659 | AB12: 0.444 | AC12: 0.279 | AD12: 1.34 | AE12: 0.224 | AF12: 1.86 | AG12: 0.407 | AH12: 1.38 | AI12: 0.198 | AJ12: 1.21 | AK12: 0.181 | AL12: 0.345 | AM12: 0.0178 | AN12: 0.308 | AO12: <0.0152 | AP12: 0.0109
A13: 012GOR128 | B13: 11.13 | C13: 16.56 | D13: 5316.96 | E13: 203682.8 | F13: 54948.23 | G13: 247541.09 | H13: 94.16 | I13: 243.42 | J13: 44597.34 | K13: 32.09 | L13: 1751.93 | M13: 197.64 | N13: 1506.44 | O13: 85512.35 | P13: 0.212 | Q13: 0.48 | R13: 31.9 | S13: 11.45 | T13: 9.79 | U13: 0.112 | V13: 0.241 | W13: 1.2 | X13: 0.106 | Y13: 0.439 | Z13: 0.082 | AA13: 0.696 | AB13: 0.509 | AC13: 0.245 | AD13: 1.11 | AE13: 0.243 | AF13: 1.9 | AG13: 0.431 | AH13: 1.33 | AI13: 0.188 | AJ13: 1.38 | AK13: 0.202 | AL13: 0.359 | AM13: 0.0176 | AN13: 0.307 | AO13: <0.0108 | AP13: <0.0073
A14: 013BCR2G | B14: 7.61 | C14: 2.89 | D14: 22549.58 | E14: 20741.1 | F14: 71778.97 | G14: 238369.95 | H14: 1266 | I14: 14150.35 | J14: 50900 | K14: 34.51 | L14: 13547.25 | M14: 401.47 | N14: 1453.95 | O14: 87000.51 | P14: 0.48 | Q14: 46.32 | R14: 336.82 | S14: 36.28 | T14: 183.53 | U14: 12.04 | V14: 1.18 | W14: 672.95 | X14: 23.96 | Y14: 51.39 | Z14: 6.45 | AA14: 28.41 | AB14: 6.08 | AC14: 1.91 | AD14: 6.75 | AE14: 1.008 | AF14: 6.58 | AG14: 1.36 | AH14: 3.72 | AI14: 0.535 | AJ14: 3.53 | AK14: 0.498 | AL14: 5 | AM14: 0.788 | AN14: 10.52 | AO14: 6.08 | AP14: 1.6
A15: 014BCR2G | B15: 7.41 | C15: 3.94 | D15: 22769.95 | E15: 20394.13 | F15: 70870.83 | G15: 243901.92 | H15: 1367.88 | I15: 14391.35 | J15: 50900 | K15: 35.09 | L15: 13583.31 | M15: 404.07 | N15: 1430.87 | O15: 87447.33 | P15: 0.53 | Q15: 46.08 | R15: 334.46 | S15: 35.84 | T15: 182.19 | U15: 12.5 | V15: 1.09 | W15: 660.47 | X15: 23.92 | Y15: 50.78 | Z15: 6.46 | AA15: 28.55 | AB15: 6.25 | AC15: 1.94 | AD15: 6.73 | AE15: 1.035 | AF15: 6.31 | AG15: 1.28 | AH15: 3.68 | AI15: 0.54 | AJ15: 3.52 | AK15: 0.539 | AL15: 4.9 | AM15: 0.835 | AN15: 11.08 | AO15: 6.19 | AP15: 1.72
A16: 015MC22-1-16 | B16: 5.1 | C16: 1.22 | D16: 20562.38 | E16: 232828.48 | F16: 68050.4 | G16: 284910.28 | H16: 2543.37 | I16: 9764.58 | J16: 88337.04 | K16: 38.06 | L16: 19325.18 | M16: 308.06 | N16: 2454.12 | O16: 147266.05 | P16: 0.71 | Q16: 29.62 | R16: 887.36 | S16: 20.75 | T16: 291.34 | U16: 93.89 | V16: 0.344 | W16: 400.57 | X16: 62.11 | Y16: 127.59 | Z16: 14.66 | AA16: 57.33 | AB16: 9.25 | AC16: 2.88 | AD16: 6.8 | AE16: 0.877 | AF16: 4.62 | AG16: 0.88 | AH16: 2.47 | AI16: 0.262 | AJ16: 1.37 | AK16: 0.288 | AL16: 6.86 | AM16: 4.96 | AN16: 11.88 | AO16: 7.32 | AP16: 1.88
A17: 016MC22-1-20 | B17: 3.67 | C17: 1.34 | D17: 19468.77 | E17: 28620.62 | F17: 70750.84 | G17: 168647.69 | H17: 1732 | I17: 8132.88 | J17: 96484.63 | K17: 36.79 | L17: 25114.34 | M17: 373.63 | N17: 1104.18 | O17: 64490.9 | P17: 0.36 | Q17: 22 | R17: 748.44 | S17: 30.41 | T17: 307.45 | U17: 63.65 | V17: 0.249 | W17: 308.48 | X17: 42.6 | Y17: 88.95 | Z17: 11.22 | AA17: 52.14 | AB17: 10.29 | AC17: 3.08 | AD17: 7.41 | AE17: 1.06 | AF17: 6.56 | AG17: 1.16 | AH17: 2.98 | AI17: 0.336 | AJ17: 2.04 | AK17: 0.375 | AL17: 7.63 | AM17: 3.54 | AN17: 6.07 | AO17: 4.58 | AP17: 1.27
A18: 017MC22-1-21 | B18: 4.47 | C18: 0.95 | D18: 15344.5 | E18: 107028.45 | F18: 59117.61 | G18: 189700.77 | H18: 1182.82 | I18: 5739.62 | J18: 94269.05 | K18: 33.69 | L18: 23916.99 | M18: 287.85 | N18: 1806.7 | O18: 109588.72 | P18: 0.37 | Q18: 11.69 | R18: 3855.13 | S18: 24.87 | T18: 275.61 | U18: 57.6 | V18: 0.137 | W18: 368.46 | X18: 37.45 | Y18: 78.94 | Z18: 10.63 | AA18: 50.12 | AB18: 9.81 | AC18: 2.45 | AD18: 6.11 | AE18: 0.839 | AF18: 6.06 | AG18: 1.04 | AH18: 2.46 | AI18: 0.308 | AJ18: 1.92 | AK18: 0.391 | AL18: 5.96 | AM18: 2.8 | AN18: 8.99 | AO18: 4.65 | AP18: 1.17
A19: 018MC22-1-26 | B19: 7.33 | C19: 1.54 | D19: 30900.85 | E19: 30189.96 | F19: 80352.15 | G19: 207945.72 | H19: 2456.18 | I19: 11276.95 | J19: 95484.05 | K19: 30.08 | L19: 18899.87 | M19: 284.17 | N19: 1501.65 | O19: 82007.19 | P19: 0.69 | Q19: 38.32 | R19: 1183.1 | S19: 35.05 | T19: 395.12 | U19: 95.9 | V19: 0.47 | W19: 481.34 | X19: 75.35 | Y19: 150.79 | Z19: 17.47 | AA19: 67.86 | AB19: 11.77 | AC19: 3.56 | AD19: 10.14 | AE19: 1.35 | AF19: 7.44 | AG19: 1.28 | AH19: 3.32 | AI19: 0.465 | AJ19: 2.68 | AK19: 0.36 | AL19: 8.82 | AM19: 5.9 | AN19: 5.22 | AO19: 8.82 | AP19: 2.08
A20: 019MC22-1-26B | B20: 7.07 | C20: 1.82 | D20: 30029.12 | E20: 31361.74 | F20: 78365.78 | G20: 204026.72 | H20: 2441.65 | I20: 11191.87 | J20: 95484.05 | K20: 30.82 | L20: 18538.85 | M20: 279.02 | N20: 1483.01 | O20: 79970.2 | P20: 0.72 | Q20: 36.3 | R20: 1169.94 | S20: 35.21 | T20: 397.16 | U20: 94.46 | V20: 0.44 | W20: 469.34 | X20: 74.06 | Y20: 147.83 | Z20: 17.53 | AA20: 67.29 | AB20: 11.83 | AC20: 3.42 | AD20: 10.12 | AE20: 1.38 | AF20: 7.24 | AG20: 1.28 | AH20: 3.09 | AI20: 0.429 | AJ20: 2.73 | AK20: 0.389 | AL20: 8.72 | AM20: 5.85 | AN20: 18.13 | AO20: 9.01 | AP20: 1.91
A21: 020MC22-1-27 | B21: 5.7 | C21: 1.57 | D21: 25121.98 | E21: 21731.77 | F21: 70488.98 | G21: 174514.03 | H21: 2268.46 | I21: 12721.8 | J21: 75615.36 | K21: 17.93 | L21: 16016.61 | M21: 212.8 | N21: 1259.88 | O21: 66244.79 | P21: 0.72 | Q21: 39.7 | R21: 1241.61 | S21: 31.82 | T21: 372.44 | U21: 85.9 | V21: 0.48 | W21: 453.51 | X21: 63.43 | Y21: 144.71 | Z21: 18.79 | AA21: 65.85 | AB21: 9.82 | AC21: 2.88 | AD21: 7.73 | AE21: 1.26 | AF21: 6.21 | AG21: 1.09 | AH21: 2.58 | AI21: 0.342 | AJ21: 2.47 | AK21: 0.286 | AL21: 6.55 | AM21: 4.71 | AN21: 21.82 | AO21: 7.71 | AP21: 1.66
A22: 021MC22-2-1 | B22: 5.2 | C22: 0.96 | D22: 17005.31 | E22: 519711.91 | F22: 76921.13 | G22: 491516.72 | H22: 1786.53 | I22: 8273.93 | J22: 90052.32 | K22: 47.17 | L22: 16352.89 | M22: 214.67 | N22: 3556.48 | O22: 219087.5 | P22: 0.31 | Q22: 15.78 | R22: 760.17 | S22: 29.94 | T22: 298.4 | U22: 48.69 | V22: 0.174 | W22: 187.02 | X22: 29.03 | Y22: 80.21 | Z22: 11.87 | AA22: 50.02 | AB22: 7.34 | AC22: 1.91 | AD22: 5.37 | AE22: 1.19 | AF22: 5.18 | AG22: 0.77 | AH22: 1.61 | AI22: 0.225 | AJ22: 2.88 | AK22: 0.294 | AL22: 5.63 | AM22: 2.14 | AN22: 100.83 | AO22: 3.68 | AP22: 0.98
A23: 022MC22-2-5 | B23: 3.61 | C23: 0.88 | D23: 23006.44 | E23: 31592.42 | F23: 71867.45 | G23: 170653.77 | H23: 1900.95 | I23: 9979.52 | J23: 88194.09 | K23: 31.71 | L23: 19300.11 | M23: 286.62 | N23: 1039.76 | O23: 64840.56 | P23: 0.46 | Q23: 27.29 | R23: 883.03 | S23: 25.18 | T23: 288.92 | U23: 80.93 | V23: 0.303 | W23: 380.46 | X23: 62.77 | Y23: 120.21 | Z23: 13.43 | AA23: 50.92 | AB23: 7.93 | AC23: 2.32 | AD23: 7.15 | AE23: 1.035 | AF23: 5.13 | AG23: 0.92 | AH23: 2.41 | AI23: 0.298 | AJ23: 2.11 | AK23: 0.269 | AL23: 6.41 | AM23: 4.76 | AN23: 3.72 | AO23: 6.61 | AP23: 1.5
A24: 023MC22-2-8 | B24: 3.09 | C24: 5.8 | D24: 11938.23 | E24: 136057.78 | F24: 45683.98 | G24: 208577.73 | H24: 1904.76 | I24: 7952.87 | J24: 93482.88 | K24: 28.16 | L24: 16378.47 | M24: 241.05 | N24: 1659.64 | O24: 107640.5 | P24: 0.69 | Q24: 16.06 | R24: 742.53 | S24: 19.86 | T24: 246.33 | U24: 86.19 | V24: 0.167 | W24: 252.32 | X24: 42.65 | Y24: 85.75 | Z24: 12.43 | AA24: 52.15 | AB24: 8.04 | AC24: 2.21 | AD24: 5.06 | AE24: 0.79 | AF24: 4.63 | AG24: 0.541 | AH24: 1.92 | AI24: 0.218 | AJ24: 1.79 | AK24: 0.157 | AL24: 4.03 | AM24: 3.56 | AN24: 153.69 | AO24: 6.04 | AP24: 1.38
A25: 024KL2 | B25: 5.07 | C25: 2.67 | D25: 18232.34 | E25: 45009.12 | F25: 73842.78 | G25: 243282.55 | H25: 1137.23 | I25: 3938.91 | J25: 77901.7 | K25: 31.33 | L25: 15301.9 | M25: 304.17 | N25: 1274.33 | O25: 88705.16 | P25: 0.19 | Q25: 8.58 | R25: 359 | S25: 26.11 | T25: 154.58 | U25: 14.98 | V25: 0.115 | W25: 131.64 | X25: 14.4 | Y25: 33.36 | Z25: 4.64 | AA25: 21.81 | AB25: 5.53 | AC25: 1.91 | AD25: 6.13 | AE25: 0.939 | AF25: 5.54 | AG25: 1.03 | AH25: 2.73 | AI25: 0.361 | AJ25: 2.14 | AK25: 0.305 | AL25: 4.51 | AM25: 1.05 | AN25: 2.17 | AO25: 1.09 | AP25: 0.513
... A42: 042KL2 | B42: 4.48 | C42: 2.24 | D42: 16538.59 | E42: 41223.55 | F42: 67925.31 | G42: 230785.91 | H42: 963.73 | I42: 4043.26 | J42: 77901.69 | K42: 31.62 | L42: 14438.25 | M42: 281.27 | N42: 1156.76 | O42: 75409.52 | P42: 0.124 | Q42: 8.5 | R42: 341 | S42: 26.36 | T42: 155.92 | U42: 13.88 | V42: 0.127 | W42: 107.87 | X42: 11.96 | Y42: 29.97 | Z42: 4.4 | AA42: 21 | AB42: 5.39 | AC42: 1.72 | AD42: 5.81 | AE42: 0.842 | AF42: 5.2 | AG42: 0.9 | AH42: 2.23 | AI42: 0.315 | AJ42: 2.23 | AK42: 0.292 | AL42: 3.91 | AM42: 0.89 | AN42: 1.88 | AO42: 1.02 | AP42: 0.438
A43: 043GOR132 | B43: 8.93 | C43: 15 | D43: 6291.95 | E43: 139167.44 | F43: 56518.28 | G43: 210152.63 | H43: 125.28 | I43: 175.82 | J43: 60392.23 | K43: 33.48 | L43: 1809.47 | M43: 228.15 | N43: 1230.28 | O43: 81603.91 | P43: 0.145 | Q43: 2.04 | R43: 15.38 | S43: 12.05 | T43: 9.11 | U43: 0.044 | V43: 7.8 | W43: 0.811 | X43: 0.079 | Y43: 0.354 | Z43: 0.0848 | AA43: 0.563 | AB43: 0.481 | AC43: 0.254 | AD43: 1.11 | AE43: 0.231 | AF43: 2.13 | AG43: 0.446 | AH43: 1.42 | AI43: 0.226 | AJ43: 1.42 | AK43: 0.204 | AL43: 0.362 | AM43: 0.0202 | AN43: 21.97 | AO43: <0.0086 | AP43: 0.051
A44: 044KL2 | B44: 5.07 | C44: 2.28 | D44: 17274.14 | E44: 43054.39 | F44: 68768.38 | G44: 238980.2 | H44: 1008.25 | I44: 4070.78 | J44: 77901.68 | K44: 32.54 | L44: 15758.94 | M44: 313.24 | N44: 1277.02 | O44: 82468.35 | P44: 0.22 | Q44: 8.79 | R44: 347.28 | S44: 25.28 | T44: 146.94 | U44: 15.23 | V44: 0.132 | W44: 122.1 | X44: 13.01 | Y44: 31.82 | Z44: 4.59 | AA44: 21.38 | AB44: 5.44 | AC44: 1.95 | AD44: 6.02 | AE44: 0.87 | AF44: 5.06 | AG44: 1 | AH44: 2.53 | AI44: 0.32 | AJ44: 1.97 | AK44: 0.285 | AL44: 4.14 | AM44: 0.92 | AN44: 2.13 | AO44: 1.01 | AP44: 0.474
A45: 045KL2 | B45: 4.99 | C45: 2.47 | D45: 17742.6 | E45: 43981.13 | F45: 69712.15 | G45: 240256.08 | H45: 1042.94 | I45: 3973.53 | J45: 77901.69 | K45: 31.49 | L45: 15681.25 | M45: 310.46 | N45: 1267.86 | O45: 84367.95 | P45: 0.155 | Q45: 8.93 | R45: 352.89 | S45: 24.92 | T45: 148.61 | U45: 14.96 | V45: 0.126 | W45: 119.61 | X45: 12.62 | Y45: 32.14 | Z45: 4.44 | AA45: 20.11 | AB45: 5.31 | AC45: 1.91 | AD45: 5.7 | AE45: 0.864 | AF45: 5.03 | AG45: 0.9 | AH45: 2.55 | AI45: 0.34 | AJ45: 2.06 | AK45: 0.323 | AL45: 3.97 | AM45: 0.9 | AN45: 2.06 | AO45: 1.03 | AP45: 0.502
A46: 046KL2 | B46: 5.13 | C46: 2.9 | D46: 17731.5 | E46: 44485.9 | F46: 68889.89 | G46: 237803.67 | H46: 1026.99 | I46: 4027.16 | J46: 77901.69 | K46: 31.07 | L46: 15243.38 | M46: 309.66 | N46: 1275.52 | O46: 85911.7 | P46: 0.165 | Q46: 8.64 | R46: 350.88 | S46: 24.52 | T46: 148.25 | U46: 14.96 | V46: 0.102 | W46: 120.9 | X46: 12.85 | Y46: 31.96 | Z46: 4.43 | AA46: 20.59 | AB46: 5.16 | AC46: 1.86 | AD46: 6.07 | AE46: 0.854 | AF46: 4.77 | AG46: 0.93 | AH46: 2.53 | AI46: 0.315 | AJ46: 2.07 | AK46: 0.256 | AL46: 3.59 | AM46: 0.92 | AN46: 2.09 | AO46: 1 | AP46: 0.514
A47: 047GOR128 | B47: 9.24 | C47: 17.88 | D47: 4404.9 | E47: 141464.02 | F47: 52126.84 | G47: 197711.66 | H47: 80.03 | I47: 206.4 | J47: 44597.33 | K47: 29.57 | L47: 1726.76 | M47: 186.72 | N47: 1363.61 | O47: 76592.48 | P47: <0.076 | Q47: 0.364 | R47: 29.94 | S47: 11 | T47: 8.98 | U47: 0.097 | V47: 0.194 | W47: 1.02 | X47: 0.113 | Y47: 0.453 | Z47: 0.0767 | AA47: 0.724 | AB47: 0.505 | AC47: 0.271 | AD47: 1.09 | AE47: 0.234 | AF47: 1.82 | AG47: 0.401 | AH47: 1.32 | AI47: 0.156 | AJ47: 1.18 | AK47: 0.167 | AL47: 0.344 | AM47: 0.0166 | AN47: 0.31 | AO47: <0.0067 | AP47: 0.0095
A48: 048MC59-1-2A | B48: 9.79 | C48: 2.62 | D48: 44626.88 | E48: 59173.95 | F48: 106219.51 | G48: 253006.88 | H48: 3797.93 | I48: 22731.52 | J48: 64751.9 | K48: 16.17 | L48: 20015.58 | M48: 176.06 | N48: 1745.18 | O48: 77952.2 | P48: 1.01 | Q48: 69.05 | R48: 1197.36 | S48: 39.48 | T48: 460.83 | U48: 143.83 | V48: 0.58 | W48: 697.19 | X48: 111.63 | Y48: 237.74 | Z48: 26.36 | AA48: 92 | AB48: 13.79 | AC48: 4.35 | AD48: 11.63 | AE48: 1.68 | AF48: 8.1 | AG48: 1.43 | AH48: 3.5 | AI48: 0.53 | AJ48: 3.58 | AK48: 0.427 | AL48: 8.21 | AM48: 8.65 | AN48: 10.37 | AO48: 11.27 | AP48: 2.9
A49: 049MC59-2-1A | B49: 4.3 | C49: 2.32 | D49: 27329.81 | E49: 21154.34 | F49: 81745.2 | G49: 190084.97 | H49: 4388.04 | I49: 8578.81 | J49: 114137.73 | K49: 34.87 | L49: 23252.36 | M49: 350.26 | N49: 966.41 | O49: 58572.9 | P49: 0.4 | Q49: 22.02 | R49: 633.7 | S49: 28.57 | T49: 224.41 | U49: 41.96 | V49: 0.281 | W49: 275.03 | X49: 27.44 | Y49: 64.62 | Z49: 9.07 | AA49: 41.34 | AB49: 9.3 | AC49: 2.94 | AD49: 8.13 | AE49: 1.08 | AF49: 5.86 | AG49: 1.17 | AH49: 2.71 | AI49: 0.418 | AJ49: 2.34 | AK49: 0.309 | AL49: 5.44 | AM49: 2.56 | AN49: 2.8 | AO49: 2.4 | AP49: 0.86
A50: 050MC59-2-6A | B50: 6.87 | C50: 3.75 | D50: 33087.27 | E50: 40047.36 | F50: 96657.41 | G50: 224707.58 | H50: 6166.63 | I50: 35982.24 | J50: 76830.34 | K50: 22.48 | L50: 13132.22 | M50: 313.52 | N50: 1453.86 | O50: 74932.47 | P50: 1.45 | Q50: 121.2 | R50: 2279.12 | S50: 32.23 | T50: 459.44 | U50: 250.89 | V50: 1.49 | W50: 1424.14 | X50: 133.39 | Y50: 199.02 | Z50: 19.07 | AA50: 63.42 | AB50: 10.39 | AC50: 3.22 | AD50: 8 | AE50: 1.03 | AF50: 6.2 | AG50: 1.27 | AH50: 3.54 | AI50: 0.47 | AJ50: 3.54 | AK50: 0.515 | AL50: 10.88 | AM50: 16.64 | AN50: 11.58 | AO50: 22.82 | AP50: 5.63
A51: 051MC59-9-1A | B51: 5.87 | C51: 2.75 | D51: 30135.31 | E51: 32786.87 | F51: 86921.61 | G51: 211769.61 | H51: 1809.58 | I51: 9777.27 | J51: 108420.13 | K51: 35.08 | L51: 21476.94 | M51: 331.23 | N51: 1091.11 | O51: 64955.32 | P51: 0.94 | Q51: 37.14 | R51: 1083.29 | S51: 28.8 | T51: 374.14 | U51: 109.45 | V51: 0.52 | W51: 486.48 | X51: 81.54 | Y51: 158.46 | Z51: 16.78 | AA51: 60.77 | AB51: 9.95 | AC51: 3.32 | AD51: 8.51 | AE51: 1.09 | AF51: 6.53 | AG51: 1.14 | AH51: 2.66 | AI51: 0.371 | AJ51: 2.31 | AK51: 0.282 | AL51: 8.81 | AM51: 6.35 | AN51: 3.79 | AO51: 9.51 | AP51: 2.63
A52: 052MC59-9-1B | B52: 5.53 | C52: 2.92 | D52: 31089.67 | E52: 87649.75 | F52: 86524.04 | G52: 258177.17 | H52: 1951.97 | I52: 10592.96 | J52: 112350.98 | K52: 41.18 | L52: 20577.35 | M52: 301.14 | N52: 1535.05 | O52: 113570.77 | P52: 0.96 | Q52: 37.59 | R52: 990.34 | S52: 26.62 | T52: 390.05 | U52: 96.9 | V52: 0.51 | W52: 480.95 | X52: 89.43 | Y52: 154.11 | Z52: 16.67 | AA52: 61.77 | AB52: 9.27 | AC52: 2.86 | AD52: 9.62 | AE52: 1.09 | AF52: 6.77 | AG52: 1.36 | AH52: 3.48 | AI52: 0.42 | AJ52: 1.93 | AK52: 0.383 | AL52: 10.54 | AM52: 6.91 | AN52: 4.26 | AO52: 10.03 | AP52: 2.4
A53: 053MC59-9-1B2 | B53: 6.25 | C53: 3.88 | D53: 40759.39 | E53: 50641.32 | F53: 94393.63 | G53: 310093.81 | H53: 2735.54 | I53: 13822.55 | J53: 112350.98 | K53: 38.86 | L53: 20957.25 | M53: 383.45 | N53: 1403.14 | O53: 102356.7 | P53: 1.28 | Q53: 52.98 | R53: 1188.79 | S53: 31.9 | T53: 453.19 | U53: 133.69 | V53: 0.69 | W53: 554.89 | X53: 93.78 | Y53: 182.51 | Z53: 19.36 | AA53: 70.78 | AB53: 10.85 | AC53: 3.47 | AD53: 9.95 | AE53: 1.27 | AF53: 6.49 | AG53: 1.27 | AH53: 3.5 | AI53: 0.363 | AJ53: 2.59 | AK53: 0.307 | AL53: 10.28 | AM53: 7.11 | AN53: 6.63 | AO53: 11.19 | AP53: 3.18
A54: 054MC59-2-8A | B54: 3.95 | C54: 0.72 | D54: 23829.33 | E54: 116898.38 | F54: 89292.41 | G54: 237802.3 | H54: 1646.56 | I54: 8239.21 | J54: 113280.09 | K54: 36.76 | L54: 18960.86 | M54: 305.44 | N54: 1290.7 | O54: 79327.91 | P54: 0.7 | Q54: 22.08 | R54: 844.19 | S54: 29.47 | T54: 281.84 | U54: 59.65 | V54: 0.213 | W54: 329.55 | X54: 44.13 | Y54: 98.57 | Z54: 12.46 | AA54: 49.66 | AB54: 8.51 | AC54: 2.86 | AD54: 7.39 | AE54: 1.11 | AF54: 5.51 | AG54: 1.02 | AH54: 2.5 | AI54: 0.333 | AJ54: 2.45 | AK54: 0.252 | AL54: 5.66 | AM54: 3.75 | AN54: 6.19 | AO54: 4.4 | AP54: 1.22
A55: 055MC59-1-3A | B55: 4.02 | C55: 2.71 | D55: 29689.55 | E55: 220437.08 | F55: 102801.8 | G55: 307653.09 | H55: 1631.29 | I55: 8241.64 | J55: 112636.85 | K55: 37.07 | L55: 20528.77 | M55: 356.1 | N55: 2041.39 | O55: 127461.78 | P55: 0.38 | Q55: 27.24 | R55: 996.57 | S55: 30.58 | T55: 286.6 | U55: 68.31 | V55: 0.238 | W55: 355.64 | X55: 63.08 | Y55: 132.64 | Z55: 14.48 | AA55: 56.93 | AB55: 10.03 | AC55: 3.39 | AD55: 8.9 | AE55: 1.2 | AF55: 7.48 | AG55: 1.29 | AH55: 3.73 | AI55: 0.54 | AJ55: 2.77 | AK55: 0.359 | AL55: 7.5 | AM55: 4.63 | AN55: 5.89 | AO55: 4.92 | AP55: 1.46
A56: 056MC59-1-3B | B56: 4.59 | C56: 2.47 | D56: 29368.58 | E56: 39620.71 | F56: 99742.35 | G56: 207311.67 | H56: 3121.11 | I56: 13489.34 | J56: 106990.72 | K56: 27.33 | L56: 18286.2 | M56: 387.83 | N56: 1138.03 | O56: 67592.09 | P56: 0.82 | Q56: 44.77 | R56: 1363.1 | S56: 36.47 | T56: 402.56 | U56: 125.36 | V56: 0.38 | W56: 614.54 | X56: 111.66 | Y56: 208.29 | Z56: 22.16 | AA56: 79.1 | AB56: 12.42 | AC56: 3.7 | AD56: 10.79 | AE56: 1.45 | AF56: 7.34 | AG56: 1.43 | AH56: 3.6 | AI56: 0.53 | AJ56: 2.95 | AK56: 0.327 | AL56: 8.49 | AM56: 8.2 | AN56: 21.06 | AO56: 10.43 | AP56: 2.56
...

Sheet Not MDL Filltered
B1: Element | C1: Li7 | D1: B11 | E1: Na23 | F1: Mg24 | G1: Al27 | H1: Si29 | I1: P31 | J1: K39 | K1: Ca43 | L1: Sc45 | M1: Ti47 | N1: V51 | O1: Mn55 | P1: Fe57 | Q1: As75 | R1: Rb85 | S1: Sr88 | T1: Y89 | U1: Zr90 | V1: Nb93 | W1: Cs133 | X1: Ba138 | Y1: La139 | Z1: Ce140 | AA1: Pr141 | AB1: Nd146 | AC1: Sm147 | AD1: Eu151 | AE1: Gd157 | AF1: Tb159 | AG1: Dy163 | AH1: Ho165 | AI1: Er166 | AJ1: Tm169 | AK1: Yb172 | AL1: Lu175 | AM1: Hf178 | AN1: Ta181 | AO1: Pb208 | AP1: Th232 | AQ1: U238
A2: 1 | B2: 004KL2 | C2: 5.21 | D2: 10.95 | E2: 17091.78 | F2: 43329.79 | G2: 68000.88 | H2: 227196.58 | I2: 977.73 | J2: 4196.2 | K2: 77901.7 | L2: 31.16 | M2: 15566.6 | N2: 312.43 | O2: 1303.11 | P2: 81991.84 | Q2: 0.165 | R2: 8.56 | S2: 351.98 | T2: 24.42 | U2: 158.89 | V2: 15.42 | W2: 0.122 | X2: 122.36 | Y2: 12.99 | Z2: 33.23 | AA2: 4.41 | AB2: 21.36 | AC2: 5.49 | AD2: 1.88 | AE2: 5.94 | AF2: 0.844 | AG2: 5.15 | AH2: 0.94 | AI2: 2.41 | AJ2: 0.288 | AK2: 2.1 | AL2: 0.261 | AM2: 3.72 | AN2: 0.934 | AO2: 2.06 | AP2: 0.913 | AQ2: 0.636
A3: 2 | B3: 005KL2 | C3: 5.22 | D3: 2.48 | E3: 17245.47 | F3: 44940.31 | G3: 69620.05 | H3: 233055.86 | I3: 919.53 | J3: 4019.08 | K3: 77901.7 | L3: 31.98 | M3: 15304.21 | N3: 310.73 | O3: 1286.29 | P3: 82919.68 | Q3: 0.107 | R3: 8.89 | S3: 353.77 | T3: 24.97 | U3: 147.91 | V3: 14.71 | W3: 0.11 | X3: 123.03 | Y3: 13.2 | Z3: 31.48 | AA3: 4.63 | AB3: 21.51 | AC3: 5.69 | AD3: 1.83 | AE3: 5.69 | AF3: 0.889 | AG3: 5.19 | AH3: 0.96 | AI3: 2.49 | AJ3: 0.33 | AK3: 2.08 | AL3: 0.288 | AM3: 3.69 | AN3: 0.936 | AO3: 2.08 | AP3: 0.977 | AQ3: 0.558
A4: 3 | B4: 006KL2 | C4: 5.23 | D4: 2.07 | E4: 18130.38 | F4: 46158.29 | G4: 72111.45 | H4: 241409.72 | I4: 956.5 | J4: 4085.24 | K4: 77901.7 | L4: 31.86 | M4: 15292.14 | N4: 314.17 | O4: 1316.63 | P4: 85107.55 | Q4: 0.199 | R4: 9.14 | S4: 362.8 | T4: 25.12 | U4: 149.61 | V4: 15.33 | W4: 0.11 | X4: 123.64 | Y4: 12.47 | Z4: 32.16 | AA4: 4.63 | AB4: 21.58 | AC4: 5.58 | AD4: 1.95 | AE4: 6.14 | AF4: 0.907 | AG4: 4.97 | AH4: 0.859 | AI4: 2.57 | AJ4: 0.341 | AK4: 2.04 | AL4: 0.295 | AM4: 3.87 | AN4: 0.97 | AO4: 2.11 | AP4: 1.05 | AQ4: 0.575
A5: 4 | B5: 007BM90 | C5: 2.02 | D5: 1.67 | E5: 872.46 | F5: 208008.56 | G5: 12476.81 | H5: 241693.27 | I5: 18.41 | J5: <-1.00 | K5: 15008.72 | L5: 16.53 | M5: 367.15 | N5: 56 | O5: 835.55 | P5: 56222.92 | Q5: 0.104 | R5: 0.262 | S5: 0.669 | T5: 2.21 | U5: 20.02 | V5: 0.022 | W5: 0.84 | X5: 0.463 | Y5: 0.215 | Z5: 0.414 | AA5: 0.0784 | AB5: 0.412 | AC5: 0.107 | AD5: 0.0436 | AE5: 0.282 | AF5: 0.0438 | AG5: 0.359 | AH5: 0.084 | AI5: 0.216 | AJ5: 0.0425 | AK5: 0.301 | AL5: 0.0561 | AM5: 0.59 | AN5: 0.0046 | AO5: 0.475 | AP5: 0.056 | AQ5: 0.085
A6: 5 | B6: 008BM90 | C6: 1.72 | D6: 1.76 | E6: 868.99 | F6: 208148.02 | G6: 12030.06 | H6: 241599.27 | I6: 17.81 | J6: <-1.00 | K6: 15008.72 | L6: 16.46 | M6: 348.62 | N6: 55.91 | O6: 843.48 | P6: 56710.61 | Q6: 0.073 | R6: 0.304 | S6: 0.65 | T6: 2.32 | U6: 19.52 | V6: 0.006 | W6: 0.9 | X6: 0.44 | Y6: 0.177 | Z6: 0.443 | AA6: 0.0734 | AB6: 0.389 | AC6: 0.151 | AD6: 0.0526 | AE6: 0.28 | AF6: 0.0453 | AG6: 0.387 | AH6: 0.091 | AI6: 0.258 | AJ6: 0.0465 | AK6: 0.318 | AL6: 0.0548 | AM6: 0.543 | AN6: 0.0024 | AO6: 0.479 | AP6: 0.0545 | AQ6: 0.072
A7: 6 | B7: 009GOR132 | C7: 8.87 | D7: 11.71 | E7: 6672.55 | F7: 142794.02 | G7: 57438.87 | H7: 218643.95 | I7: 118.34 | J7: 189.71 | K7: 60392.23 | L7: 35.59 | M7: 1785.51 | N7: 233.08 | O7: 1251.49 | P7: 86376.49 | Q7: 0.141 | R7: 2.31 | S7: 15.82 | T7: 13.19 | U7: 9.58 | V7: 0.069 | W7: 8.21 | X7: 0.868 | Y7: 0.093 | Z7: 0.344 | AA7: 0.088 | AB7: 0.743 | AC7: 0.486 | AD7: 0.262 | AE7: 1.14 | AF7: 0.215 | AG7: 2.08 | AH7: 0.489 | AI7: 1.6 | AJ7: 0.229 | AK7: 1.42 | AL7: 0.232 | AM7: 0.348 | AN7: 0.0362 | AO7: 22.24 | AP7: 0.0075 | AQ7: 0.051
A8: 7 | B8: 010GOR132 | C8: 8.99 | D8: 11.28 | E8: 6319.15 | F8: 138234.5 | G8: 56407.36 | H8: 212192.69 | I8: 111.61 | J8: 165.22 | K8: 60392.23 | L8: 34.88 | M8: 1743.55 | N8: 220.64 | O8: 1203.94 | P8: 83189.79 | Q8: 0.107 | R8: 2.15 | S8: 15.1 | T8: 13.12 | U8: 9.84 | V8: 0.0263 | W8: 8.04 | X8: 0.683 | Y8: 0.08 | Z8: 0.311 | AA8: 0.0847 | AB8: 0.609 | AC8: 0.511 | AD8: 0.278 | AE8: 1.27 | AF8: 0.264 | AG8: 2.03 | AH8: 0.504 | AI8: 1.55 | AJ8: 0.222 | AK8: 1.54 | AL8: 0.229 | AM8: 0.323 | AN8: 0.0259 | AO8: 21.39 | AP8: 0.0018 | AQ8: 0.066
A9: 8 | B9: 011GOR128 | C9: 10.12 | D9: 14.42 | E9: 4600.63 | F9: 147788.48 | G9: 50541.61 | H9: 213893.53 | I9: 86.35 | J9: 246.9 | K9: 44597.34 | L9: 30.37 | M9: 1671.98 | N9: 183.08 | O9: 1441.6 | P9: 84292.74 | Q9: 0.126 | R9: 0.338 | S9: 29.01 | T9: 11.38 | U9: 9.33 | V9: 0.115 | W9: 0.208 | X9: 0.956 | Y9: 0.104 | Z9: 0.402 | AA9: 0.094 | AB9: 0.659 | AC9: 0.444 | AD9: 0.279 | AE9: 1.34 | AF9: 0.224 | AG9: 1.86 | AH9: 0.407 | AI9: 1.38 | AJ9: 0.198 | AK9: 1.21 | AL9: 0.181 | AM9: 0.345 | AN9: 0.0178 | AO9: 0.308 | AP9: -0.0044 | AQ9: 0.0109
A10: 9 | B10: 012GOR128 | C10: 11.13 | D10: 16.56 | E10: 5316.96 | F10: 203682.8 | G10: 54948.23 | H10: 247541.09 | I10: 94.16 | J10: 243.42 | K10: 44597.34 | L10: 32.09 | M10: 1751.93 | N10: 197.64 | O10: 1506.44 | P10: 85512.35 | Q10: 0.212 | R10: 0.48 | S10: 31.9 | T10: 11.45 | U10: 9.79 | V10: 0.112 | W10: 0.241 | X10: 1.2 | Y10: 0.106 | Z10: 0.439 | AA10: 0.082 | AB10: 0.696 | AC10: 0.509 | AD10: 0.245 | AE10: 1.11 | AF10: 0.243 | AG10: 1.9 | AH10: 0.431 | AI10: 1.33 | AJ10: 0.188 | AK10: 1.38 | AL10: 0.202 | AM10: 0.359 | AN10: 0.0176 | AO10: 0.307 | AP10: 0.0039 | AQ10: 0.006
A11: 10 | B11: 013BCR2G | C11: 7.61 | D11: 2.89 | E11: 22549.58 | F11: 20741.1 | G11: 71778.97 | H11: 238369.95 | I11: 1266 | J11: 14150.35 | K11: 50900 | L11: 34.51 | M11: 13547.25 | N11: 401.47 | O11: 1453.95 | P11: 87000.51 | Q11: 0.48 | R11: 46.32 | S11: 336.82 | T11: 36.28 | U11: 183.53 | V11: 12.04 | W11: 1.18 | X11: 672.95 | Y11: 23.96 | Z11: 51.39 | AA11: 6.45 | AB11: 28.41 | AC11: 6.08 | AD11: 1.91 | AE11: 6.75 | AF11: 1.008 | AG11: 6.58 | AH11: 1.36 | AI11: 3.72 | AJ11: 0.535 | AK11: 3.53 | AL11: 0.498 | AM11: 5 | AN11: 0.788 | AO11: 10.52 | AP11: 6.08 | AQ11: 1.6
A12: 11 | B12: 014BCR2G | C12: 7.41 | D12: 3.94 | E12: 22769.95 | F12: 20394.13 | G12: 70870.83 | H12: 243901.92 | I12: 1367.88 | J12: 14391.35 | K12: 50900 | L12: 35.09 | M12: 13583.31 | N12: 404.07 | O12: 1430.87 | P12: 87447.33 | Q12: 0.53 | R12: 46.08 | S12: 334.46 | T12: 35.84 | U12: 182.19 | V12: 12.5 | W12: 1.09 | X12: 660.47 | Y12: 23.92 | Z12: 50.78 | AA12: 6.46 | AB12: 28.55 | AC12: 6.25 | AD12: 1.94 | AE12: 6.73 | AF12: 1.035 | AG12: 6.31 | AH12: 1.28 | AI12: 3.68 | AJ12: 0.54 | AK12: 3.52 | AL12: 0.539 | AM12: 4.9 | AN12: 0.835 | AO12: 11.08 | AP12: 6.19 | AQ12: 1.72
A13: 12 | B13: 015MC22-1-16 | C13: 5.1 | D13: 1.22 | E13: 20562.38 | F13: 232828.48 | G13: 68050.4 | H13: 284910.28 | I13: 2543.37 | J13: 9764.58 | K13: 88337.04 | L13: 38.06 | M13: 19325.18 | N13: 308.06 | O13: 2454.12 | P13: 147266.05 | Q13: 0.71 | R13: 29.62 | S13: 887.36 | T13: 20.75 | U13: 291.34 | V13: 93.89 | W13: 0.344 | X13: 400.57 | Y13: 62.11 | Z13: 127.59 | AA13: 14.66 | AB13: 57.33 | AC13: 9.25 | AD13: 2.88 | AE13: 6.8 | AF13: 0.877 | AG13: 4.62 | AH13: 0.88 | AI13: 2.47 | AJ13: 0.262 | AK13: 1.37 | AL13: 0.288 | AM13: 6.86 | AN13: 4.96 | AO13: 11.88 | AP13: 7.32 | AQ13: 1.88
A14: 13 | B14: 016MC22-1-20 | C14: 3.67 | D14: 1.34 | E14: 19468.77 | F14: 28620.62 | G14: 70750.84 | H14: 168647.69 | I14: 1732 | J14: 8132.88 | K14: 96484.63 | L14: 36.79 | M14: 25114.34 | N14: 373.63 | O14: 1104.18 | P14: 64490.9 | Q14: 0.36 | R14: 22 | S14: 748.44 | T14: 30.41 | U14: 307.45 | V14: 63.65 | W14: 0.249 | X14: 308.48 | Y14: 42.6 | Z14: 88.95 | AA14: 11.22 | AB14: 52.14 | AC14: 10.29 | AD14: 3.08 | AE14: 7.41 | AF14: 1.06 | AG14: 6.56 | AH14: 1.16 | AI14: 2.98 | AJ14: 0.336 | AK14: 2.04 | AL14: 0.375 | AM14: 7.63 | AN14: 3.54 | AO14: 6.07 | AP14: 4.58 | AQ14: 1.27
A15: 14 | B15: 017MC22-1-21 | C15: 4.47 | D15: 0.95 | E15: 15344.5 | F15: 107028.45 | G15: 59117.61 | H15: 189700.77 | I15: 1182.82 | J15: 5739.62 | K15: 94269.05 | L15: 33.69 | M15: 23916.99 | N15: 287.85 | O15: 1806.7 | P15: 109588.72 | Q15: 0.37 | R15: 11.69 | S15: 3855.13 | T15: 24.87 | U15: 275.61 | V15: 57.6 | W15: 0.137 | X15: 368.46 | Y15: 37.45 | Z15: 78.94 | AA15: 10.63 | AB15: 50.12 | AC15: 9.81 | AD15: 2.45 | AE15: 6.11 | AF15: 0.839 | AG15: 6.06 | AH15: 1.04 | AI15: 2.46 | AJ15: 0.308 | AK15: 1.92 | AL15: 0.391 | AM15: 5.96 | AN15: 2.8 | AO15: 8.99 | AP15: 4.65 | AQ15: 1.17
A16: 15 | B16: 018MC22-1-26 | C16: 7.33 | D16: 1.54 | E16: 30900.85 | F16: 30189.96 | G16: 80352.15 | H16: 207945.72 | I16: 2456.18 | J16: 11276.95 | K16: 95484.05 | L16: 30.08 | M16: 18899.87 | N16: 284.17 | O16: 1501.65 | P16: 82007.19 | Q16: 0.69 | R16: 38.32 | S16: 1183.1 | T16: 35.05 | U16: 395.12 | V16: 95.9 | W16: 0.47 | X16: 481.34 | Y16: 75.35 | Z16: 150.79 | AA16: 17.47 | AB16: 67.86 | AC16: 11.77 | AD16: 3.56 | AE16: 10.14 | AF16: 1.35 | AG16: 7.44 | AH16: 1.28 | AI16: 3.32 | AJ16: 0.465 | AK16: 2.68 | AL16: 0.36 | AM16: 8.82 | AN16: 5.9 | AO16: 5.22 | AP16: 8.82 | AQ16: 2.08
A17: 16 | B17: 019MC22-1-26B | C17: 7.07 | D17: 1.82 | E17: 30029.12 | F17: 31361.74 | G17: 78365.78 | H17: 204026.72 | I17: 2441.65 | J17: 11191.87 | K17: 95484.05 | L17: 30.82 | M17: 18538.85 | N17: 279.02 | O17: 1483.01 | P17: 79970.2 | Q17: 0.72 | R17: 36.3 | S17: 1169.94 | T17: 35.21 | U17: 397.16 | V17: 94.46 | W17: 0.44 | X17: 469.34 | Y17: 74.06 | Z17: 147.83 | AA17: 17.53 | AB17: 67.29 | AC17: 11.83 | AD17: 3.42 | AE17: 10.12 | AF17: 1.38 | AG17: 7.24 | AH17: 1.28 | AI17: 3.09 | AJ17: 0.429 | AK17: 2.73 | AL17: 0.389 | AM17: 8.72 | AN17: 5.85 | AO17: 18.13 | AP17: 9.01 | AQ17: 1.91
A18: 17 | B18: 020MC22-1-27 | C18: 5.7 | D18: 1.57 | E18: 25121.98 | F18: 21731.77 | G18: 70488.98 | H18: 174514.03 | I18: 2268.46 | J18: 12721.8 | K18: 75615.36 | L18: 17.93 | M18: 16016.61 | N18: 212.8 | O18: 1259.88 | P18: 66244.79 | Q18: 0.72 | R18: 39.7 | S18: 1241.61 | T18: 31.82 | U18: 372.44 | V18: 85.9 | W18: 0.48 | X18: 453.51 | Y18: 63.43 | Z18: 144.71 | AA18: 18.79 | AB18: 65.85 | AC18: 9.82 | AD18: 2.88 | AE18: 7.73 | AF18: 1.26 | AG18: 6.21 | AH18: 1.09 | AI18: 2.58 | AJ18: 0.342 | AK18: 2.47 | AL18: 0.286 | AM18: 6.55 | AN18: 4.71 | AO18: 21.82 | AP18: 7.71 | AQ18: 1.66
... A79: 78 | B79: 083KL2 | C79: 5.32 | D79: 3.69 | E79: 18344.55 | F79: 47033.02 | G79: 74728.29 | H79: 234139.11 | I79: 987.47 | J79: 4088.98 | K79: 77901.7 | L79: 31 | M79: 15255.21 | N79: 314.08 | O79: 1325.92 | P79: 86456.66 | Q79: 0.14 | R79: 9.19 | S79: 374.86 | T79: 25.76 | U79: 153.81 | V79: 15.07 | W79: 0.14 | X79: 128.81 | Y79: 13.81 | Z79: 33.85 | AA79: 4.71 | AB79: 21.04 | AC79: 5.95 | AD79: 1.91 | AE79: 6.31 | AF79: 0.96 | AG79: 5.54 | AH79: 0.94 | AI79: 2.84 | AJ79: 0.346 | AK79: 2.09 | AL79: 0.278 | AM79: 3.95 | AN79: 1 | AO79: 2.11 | AP79: 1.03 | AQ79: 0.56

Sheet MDL Filtered Clean
B1: Element | C1: Li7 | D1: B11 | E1: Na23 | F1: Mg24 | G1: Al27 | H1: Si29 | I1: P31 | J1: K39 | K1: Ca43 | L1: Sc45 | M1: Ti47 | N1: V51 | O1: Mn55 | P1: Fe57 | Q1: As75 | R1: Rb85 | S1: Sr88 | T1: Y89 | U1: Zr90 | V1: Nb93 | W1: Cs133 | X1: Ba138 | Y1: La139 | Z1: Ce140 | AA1: Pr141 | AB1: Nd146 | AC1: Sm147 | AD1: Eu151 | AE1: Gd157 | AF1: Tb159 | AG1: Dy163 | AH1: Ho165 | AI1: Er166 | AJ1: Tm169 | AK1: Yb172 | AL1: Lu175 | AM1: Hf178 | AN1: Ta181 | AO1: Pb208 | AP1: Th232 | AQ1: U238
A2: 1 | B2: 004KL2 | C2: 5.21 | D2: 10.95 | E2: 17091.78 | F2: 43329.79 | G2: 68000.88 | H2: 227196.58 | I2: 977.73 | J2: 4196.2 | K2: 77901.7 | L2: 31.16 | M2: 15566.6 | N2: 312.43 | O2: 1303.11 | P2: 81991.84 | Q2: 0.165 | R2: 8.56 | S2: 351.98 | T2: 24.42 | U2: 158.89 | V2: 15.42 | W2: 0.122 | X2: 122.36 | Y2: 12.99 | Z2: 33.23 | AA2: 4.41 | AB2: 21.36 | AC2: 5.49 | AD2: 1.88 | AE2: 5.94 | AF2: 0.844 | AG2: 5.15 | AH2: 0.94 | AI2: 2.41 | AJ2: 0.288 | AK2: 2.1 | AL2: 0.261 | AM2: 3.72 | AN2: 0.934 | AO2: 2.06 | AP2: 0.913 | AQ2: 0.636
A3: 2 | B3: 005KL2 | C3: 5.22 | D3: 2.48 | E3: 17245.47 | F3: 44940.31 | G3: 69620.05 | H3: 233055.86 | I3: 919.53 | J3: 4019.08 | K3: 77901.7 | L3: 31.98 | M3: 15304.21 | N3: 310.73 | O3: 1286.29 | P3: 82919.68 | Q3: 0.107 | R3: 8.89 | S3: 353.77 | T3: 24.97 | U3: 147.91 | V3: 14.71 | W3: 0.11 | X3: 123.03 | Y3: 13.2 | Z3: 31.48 | AA3: 4.63 | AB3: 21.51 | AC3: 5.69 | AD3: 1.83 | AE3: 5.69 | AF3: 0.889 | AG3: 5.19 | AH3: 0.96 | AI3: 2.49 | AJ3: 0.33 | AK3: 2.08 | AL3: 0.288 | AM3: 3.69 | AN3: 0.936 | AO3: 2.08 | AP3: 0.977 | AQ3: 0.558
A4: 3 | B4: 006KL2 | C4: 5.23 | D4: 2.07 | E4: 18130.38 | F4: 46158.29 | G4: 72111.45 | H4: 241409.72 | I4: 956.5 | J4: 4085.24 | K4: 77901.7 | L4: 31.86 | M4: 15292.14 | N4: 314.17 | O4: 1316.63 | P4: 85107.55 | Q4: 0.199 | R4: 9.14 | S4: 362.8 | T4: 25.12 | U4: 149.61 | V4: 15.33 | W4: 0.11 | X4: 123.64 | Y4: 12.47 | Z4: 32.16 | AA4: 4.63 | AB4: 21.58 | AC4: 5.58 | AD4: 1.95 | AE4: 6.14 | AF4: 0.907 | AG4: 4.97 | AH4: 0.859 | AI4: 2.57 | AJ4: 0.341 | AK4: 2.04 | AL4: 0.295 | AM4: 3.87 | AN4: 0.97 | AO4: 2.11 | AP4: 1.05 | AQ4: 0.575
A5: 4 | B5: 007BM90 | C5: 2.02 | D5: 1.67 | E5: 872.46 | F5: 208008.56 | G5: 12476.81 | H5: 241693.27 | I5: 18.41 | J5: <24.43 | K5: 15008.72 | L5: 16.53 | M5: 367.15 | N5: 56 | O5: 835.55 | P5: 56222.92 | Q5: 0.104 | R5: 0.262 | S5: 0.669 | T5: 2.21 | U5: 20.02 | V5: 0.022 | W5: 0.84 | X5: 0.463 | Y5: 0.215 | Z5: 0.414 | AA5: 0.0784 | AB5: 0.412 | AC5: 0.107 | AD5: 0.0436 | AE5: 0.282 | AF5: 0.0438 | AG5: 0.359 | AH5: 0.084 | AI5: 0.216 | AJ5: 0.0425 | AK5: 0.301 | AL5: 0.0561 | AM5: 0.59 | AN5: 0.0046 | AO5: 0.475 | AP5: 0.056 | AQ5: 0.085
A6: 5 | B6: 008BM90 | C6: 1.72 | D6: 1.76 | E6: 868.99 | F6: 208148.02 | G6: 12030.06 | H6: 241599.27 | I6: 17.81 | J6: <25.01 | K6: 15008.72 | L6: 16.46 | M6: 348.62 | N6: 55.91 | O6: 843.48 | P6: 56710.61 | Q6: <0.074 | R6: 0.304 | S6: 0.65 | T6: 2.32 | U6: 19.52 | V6: <0.0218 | W6: 0.9 | X6: 0.44 | Y6: 0.177 | Z6: 0.443 | AA6: 0.0734 | AB6: 0.389 | AC6: 0.151 | AD6: 0.0526 | AE6: 0.28 | AF6: 0.0453 | AG6: 0.387 | AH6: 0.091 | AI6: 0.258 | AJ6: 0.0465 | AK6: 0.318 | AL6: 0.0548 | AM6: 0.543 | AN6: <0.0062 | AO6: 0.479 | AP6: 0.0545 | AQ6: 0.072
A7: 6 | B7: 009GOR132 | C7: 8.87 | D7: 11.71 | E7: 6672.55 | F7: 142794.02 | G7: 57438.87 | H7: 218643.95 | I7: 118.34 | J7: 189.71 | K7: 60392.23 | L7: 35.59 | M7: 1785.51 | N7: 233.08 | O7: 1251.49 | P7: 86376.49 | Q7: 0.141 | R7: 2.31 | S7: 15.82 | T7: 13.19 | U7: 9.58 | V7: 0.069 | W7: 8.21 | X7: 0.868 | Y7: 0.093 | Z7: 0.344 | AA7: 0.088 | AB7: 0.743 | AC7: 0.486 | AD7: 0.262 | AE7: 1.14 | AF7: 0.215 | AG7: 2.08 | AH7: 0.489 | AI7: 1.6 | AJ7: 0.229 | AK7: 1.42 | AL7: 0.232 | AM7: 0.348 | AN7: 0.0362 | AO7: 22.24 | AP7: 0.0075 | AQ7: 0.051
A8: 7 | B8: 010GOR132 | C8: 8.99 | D8: 11.28 | E8: 6319.15 | F8: 138234.5 | G8: 56407.36 | H8: 212192.69 | I8: 111.61 | J8: 165.22 | K8: 60392.23 | L8: 34.88 | M8: 1743.55 | N8: 220.64 | O8: 1203.94 | P8: 83189.79 | Q8: 0.107 | R8: 2.15 | S8: 15.1 | T8: 13.12 | U8: 9.84 | V8: 0.0263 | W8: 8.04 | X8: 0.683 | Y8: 0.08 | Z8: 0.311 | AA8: 0.0847 | AB8: 0.609 | AC8: 0.511 | AD8: 0.278 | AE8: 1.27 | AF8: 0.264 | AG8: 2.03 | AH8: 0.504 | AI8: 1.55 | AJ8: 0.222 | AK8: 1.54 | AL8: 0.229 | AM8: 0.323 | AN8: 0.0259 | AO8: 21.39 | AP8: <0.0051 | AQ8: 0.066
A9: 8 | B9: 011GOR128 | C9: 10.12 | D9: 14.42 | E9: 4600.63 | F9: 147788.48 | G9: 50541.61 | H9: 213893.53 | I9: 86.35 | J9: 246.9 | K9: 44597.34 | L9: 30.37 | M9: 1671.98 | N9: 183.08 | O9: 1441.6 | P9: 84292.74 | Q9: 0.126 | R9: 0.338 | S9: 29.01 | T9: 11.38 | U9: 9.33 | V9: 0.115 | W9: 0.208 | X9: 0.956 | Y9: 0.104 | Z9: 0.402 | AA9: 0.094 | AB9: 0.659 | AC9: 0.444 | AD9: 0.279 | AE9: 1.34 | AF9: 0.224 | AG9: 1.86 | AH9: 0.407 | AI9: 1.38 | AJ9: 0.198 | AK9: 1.21 | AL9: 0.181 | AM9: 0.345 | AN9: 0.0178 | AO9: 0.308 | AP9: <0.0152 | AQ9: 0.0109
A10: 9 | B10: 012GOR128 | C10: 11.13 | D10: 16.56 | E10: 5316.96 | F10: 203682.8 | G10: 54948.23 | H10: 247541.09 | I10: 94.16 | J10: 243.42 | K10: 44597.34 | L10: 32.09 | M10: 1751.93 | N10: 197.64 | O10: 1506.44 | P10: 85512.35 | Q10: 0.212 | R10: 0.48 | S10: 31.9 | T10: 11.45 | U10: 9.79 | V10: 0.112 | W10: 0.241 | X10: 1.2 | Y10: 0.106 | Z10: 0.439 | AA10: 0.082 | AB10: 0.696 | AC10: 0.509 | AD10: 0.245 | AE10: 1.11 | AF10: 0.243 | AG10: 1.9 | AH10: 0.431 | AI10: 1.33 | AJ10: 0.188 | AK10: 1.38 | AL10: 0.202 | AM10: 0.359 | AN10: 0.0176 | AO10: 0.307 | AP10: <0.0108 | AQ10: <0.0073
A11: 10 | B11: 013BCR2G | C11: 7.61 | D11: 2.89 | E11: 22549.58 | F11: 20741.1 | G11: 71778.97 | H11: 238369.95 | I11: 1266 | J11: 14150.35 | K11: 50900 | L11: 34.51 | M11: 13547.25 | N11: 401.47 | O11: 1453.95 | P11: 87000.51 | Q11: 0.48 | R11: 46.32 | S11: 336.82 | T11: 36.28 | U11: 183.53 | V11: 12.04 | W11: 1.18 | X11: 672.95 | Y11: 23.96 | Z11: 51.39 | AA11: 6.45 | AB11: 28.41 | AC11: 6.08 | AD11: 1.91 | AE11: 6.75 | AF11: 1.008 | AG11: 6.58 | AH11: 1.36 | AI11: 3.72 | AJ11: 0.535 | AK11: 3.53 | AL11: 0.498 | AM11: 5 | AN11: 0.788 | AO11: 10.52 | AP11: 6.08 | AQ11: 1.6
A12: 11 | B12: 014BCR2G | C12: 7.41 | D12: 3.94 | E12: 22769.95 | F12: 20394.13 | G12: 70870.83 | H12: 243901.92 | I12: 1367.88 | J12: 14391.35 | K12: 50900 | L12: 35.09 | M12: 13583.31 | N12: 404.07 | O12: 1430.87 | P12: 87447.33 | Q12: 0.53 | R12: 46.08 | S12: 334.46 | T12: 35.84 | U12: 182.19 | V12: 12.5 | W12: 1.09 | X12: 660.47 | Y12: 23.92 | Z12: 50.78 | AA12: 6.46 | AB12: 28.55 | AC12: 6.25 | AD12: 1.94 | AE12: 6.73 | AF12: 1.035 | AG12: 6.31 | AH12: 1.28 | AI12: 3.68 | AJ12: 0.54 | AK12: 3.52 | AL12: 0.539 | AM12: 4.9 | AN12: 0.835 | AO12: 11.08 | AP12: 6.19 | AQ12: 1.72
A13: 12 | B13: 015MC22-1-16 | C13: 5.1 | D13: 1.22 | E13: 20562.38 | F13: 232828.48 | G13: 68050.4 | H13: 284910.28 | I13: 2543.37 | J13: 9764.58 | K13: 88337.04 | L13: 38.06 | M13: 19325.18 | N13: 308.06 | O13: 2454.12 | P13: 147266.05 | Q13: 0.71 | R13: 29.62 | S13: 887.36 | T13: 20.75 | U13: 291.34 | V13: 93.89 | W13: 0.344 | X13: 400.57 | Y13: 62.11 | Z13: 127.59 | AA13: 14.66 | AB13: 57.33 | AC13: 9.25 | AD13: 2.88 | AE13: 6.8 | AF13: 0.877 | AG13: 4.62 | AH13: 0.88 | AI13: 2.47 | AJ13: 0.262 | AK13: 1.37 | AL13: 0.288 | AM13: 6.86 | AN13: 4.96 | AO13: 11.88 | AP13: 7.32 | AQ13: 1.88
A14: 13 | B14: 016MC22-1-20 | C14: 3.67 | D14: 1.34 | E14: 19468.77 | F14: 28620.62 | G14: 70750.84 | H14: 168647.69 | I14: 1732 | J14: 8132.88 | K14: 96484.63 | L14: 36.79 | M14: 25114.34 | N14: 373.63 | O14: 1104.18 | P14: 64490.9 | Q14: 0.36 | R14: 22 | S14: 748.44 | T14: 30.41 | U14: 307.45 | V14: 63.65 | W14: 0.249 | X14: 308.48 | Y14: 42.6 | Z14: 88.95 | AA14: 11.22 | AB14: 52.14 | AC14: 10.29 | AD14: 3.08 | AE14: 7.41 | AF14: 1.06 | AG14: 6.56 | AH14: 1.16 | AI14: 2.98 | AJ14: 0.336 | AK14: 2.04 | AL14: 0.375 | AM14: 7.63 | AN14: 3.54 | AO14: 6.07 | AP14: 4.58 | AQ14: 1.27
A15: 14 | B15: 017MC22-1-21 | C15: 4.47 | D15: 0.95 | E15: 15344.5 | F15: 107028.45 | G15: 59117.61 | H15: 189700.77 | I15: 1182.82 | J15: 5739.62 | K15: 94269.05 | L15: 33.69 | M15: 23916.99 | N15: 287.85 | O15: 1806.7 | P15: 109588.72 | Q15: 0.37 | R15: 11.69 | S15: 3855.13 | T15: 24.87 | U15: 275.61 | V15: 57.6 | W15: 0.137 | X15: 368.46 | Y15: 37.45 | Z15: 78.94 | AA15: 10.63 | AB15: 50.12 | AC15: 9.81 | AD15: 2.45 | AE15: 6.11 | AF15: 0.839 | AG15: 6.06 | AH15: 1.04 | AI15: 2.46 | AJ15: 0.308 | AK15: 1.92 | AL15: 0.391 | AM15: 5.96 | AN15: 2.8 | AO15: 8.99 | AP15: 4.65 | AQ15: 1.17
A16: 15 | B16: 018MC22-1-26 | C16: 7.33 | D16: 1.54 | E16: 30900.85 | F16: 30189.96 | G16: 80352.15 | H16: 207945.72 | I16: 2456.18 | J16: 11276.95 | K16: 95484.05 | L16: 30.08 | M16: 18899.87 | N16: 284.17 | O16: 1501.65 | P16: 82007.19 | Q16: 0.69 | R16: 38.32 | S16: 1183.1 | T16: 35.05 | U16: 395.12 | V16: 95.9 | W16: 0.47 | X16: 481.34 | Y16: 75.35 | Z16: 150.79 | AA16: 17.47 | AB16: 67.86 | AC16: 11.77 | AD16: 3.56 | AE16: 10.14 | AF16: 1.35 | AG16: 7.44 | AH16: 1.28 | AI16: 3.32 | AJ16: 0.465 | AK16: 2.68 | AL16: 0.36 | AM16: 8.82 | AN16: 5.9 | AO16: 5.22 | AP16: 8.82 | AQ16: 2.08
A17: 16 | B17: 019MC22-1-26B | C17: 7.07 | D17: 1.82 | E17: 30029.12 | F17: 31361.74 | G17: 78365.78 | H17: 204026.72 | I17: 2441.65 | J17: 11191.87 | K17: 95484.05 | L17: 30.82 | M17: 18538.85 | N17: 279.02 | O17: 1483.01 | P17: 79970.2 | Q17: 0.72 | R17: 36.3 | S17: 1169.94 | T17: 35.21 | U17: 397.16 | V17: 94.46 | W17: 0.44 | X17: 469.34 | Y17: 74.06 | Z17: 147.83 | AA17: 17.53 | AB17: 67.29 | AC17: 11.83 | AD17: 3.42 | AE17: 10.12 | AF17: 1.38 | AG17: 7.24 | AH17: 1.28 | AI17: 3.09 | AJ17: 0.429 | AK17: 2.73 | AL17: 0.389 | AM17: 8.72 | AN17: 5.85 | AO17: 18.13 | AP17: 9.01 | AQ17: 1.91
A18: 17 | B18: 020MC22-1-27 | C18: 5.7 | D18: 1.57 | E18: 25121.98 | F18: 21731.77 | G18: 70488.98 | H18: 174514.03 | I18: 2268.46 | J18: 12721.8 | K18: 75615.36 | L18: 17.93 | M18: 16016.61 | N18: 212.8 | O18: 1259.88 | P18: 66244.79 | Q18: 0.72 | R18: 39.7 | S18: 1241.61 | T18: 31.82 | U18: 372.44 | V18: 85.9 | W18: 0.48 | X18: 453.51 | Y18: 63.43 | Z18: 144.71 | AA18: 18.79 | AB18: 65.85 | AC18: 9.82 | AD18: 2.88 | AE18: 7.73 | AF18: 1.26 | AG18: 6.21 | AH18: 1.09 | AI18: 2.58 | AJ18: 0.342 | AK18: 2.47 | AL18: 0.286 | AM18: 6.55 | AN18: 4.71 | AO18: 21.82 | AP18: 7.71 | AQ18: 1.66
A19: 18 | B19: 021MC22-2-1 | C19: 5.2 | D19: 0.96 | E19: 17005.31 | F19: 519711.91 | G19: 76921.13 | H19: 491516.72 | I19: 1786.53 | J19: 8273.93 | K19: 90052.32 | L19: 47.17 | M19: 16352.89 | N19: 214.67 | O19: 3556.48 | P19: 219087.5 | Q19: 0.31 | R19: 15.78 | S19: 760.17 | T19: 29.94 | U19: 298.4 | V19: 48.69 | W19: 0.174 | X19: 187.02 | Y19: 29.03 | Z19: 80.21 | AA19: 11.87 | AB19: 50.02 | AC19: 7.34 | AD19: 1.91 | AE19: 5.37 | AF19: 1.19 | AG19: 5.18 | AH19: 0.77 | AI19: 1.61 | AJ19: 0.225 | AK19: 2.88 | AL19: 0.294 | AM19: 5.63 | AN19: 2.14 | AO19: 100.83 | AP19: 3.68 | AQ19: 0.98
A20: 19 | B20: 022MC22-2-5 | C20: 3.61 | D20: 0.88 | E20: 23006.44 | F20: 31592.42 | G20: 71867.45 | H20: 170653.77 | I20: 1900.95 | J20: 9979.52 | K20: 88194.09 | L20: 31.71 | M20: 19300.11 | N20: 286.62 | O20: 1039.76 | P20: 64840.56 | Q20: 0.46 | R20: 27.29 | S20: 883.03 | T20: 25.18 | U20: 288.92 | V20: 80.93 | W20: 0.303 | X20: 380.46 | Y20: 62.77 | Z20: 120.21 | AA20: 13.43 | AB20: 50.92 | AC20: 7.93 | AD20: 2.32 | AE20: 7.15 | AF20: 1.035 | AG20: 5.13 | AH20: 0.92 | AI20: 2.41 | AJ20: 0.298 | AK20: 2.11 | AL20: 0.269 | AM20: 6.41 | AN20: 4.76 | AO20: 3.72 | AP20: 6.61 | AQ20: 1.5
A21: 20 | B21: 023MC22-2-8 | C21: 3.09 | D21: 5.8 | E21: 11938.23 | F21: 136057.78 | G21: 45683.98 | H21: 208577.73 | I21: 1904.76 | J21: 7952.87 | K21: 93482.88 | L21: 28.16 | M21: 16378.47 | N21: 241.05 | O21: 1659.64 | P21: 107640.5 | Q21: 0.69 | R21: 16.06 | S21: 742.53 | T21: 19.86 | U21: 246.33 | V21: 86.19 | W21: 0.167 | X21: 252.32 | Y21: 42.65 | Z21: 85.75 | AA21: 12.43 | AB21: 52.15 | AC21: 8.04 | AD21: 2.21 | AE21: 5.06 | AF21: 0.79 | AG21: 4.63 | AH21: 0.541 | AI21: 1.92 | AJ21: 0.218 | AK21: 1.79 | AL21: 0.157 | AM21: 4.03 | AN21: 3.56 | AO21: 153.69 | AP21: 6.04 | AQ21: 1.38
A22: 21 | B22: 024KL2 | C22: 5.07 | D22: 2.67 | E22: 18232.34 | F22: 45009.12 | G22: 73842.78 | H22: 243282.55 | I22: 1137.23 | J22: 3938.91 | K22: 77901.7 | L22: 31.33 | M22: 15301.9 | N22: 304.17 | O22: 1274.33 | P22: 88705.16 | Q22: 0.19 | R22: 8.58 | S22: 359 | T22: 26.11 | U22: 154.58 | V22: 14.98 | W22: 0.115 | X22: 131.64 | Y22: 14.4 | Z22: 33.36 | AA22: 4.64 | AB22: 21.81 | AC22: 5.53 | AD22: 1.91 | AE22: 6.13 | AF22: 0.939 | AG22: 5.54 | AH22: 1.03 | AI22: 2.73 | AJ22: 0.361 | AK22: 2.14 | AL22: 0.305 | AM22: 4.51 | AN22: 1.05 | AO22: 2.17 | AP22: 1.09 | AQ22: 0.513
... A38: 37 | B38: 042KL2 | C38: 4.48 | D38: 2.24 | E38: 16538.59 | F38: 41223.55 | G38: 67925.31 | H38: 230785.91 | I38: 963.73 | J38: 4043.26 | K38: 77901.69 | L38: 31.62 | M38: 14438.25 | N38: 281.27 | O38: 1156.76 | P38: 75409.52 | Q38: 0.124 | R38: 8.5 | S38: 341 | T38: 26.36 | U38: 155.92 | V38: 13.88 | W38: 0.127 | X38: 107.87 | Y38: 11.96 | Z38: 29.97 | AA38: 4.4 | AB38: 21 | AC38: 5.39 | AD38: 1.72 | AE38: 5.81 | AF38: 0.842 | AG38: 5.2 | AH38: 0.9 | AI38: 2.23 | AJ38: 0.315 | AK38: 2.23 | AL38: 0.292 | AM38: 3.91 | AN38: 0.89 | AO38: 1.88 | AP38: 1.02 | AQ38: 0.438
A39: 38 | B39: 043GOR132 | C39: 8.93 | D39: 15 | E39: 6291.95 | F39: 139167.44 | G39: 56518.28 | H39: 210152.63 | I39: 125.28 | J39: 175.82 | K39: 60392.23 | L39: 33.48 | M39: 1809.47 | N39: 228.15 | O39: 1230.28 | P39: 81603.91 | Q39: 0.145 | R39: 2.04 | S39: 15.38 | T39: 12.05 | U39: 9.11 | V39: 0.044 | W39: 7.8 | X39: 0.811 | Y39: 0.079 | Z39: 0.354 | AA39: 0.0848 | AB39: 0.563 | AC39: 0.481 | AD39: 0.254 | AE39: 1.11 | AF39: 0.231 | AG39: 2.13 | AH39: 0.446 | AI39: 1.42 | AJ39: 0.226 | AK39: 1.42 | AL39: 0.204 | AM39: 0.362 | AN39: 0.0202 | AO39: 21.97 | AP39: <0.0086 | AQ39: 0.051
A40: 39 | B40: 044KL2 | C40: 5.07 | D40: 2.28 | E40: 17274.14 | F40: 43054.39 | G40: 68768.38 | H40: 238980.2 | I40: 1008.25 | J40: 4070.78 | K40: 77901.68 | L40: 32.54 | M40: 15758.94 | N40: 313.24 | O40: 1277.02 | P40: 82468.35 | Q40: 0.22 | R40: 8.79 | S40: 347.28 | T40: 25.28 | U40: 146.94 | V40: 15.23 | W40: 0.132 | X40: 122.1 | Y40: 13.01 | Z40: 31.82 | AA40: 4.59 | AB40: 21.38 | AC40: 5.44 | AD40: 1.95 | AE40: 6.02 | AF40: 0.87 | AG40: 5.06 | AH40: 1 | AI40: 2.53 | AJ40: 0.32 | AK40: 1.97 | AL40: 0.285 | AM40: 4.14 | AN40: 0.92 | AO40: 2.13 | AP40: 1.01 | AQ40: 0.474
A41: 40 | B41: 045KL2 | C41: 4.99 | D41: 2.47 | E41: 17742.6 | F41: 43981.13 | G41: 69712.15 | H41: 240256.08 | I41: 1042.94 | J41: 3973.53 | K41: 77901.69 | L41: 31.49 | M41: 15681.25 | N41: 310.46 | O41: 1267.86 | P41: 84367.95 | Q41: 0.155 | R41: 8.93 | S41: 352.89 | T41: 24.92 | U41: 148.61 | V41: 14.96 | W41: 0.126 | X41: 119.61 | Y41: 12.62 | Z41: 32.14 | AA41: 4.44 | AB41: 20.11 | AC41: 5.31 | AD41: 1.91 | AE41: 5.7 | AF41: 0.864 | AG41: 5.03 | AH41: 0.9 | AI41: 2.55 | AJ41: 0.34 | AK41: 2.06 | AL41: 0.323 | AM41: 3.97 | AN41: 0.9 | AO41: 2.06 | AP41: 1.03 | AQ41: 0.502
A42: 41 | B42: 046KL2 | C42: 5.13 | D42: 2.9 | E42: 17731.5 | F42: 44485.9 | G42: 68889.89 | H42: 237803.67 | I42: 1026.99 | J42: 4027.16 | K42: 77901.69 | L42: 31.07 | M42: 15243.38 | N42: 309.66 | O42: 1275.52 | P42: 85911.7 | Q42: 0.165 | R42: 8.64 | S42: 350.88 | T42: 24.52 | U42: 148.25 | V42: 14.96 | W42: 0.102 | X42: 120.9 | Y42: 12.85 | Z42: 31.96 | AA42: 4.43 | AB42: 20.59 | AC42: 5.16 | AD42: 1.86 | AE42: 6.07 | AF42: 0.854 | AG42: 4.77 | AH42: 0.93 | AI42: 2.53 | AJ42: 0.315 | AK42: 2.07 | AL42: 0.256 | AM42: 3.59 | AN42: 0.92 | AO42: 2.09 | AP42: 1 | AQ42: 0.514
A43: 42 | B43: 047GOR128 | C43: 9.24 | D43: 17.88 | E43: 4404.9 | F43: 141464.02 | G43: 52126.84 | H43: 197711.66 | I43: 80.03 | J43: 206.4 | K43: 44597.33 | L43: 29.57 | M43: 1726.76 | N43: 186.72 | O43: 1363.61 | P43: 76592.48 | Q43: <0.076 | R43: 0.364 | S43: 29.94 | T43: 11 | U43: 8.98 | V43: 0.097 | W43: 0.194 | X43: 1.02 | Y43: 0.113 | Z43: 0.453 | AA43: 0.0767 | AB43: 0.724 | AC43: 0.505 | AD43: 0.271 | AE43: 1.09 | AF43: 0.234 | AG43: 1.82 | AH43: 0.401 | AI43: 1.32 | AJ43: 0.156 | AK43: 1.18 | AL43: 0.167 | AM43: 0.344 | AN43: 0.0166 | AO43: 0.31 | AP43: <0.0067 | AQ43: 0.0095
A44: 43 | B44: 048MC59-1-2A | C44: 9.79 | D44: 2.62 | E44: 44626.88 | F44: 59173.95 | G44: 106219.51 | H44: 253006.88 | I44: 3797.93 | J44: 22731.52 | K44: 64751.9 | L44: 16.17 | M44: 20015.58 | N44: 176.06 | O44: 1745.18 | P44: 77952.2 | Q44: 1.01 | R44: 69.05 | S44: 1197.36 | T44: 39.48 | U44: 460.83 | V44: 143.83 | W44: 0.58 | X44: 697.19 | Y44: 111.63 | Z44: 237.74 | AA44: 26.36 | AB44: 92 | AC44: 13.79 | AD44: 4.35 | AE44: 11.63 | AF44: 1.68 | AG44: 8.1 | AH44: 1.43 | AI44: 3.5 | AJ44: 0.53 | AK44: 3.58 | AL44: 0.427 | AM44: 8.21 | AN44: 8.65 | AO44: 10.37 | AP44: 11.27 | AQ44: 2.9
A45: 44 | B45: 049MC59-2-1A | C45: 4.3 | D45: 2.32 | E45: 27329.81 | F45: 21154.34 | G45: 81745.2 | H45: 190084.97 | I45: 4388.04 | J45: 8578.81 | K45: 114137.73 | L45: 34.87 | M45: 23252.36 | N45: 350.26 | O45: 966.41 | P45: 58572.9 | Q45: 0.4 | R45: 22.02 | S45: 633.7 | T45: 28.57 | U45: 224.41 | V45: 41.96 | W45: 0.281 | X45: 275.03 | Y45: 27.44 | Z45: 64.62 | AA45: 9.07 | AB45: 41.34 | AC45: 9.3 | AD45: 2.94 | AE45: 8.13 | AF45: 1.08 | AG45: 5.86 | AH45: 1.17 | AI45: 2.71 | AJ45: 0.418 | AK45: 2.34 | AL45: 0.309 | AM45: 5.44 | AN45: 2.56 | AO45: 2.8 | AP45: 2.4 | AQ45: 0.86
A46: 45 | B46: 050MC59-2-6A | C46: 6.87 | D46: 3.75 | E46: 33087.27 | F46: 40047.36 | G46: 96657.41 | H46: 224707.58 | I46: 6166.63 | J46: 35982.24 | K46: 76830.34 | L46: 22.48 | M46: 13132.22 | N46: 313.52 | O46: 1453.86 | P46: 74932.47 | Q46: 1.45 | R46: 121.2 | S46: 2279.12 | T46: 32.23 | U46: 459.44 | V46: 250.89 | W46: 1.49 | X46: 1424.14 | Y46: 133.39 | Z46: 199.02 | AA46: 19.07 | AB46: 63.42 | AC46: 10.39 | AD46: 3.22 | AE46: 8 | AF46: 1.03 | AG46: 6.2 | AH46: 1.27 | AI46: 3.54 | AJ46: 0.47 | AK46: 3.54 | AL46: 0.515 | AM46: 10.88 | AN46: 16.64 | AO46: 11.58 | AP46: 22.82 | AQ46: 5.63
A47: 46 | B47: 051MC59-9-1A | C47: 5.87 | D47: 2.75 | E47: 30135.31 | F47: 32786.87 | G47: 86921.61 | H47: 211769.61 | I47: 1809.58 | J47: 9777.27 | K47: 108420.13 | L47: 35.08 | M47: 21476.94 | N47: 331.23 | O47: 1091.11 | P47: 64955.32 | Q47: 0.94 | R47: 37.14 | S47: 1083.29 | T47: 28.8 | U47: 374.14 | V47: 109.45 | W47: 0.52 | X47: 486.48 | Y47: 81.54 | Z47: 158.46 | AA47: 16.78 | AB47: 60.77 | AC47: 9.95 | AD47: 3.32 | AE47: 8.51 | AF47: 1.09 | AG47: 6.53 | AH47: 1.14 | AI47: 2.66 | AJ47: 0.371 | AK47: 2.31 | AL47: 0.282 | AM47: 8.81 | AN47: 6.35 | AO47: 3.79 | AP47: 9.51 | AQ47: 2.63
A48: 47 | B48: 052MC59-9-1B | C48: 5.53 | D48: 2.92 | E48: 31089.67 | F48: 87649.75 | G48: 86524.04 | H48: 258177.17 | I48: 1951.97 | J48: 10592.96 | K48: 112350.98 | L48: 41.18 | M48: 20577.35 | N48: 301.14 | O48: 1535.05 | P48: 113570.77 | Q48: 0.96 | R48: 37.59 | S48: 990.34 | T48: 26.62 | U48: 390.05 | V48: 96.9 | W48: 0.51 | X48: 480.95 | Y48: 89.43 | Z48: 154.11 | AA48: 16.67 | AB48: 61.77 | AC48: 9.27 | AD48: 2.86 | AE48: 9.62 | AF48: 1.09 | AG48: 6.77 | AH48: 1.36 | AI48: 3.48 | AJ48: 0.42 | AK48: 1.93 | AL48: 0.383 | AM48: 10.54 | AN48: 6.91 | AO48: 4.26 | AP48: 10.03 | AQ48: 2.4
A49: 48 | B49: 053MC59-9-1B2 | C49: 6.25 | D49: 3.88 | E49: 40759.39 | F49: 50641.32 | G49: 94393.63 | H49: 310093.81 | I49: 2735.54 | J49: 13822.55 | K49: 112350.98 | L49: 38.86 | M49: 20957.25 | N49: 383.45 | O49: 1403.14 | P49: 102356.7 | Q49: 1.28 | R49: 52.98 | S49: 1188.79 | T49: 31.9 | U49: 453.19 | V49: 133.69 | W49: 0.69 | X49: 554.89 | Y49: 93.78 | Z49: 182.51 | AA49: 19.36 | AB49: 70.78 | AC49: 10.85 | AD49: 3.47 | AE49: 9.95 | AF49: 1.27 | AG49: 6.49 | AH49: 1.27 | AI49: 3.5 | AJ49: 0.363 | AK49: 2.59 | AL49: 0.307 | AM49: 10.28 | AN49: 7.11 | AO49: 6.63 | AP49: 11.19 | AQ49: 3.18
A50: 49 | B50: 054MC59-2-8A | C50: 3.95 | D50: 0.72 | E50: 23829.33 | F50: 116898.38 | G50: 89292.41 | H50: 237802.3 | I50: 1646.56 | J50: 8239.21 | K50: 113280.09 | L50: 36.76 | M50: 18960.86 | N50: 305.44 | O50: 1290.7 | P50: 79327.91 | Q50: 0.7 | R50: 22.08 | S50: 844.19 | T50: 29.47 | U50: 281.84 | V50: 59.65 | W50: 0.213 | X50: 329.55 | Y50: 44.13 | Z50: 98.57 | AA50: 12.46 | AB50: 49.66 | AC50: 8.51 | AD50: 2.86 | AE50: 7.39 | AF50: 1.11 | AG50: 5.51 | AH50: 1.02 | AI50: 2.5 | AJ50: 0.333 | AK50: 2.45 | AL50: 0.252 | AM50: 5.66 | AN50: 3.75 | AO50: 6.19 | AP50: 4.4 | AQ50: 1.22
A51: 50 | B51: 055MC59-1-3A | C51: 4.02 | D51: 2.71 | E51: 29689.55 | F51: 220437.08 | G51: 102801.8 | H51: 307653.09 | I51: 1631.29 | J51: 8241.64 | K51: 112636.85 | L51: 37.07 | M51: 20528.77 | N51: 356.1 | O51: 2041.39 | P51: 127461.78 | Q51: 0.38 | R51: 27.24 | S51: 996.57 | T51: 30.58 | U51: 286.6 | V51: 68.31 | W51: 0.238 | X51: 355.64 | Y51: 63.08 | Z51: 132.64 | AA51: 14.48 | AB51: 56.93 | AC51: 10.03 | AD51: 3.39 | AE51: 8.9 | AF51: 1.2 | AG51: 7.48 | AH51: 1.29 | AI51: 3.73 | AJ51: 0.54 | AK51: 2.77 | AL51: 0.359 | AM51: 7.5 | AN51: 4.63 | AO51: 5.89 | AP51: 4.92 | AQ51: 1.46
A52: 51 | B52: 056MC59-1-3B | C52: 4.59 | D52: 2.47 | E52: 29368.58 | F52: 39620.71 | G52: 99742.35 | H52: 207311.67 | I52: 3121.11 | J52: 13489.34 | K52: 106990.72 | L52: 27.33 | M52: 18286.2 | N52: 387.83 | O52: 1138.03 | P52: 67592.09 | Q52: 0.82 | R52: 44.77 | S52: 1363.1 | T52: 36.47 | U52: 402.56 | V52: 125.36 | W52: 0.38 | X52: 614.54 | Y52: 111.66 | Z52: 208.29 | AA52: 22.16 | AB52: 79.1 | AC52: 12.42 | AD52: 3.7 | AE52: 10.79 | AF52: 1.45 | AG52: 7.34 | AH52: 1.43 | AI52: 3.6 | AJ52: 0.53 | AK52: 2.95 | AL52: 0.327 | AM52: 8.49 | AN52: 8.2 | AO52: 21.06 | AP52: 10.43 | AQ52: 2.56
A53: 52 | B53: 057MC59-1-7B | C53: 5.68 | D53: 2.24 | E53: 33654.76 | F53: 27416.9 | G53: 87475.92 | H53: 220188.77 | I53: 2094.34 | J53: 9918.6 | K53: 103274.27 | L53: 29.87 | M53: 26801.64 | N53: 324.94 | O53: 1412.79 | P53: 83581.31 | Q53: 0.56 | R53: 24.34 | S53: 1011.95 | T53: 36.51 | U53: 403.85 | V53: 67.26 | W53: 0.288 | X53: 313.34 | Y53: 54.96 | Z53: 128.8 | AA53: 16.25 | AB53: 69.73 | AC53: 13.98 | AD53: 4 | AE53: 11.1 | AF53: 1.56 | AG53: 8.03 | AH53: 1.37 | AI53: 3.44 | AJ53: 0.446 | AK53: 2.75 | AL53: 0.359 | AM53: 10.11 | AN53: 4.01 | AO53: 4.07 | AP53: 5.07 | AQ53: 1.39
A54: 53 | B54: 058MC82-6 | C54: 4.03 | D54: 1.67 | E54: 21856.55 | F54: 22635.95 | G54: 77475.99 | H54: 170249.72 | I54: 1855.71 | J54: 8862.9 | K54: 91982.01 | L54: 28.02 | M54: 19205.7 | N54: 283.4 | O54: 1100.03 | P54: 65180.92 | Q54: 0.44 | R54: 25.19 | S54: 855.26 | T54: 29.09 | U54: 281.53 | V54: 70.1 | W54: 0.281 | X54: 300.28 | Y54: 51.95 | Z54: 108.26 | AA54: 12.95 | AB54: 52.23 | AC54: 8.63 | AD54: 2.71 | AE54: 8.26 | AF54: 1.19 | AG54: 6.12 | AH54: 0.96 | AI54: 2.45 | AJ54: 0.393 | AK54: 2.11 | AL54: 0.279 | AM54: 5.59 | AN54: 3.75 | AO54: 3.8 | AP54: 6.02 | AQ54: 1.24
A55: 54 | B55: 059MC82-11 | C55: 4.44 | D55: 2.42 | E55: 24432.84 | F55: 68036.59 | G55: 90426.33 | H55: 228742.73 | I55: 2794.03 | J55: 12290.9 | K55: 112065.09 | L55: 38.56 | M55: 23168.01 | N55: 379.06 | O55: 1558.23 | P55: 93138.12 | Q55: 0.71 | R55: 32.75 | S55: 1159.21 | T55: 37.82 | U55: 393.95 | V55: 112.51 | W55: 0.44 | X55: 460.62 | Y55: 83.92 | Z55: 168.57 | AA55: 19.92 | AB55: 81.26 | AC55: 12.37 | AD55: 3.2 | AE55: 9.8 | AF55: 1.47 | AG55: 7.49 | AH55: 1.21 | AI55: 3.23 | AJ55: 0.47 | AK55: 3.12 | AL55: 0.411 | AM55: 8.33 | AN55: 6.09 | AO55: 5.5 | AP55: 9.55 | AQ55: 2.06
...

Sheet Sheet4
A1: Element | B1: Li7 | C1: B11 | D1: Na23 | E1: Mg24 | F1: Al27 | G1: Si29 | H1: P31 | I1: K39 | J1: Ca43 | K1: Sc45 | L1: Ti47 | M1: V51 | N1: Mn55 | O1: Fe57 | P1: As75 | Q1: Rb85 | R1: Sr88 | S1: Y89 | T1: Zr90 | U1: Nb93 | V1: Cs133 | W1: Ba138 | X1: La139 | Y1: Ce140 | Z1: Pr141 | AA1: Nd146 | AB1: Sm147 | AC1: Eu151 | AD1: Gd157 | AE1: Tb159 | AF1: Dy163 | AG1: Ho165 | AH1: Er166 | AI1: Tm169 | AJ1: Yb172 | AK1: Lu175 | AL1: Hf178 | AM1: Ta181 | AN1: Pb208 | AO1: Th232 | AP1: U238
A2: 005KL2 | B2: 5.22 | C2: 2.48 | D2: 17245.47 | E2: 44940.31 | F2: 69620.05 | G2: 233055.86 | H2: 919.53 | I2: 4019.08 | J2: 77901.7 | K2: 31.98 | L2: 15304.21 | M2: 310.73 | N2: 1286.29 | O2: 82919.68 | P2: 0.107 | Q2: 8.89 | R2: 353.77 | S2: 24.97 | T2: 147.91 | U2: 14.71 | V2: 0.11 | W2: 123.03 | X2: 13.2 | Y2: 31.48 | Z2: 4.63 | AA2: 21.51 | AB2: 5.69 | AC2: 1.83 | AD2: 5.69 | AE2: 0.889 | AF2: 5.19 | AG2: 0.96 | AH2: 2.49 | AI2: 0.33 | AJ2: 2.08 | AK2: 0.288 | AL2: 3.69 | AM2: 0.936 | AN2: 2.08 | AO2: 0.977 | AP2: 0.558
A3: 007BM90 | B3: 2.02 | C3: 1.67 | D3: 872.46 | E3: 208008.56 | F3: 12476.81 | G3: 241693.27 | H3: 18.41 | I3: <24.43 | J3: 15008.72 | K3: 16.53 | L3: 367.15 | M3: 56 | N3: 835.55 | O3: 56222.92 | P3: 0.104 | Q3: 0.262 | R3: 0.669 | S3: 2.21 | T3: 20.02 | U3: 0.022 | V3: 0.84 | W3: 0.463 | X3: 0.215 | Y3: 0.414 | Z3: 0.0784 | AA3: 0.412 | AB3: 0.107 | AC3: 0.0436 | AD3: 0.282 | AE3: 0.0438 | AF3: 0.359 | AG3: 0.084 | AH3: 0.216 | AI3: 0.0425 | AJ3: 0.301 | AK3: 0.0561 | AL3: 0.59 | AM3: 0.0046 | AN3: 0.475 | AO3: 0.056 | AP3: 0.085
A4: 008BM90 | B4: 1.72 | C4: 1.76 | D4: 868.99 | E4: 208148.02 | F4: 12030.06 | G4: 241599.27 | H4: 17.81 | I4: <25.01 | J4: 15008.72 | K4: 16.46 | L4: 348.62 | M4: 55.91 | N4: 843.48 | O4: 56710.61 | P4: <0.074 | Q4: 0.304 | R4: 0.65 | S4: 2.32 | T4: 19.52 | U4: <0.0218 | V4: 0.9 | W4: 0.44 | X4: 0.177 | Y4: 0.443 | Z4: 0.0734 | AA4: 0.389 | AB4: 0.151 | AC4: 0.0526 | AD4: 0.28 | AE4: 0.0453 | AF4: 0.387 | AG4: 0.091 | AH4: 0.258 | AI4: 0.0465 | AJ4: 0.318 | AK4: 0.0548 | AL4: 0.543 | AM4: <0.0062 | AN4: 0.479 | AO4: 0.0545 | AP4: 0.072
A5: 009GOR132 | B5: 8.87 | C5: 11.71 | D5: 6672.55 | E5: 142794.02 | F5: 57438.87 | G5: 218643.95 | H5: 118.34 | I5: 189.71 | J5: 60392.23 | K5: 35.59 | L5: 1785.51 | M5: 233.08 | N5: 1251.49 | O5: 86376.49 | P5: 0.141 | Q5: 2.31 | R5: 15.82 | S5: 13.19 | T5: 9.58 | U5: 0.069 | V5: 8.21 | W5: 0.868 | X5: 0.093 | Y5: 0.344 | Z5: 0.088 | AA5: 0.743 | AB5: 0.486 | AC5: 0.262 | AD5: 1.14 | AE5: 0.215 | AF5: 2.08 | AG5: 0.489 | AH5: 1.6 | AI5: 0.229 | AJ5: 1.42 | AK5: 0.232 | AL5: 0.348 | AM5: 0.0362 | AN5: 22.24 | AO5: 0.0075 | AP5: 0.051
